Workbook

Sheet Variables
A1: Variable | B1: Description | C1: Time Frame | D1: Time Unit | E1: Links
A2: S&P 500 Index | B2: A stock market index that may influence investment decisions and consumer confidence, impacting gasoline demand. | C2: 2016 - 2026 | D2: Daily except weekends | E2: S&P 500® | S&P Dow Jones Indices (spglobal.com)
A3: Weekly Jobless Claims | B3: A measure of unemployment trends, which can affect consumer spending on gasoline. | C3: 1967 - 2026 | D3: Weekly | E3: Initial Claims (ICSA) | FRED | St. Louis Fed (stlouisfed.org)
A4: TSA Passenger Throughput | B4: Indicates air travel activity and its impact on airport gasoline sales. | C4: 2019 - 2026 | D4: Daily | E4: Travel Passenger Throughputs
A5: US Spot Market Prices of Crude Oil | B5: The cost of crude oil in the United States, influencing gasoline production costs and prices. | C5: 1986 - 2026 | D5: Weekly | E5: Weekly Cushing, OK WTI Spot Price FOB (Dollars per Barrel) (eia.gov)
A6: Europe Spot Market Prices of Crude Oil | B6: Crude oil prices in Europe, affecting international oil markets and gasoline pricing. | C6: 1987 - 2026 | D6: Weekly | E6: Weekly Europe Brent Spot Price FOB (Dollars per Barrel) (eia.gov)
A7: Regular (87 Octane) Gasoline Prices | B7: The cost of regular gasoline, a key factor in consumer gasoline purchasing decisions. | C7: 1990 - 2026 | D7: Weekly | E7: Weekly U.S. Regular All Formulations Retail Gasoline Prices (Dollars per Gallon) (eia.gov)
A8: USA GDP | B8: The overall economic output of the United States, influencing gasoline consumption patterns. | C8: 1947 - 2026 | D8: Quarterly | E8: Gross Domestic Product (GDP) | FRED | St. Louis Fed (stlouisfed.org)
A9: Public Transport Ridership | B9: Trends in the use of public transportation, which can affect gasoline demand. | C9: 1990 - 2026 | D9: Quarterly | E9: Ridership Data Archives - APTA
A10: Rig Count | B10: The number of active drilling rigs, providing insight into future oil and gasoline supply. | C10: 1973 - 2026 | D10: Monthly | E10: U.S. Crude Oil and Natural Gas Drilling Activity
A11: Automobile Sales | B11: Sales of vehicles, impacting gasoline consumption through vehicle ownership. | C11: 1976 - 2026 | D11: Monthly | E11: Total Vehicle Sales (TOTALSA) | FRED | St. Louis Fed (stlouisfed.org)
A12: Highway Traffic Data | B12: Data on road traffic and congestion levels, influencing gasoline usage patterns. | C12: 2002 - 2026 | D12: Monthly | E12: Office of Highway Policy Information - Policy | Federal Highway Administration (dot.gov)
... A29: US Population-Weighted CDD | B29: Weekly sum of cooling degree days weighted across U.S. population to capture real summer heatwaves. | C29: 1991 - 2026 | D29: Weekly (Ending Friday) | E29: https://open-meteo.com/

Sheet Hypotheses
A1: Predictor | B1: Hypothesis | C1: Magnitude | D1: Direction
A2: US Spot Market Prices of Crude Oil | B2: Higher crude prices often deter gasoline consumption due to price elasticity. | C2: High | D2: Negative | F2: Karina's personal hypotheses: you can challenge or disagree.
A3: Regular (87 Octane) Gasoline Prices | B3: Higher gasoline prices generally deter consumption. | C3: High | D3: Negative
A4: EV Sales | B4: Increased EV sales may decrease gasoline demand as more people use electric vehicles. | C4: High | D4: Negative
A5: EV Regulations | B5: Higher EV regulations decrease gasoline demand as fleet companies are forced to transition away from gasoline vehicles. | C5: High | D5: Negative
A6: Highway Traffic Data | B6: Increased highway traffic indicates greater vehicle usage, leading to higher gasoline demand. | C6: High | D6: Positive
A7: S&P 500 Index | B7: Higher stock market performance may indicate a booming economy, leading to increased gasoline demand. | C7: Medium | D7: Positive
A8: Weekly Jobless Claims | B8: Higher jobless claims indicate economic downturns, which may result in decreased gasoline demand. | C8: Medium | D8: Negative
A9: Europe Spot Market Prices of Crude Oil | B9: If European crude prices rise and the US follows, it could deter gasoline demand. | C9: Medium | D9: Negative
A10: USA GDP | B10: Higher GDP indicates a robust economy, potentially driving up gasoline demand. | C10: Medium | D10: Positive
A11: Public Transport Ridership | B11: Increased public transport ridership may lead to decreased gasoline demand. | C11: Medium | D11: Negative
A12: Automobile Sales | B12: Higher sales, especially of gasoline-based vehicles, indicate potential increased gasoline demand. | C12: Medium | D12: Positive
A13: Personal Consumption Expenditures | B13: Higher consumer spending can suggest increased economic activity and gasoline demand. | C13: Medium | D13: Positive
A14: Refinery Utilization | B14: Higher refinery utilization can lead to increased gasoline supply, potentially affecting demand balance. | C14: Medium | D14: Positive
... A16: Inflation Expectations | B16: Higher inflation expectations could deter spending, potentially reducing gasoline demand. | C16: Medium | D16: Negative
A17: Employee Earnings | B17: Higher earnings boost disposable income, possibly increasing gasoline demand due to increased travel. | C17: Medium | D17: Positive | O17: -
A18: TSA Passenger Throughput | B18: An increase in passenger throughput may indicate higher air travel, potentially reducing gasoline demand. | C18: Low | D18: Negative
A19: Rig Count | B19: A higher rig count suggests increased domestic production, potentially influencing gasoline demand. | C19: Low | D19: Positive
A20: Consumer Credit Data | B20: Higher consumer credit indicates more spending, including on vehicles and travel, potentially driving gasoline demand. | C20: Low | D20: Positive
A21: Household Debt and Credit | B21: Higher household debt may deter spending, including on travel, potentially reducing gasoline demand. | C21: Low | D21: Negative
A22: Labor Costs | B22: Rising labor costs could affect gasoline production costs, potentially affecting gasoline demand. | C22: Low | D22: Negative
A23: Smoking Consumption | B23: Decrease in smoking might indicate health-conscious decisions, including eco-friendly transportation choices. | C23: Low | D23: Negative
A24: Housing Market Expectations | B24: A booming housing market might lead to increased travel, potentially driving up gasoline demand. | C24: Low | D24: Positive
A25: Major Driving Holiday Week | B25: Weeks containing Memorial Day, July 4, Labor Day, Thanksgiving, Christmas, or New Year's Day see a surge in road trips and family travel, which should raise gasoline demand relative to an ordinary week. But Thanksgiving and Christmas weeks also carry days when many people don't commute or run errands at all, so the net effect could go either way depending on which force dominates. | C25: High | D25: Conditional
A26: Work From Home Share | B26: A higher share of work-from-home days should lower gasoline demand, since commuting is a large and regular share of vehicle miles driven and this trip disappears entirely on remote days. This is a structural shift rather than a short-term fluctuation, and expected to matter most in explaining why demand hasn't returned to pre-2020 levels rather than in explaining week-to-week noise. | C26: High | D26: Negative
A27: US Population-Weighted HDD | B27: Severe winter cold and winter storms reduce vehicle miles traveled and suppress gasoline demand. | C27: Medium | D27: Negative
A28: US Population-Weighted CDD | B28: Warmer summer temperatures increase vacation driving trips and air conditioning load. | C28: Medium | D28: Positive

Sheet Simple Linear Regression
A1: SUMMARY OUTPUT
A3: Regression Statistics
A4: Multiple R | B4: 0.59469786
A5: R Square | B5: 0.35366554
A6: Adjusted R Square | B6: 0.35329976
A7: Standard Error | B7: 589.22746
A8: Observations | B8: 1769
A10: ANOVA
B11: df | C11: SS | D11: MS | E11: F | F11: Significance F
A12: Regression | B12: 1 | C12: 3.3568964e+08 | D12: 3.3568964e+08 | E12: 966.87869 | F12: 1.1029353e-169
A13: Residual | B13: 1767 | C13: 6.1348295e+08 | D13: 347188.99
A14: Total | B14: 1768 | C14: 9.4917259e+08
B16: Coefficients | C16: Standard Error | D16: t Stat | E16: P-value | F16: Lower 95% | G16: Upper 95% | H16: Lower 95.0% | I16: Upper 95.0%
A17: Intercept | B17: 7885.3363 | C17: 28.030652 | D17: 281.31119 | E17: 0 | F17: 7830.3596 | G17: 7940.3131 | H17: 7830.3596 | I17: 7940.3131
A18: X Variable 1 | B18: 0.85303708 | C18: 0.027433544 | D18: 31.094673 | E18: 1.1029353e-169 | F18: 0.79923147 | G18: 0.9068427 | H18: 0.79923147 | I18: 0.9068427

Sheet Target
A1: Week # | B1: Date | C1: Demand | D1: sp500_weekly_avg | E1: initial_jobless_claims | F1: tsa_passengers_weekly_avg | G1: wti_spot_usd_per_bbl | H1: brent_spot_usd_per_bbl | I1: regular_gas_usd_per_gal | J1: gdp_saar_bil_usd | K1: transit_unlinked_trips_thous | L1: rotary_rig_count | M1: vehicle_sales_saar_mil | N1: vehicle_miles_mil | O1: pce_saar_bil_usd | P1: consumer_credit_mil_usd | Q1: ev_sales_vehicles | R1: regulated_afv_acquisitions | S1: household_debt_tril_usd | T1: eci_total_comp_index | U1: smoking_adults_pct | V1: refinery_utilization_pct | W1: fed_broad_dollar_index | X1: home_price_expectation_pct | Y1: inflation_expectation_1y_pct | Z1: mean_annual_earnings_thous_usd | AA1: us_population_thous | AB1: wfh_share_paid_days_pct | AC1: major_holiday_week | AD1: hdd_pop_weighted | AE1: cdd_pop_weighted | AG1: Model C | AH1: Simple Linear Regression Model | AI1: forward selection | AJ1: backward selection | AK1: Restricted Model C | AL1: gas*VMT interaction | AM1: M1 Weather + Holiday | AN1: ARIMAX with cdd and hdd | AP1: ARIMAX(1,1,1) + covariates: fit / forecast | AQ1: ARIMAX Xβ (regression part) | AR1: ARIMAX u (level error) | AS1: ARIMAX ε (1-step residual) | AT1: ARIMAX horizon h | AU1: ARIMAX ψ weight | AV1: ARIMAX Σψ² | AW1: ARIMAX 95% lower | AX1: ARIMAX 95% upper
A2: 1 | B2: 33277 | C2: 6621 | E2: 483000 | G2: 21.304 | H2: 20.626 | I2: 1.139 | L2: 1136 | V2: 84.2 | AC2: 0 | AD2: 18.5 | AE2: 0 | AG2: =6753.47943187+0.36116788*I2+0.01252571*N2-22.85359542*V2+0.00407811*AA2-0.00067349*E2 -> 4504.3224 | AH2: =A2*'Simple Linear Regression'!$B$18+'Simple Linear Regression'!$B$17 -> 7886.1894 | AI2: =7491.3971+0.0137554*N2-0.00058829*E2-34.3283*V2+0.30565*L2+54.6031*M2 -> 4664.0286 | AJ2: =7491.3971-0.00058829*E2+0.30565*L2+54.6031*M2+0.0137554*N2-34.3283*V2 -> 4664.0286 | AL2: =2192.59+2373.87*I2+0.0316653*N2-15.7623*V2+0.00202406*AA2-0.000740146*E2-0.00963493*(I2*N2) -> 3211.7518 | AM2: =5205.907083+122.0638992*I2+13.609808*(N2/1000)-1.245906883*AD2+0.7746840854*AE2-134.2474226*AC2-1547.125689*IF(AND(B2>=DATE(2020,3,20),B2<=DATE(2020,6,26)),1,0) -> 5321.8886 | AN2: =IF(ISNUMBER(C3),C3,AN3)-0.8328750492*(AD4-AD3)+3.274150872*(AE4-AE3)+0.7954612886*((IF(ISNUMBER(C3),C3,AN3)-IF(ISNUMBER(C2),C2,AN2))-(-0.8328750492*(AD3-AD2)+3.274150872*(AE3-AE2)))-1.394571582*AO3+0.4181414112*AO2 -> 6381.8139
A3: 2 | B3: 33284 | C3: 6433 | E3: 480000 | G3: 22.116 | H3: 20.436 | I3: 1.106 | L3: 1136 | V3: 84.2 | AC3: 0 | AD3: 145.9 | AE3: 0.7 | AG3: =6753.47943187+0.36116788*I3+0.01252571*N3-22.85359542*V3+0.00407811*AA3-0.00067349*E3 -> 4506.3309 | AH3: =A3*'Simple Linear Regression'!$B$18+'Simple Linear Regression'!$B$17 -> 7887.0424 | AI3: =7491.3971+0.0137554*N3-0.00058829*E3-34.3283*V3+0.30565*L3+54.6031*M3 -> 4665.7934 | AJ3: =7491.3971-0.00058829*E3+0.30565*L3+54.6031*M3+0.0137554*N3-34.3283*V3 -> 4665.7934 | AL3: =2192.59+2373.87*I3+0.0316653*N3-15.7623*V3+0.00202406*AA3-0.000740146*E3-0.00963493*(I3*N3) -> 3135.6345 | AM3: =5205.907083+122.0638992*I3+13.609808*(N3/1000)-1.245906883*AD3+0.7746840854*AE3-134.2474226*AC3-1547.125689*IF(AND(B3>=DATE(2020,3,20),B3<=DATE(2020,6,26)),1,0) -> 5159.6742 | AN3: =IF(ISNUMBER(C4),C4,AN4)-0.8328750492*(AD5-AD4)+3.274150872*(AE5-AE4)+0.7954612886*((IF(ISNUMBER(C4),C4,AN4)-IF(ISNUMBER(C3),C3,AN3))-(-0.8328750492*(AD4-AD3)+3.274150872*(AE4-AE3)))-1.394571582*AO4+0.4181414112*AO3 -> 6669.6002
A4: 3 | B4: 33291 | C4: 6582 | E4: 474000 | G4: 19.38 | H4: 18.126 | I4: 1.078 | L4: 1136 | M4: 11.829 | V4: 84.2 | AC4: 0 | AD4: 130.1 | AE4: 1.5 | AG4: =6753.47943187+0.36116788*I4+0.01252571*N4-22.85359542*V4+0.00407811*AA4-0.00067349*E4 -> 4510.3618 | AH4: =A4*'Simple Linear Regression'!$B$18+'Simple Linear Regression'!$B$17 -> 7887.8955 | AI4: =7491.3971+0.0137554*N4-0.00058829*E4-34.3283*V4+0.30565*L4+54.6031*M4 -> 5315.2232 | AJ4: =7491.3971-0.00058829*E4+0.30565*L4+54.6031*M4+0.0137554*N4-34.3283*V4 -> 5315.2232 | AL4: =2192.59+2373.87*I4+0.0316653*N4-15.7623*V4+0.00202406*AA4-0.000740146*E4-0.00963493*(I4*N4) -> 3073.607 | AM4: =5205.907083+122.0638992*I4+13.609808*(N4/1000)-1.245906883*AD4+0.7746840854*AE4-134.2474226*AC4-1547.125689*IF(AND(B4>=DATE(2020,3,20),B4<=DATE(2020,6,26)),1,0) -> 5176.5615 | AN4: =IF(ISNUMBER(C5),C5,AN5)-0.8328750492*(AD6-AD5)+3.274150872*(AE6-AE5)+0.7954612886*((IF(ISNUMBER(C5),C5,AN5)-IF(ISNUMBER(C4),C4,AN4))-(-0.8328750492*(AD5-AD4)+3.274150872*(AE5-AE4)))-1.394571582*AO5+0.4181414112*AO4 -> 7784.4795
A5: 4 | B5: 33298 | C5: 7224 | E5: 499000 | G5: 18.73 | H5: 18.662 | I5: 1.054 | L5: 1136 | M5: 11.829 | V5: 84.2 | AC5: 0 | AD5: 149.8 | AE5: 0.9 | AG5: =6753.47943187+0.36116788*I5+0.01252571*N5-22.85359542*V5+0.00407811*AA5-0.00067349*E5 -> 4493.5159 | AH5: =A5*'Simple Linear Regression'!$B$18+'Simple Linear Regression'!$B$17 -> 7888.7485 | AI5: =7491.3971+0.0137554*N5-0.00058829*E5-34.3283*V5+0.30565*L5+54.6031*M5 -> 5300.516 | AJ5: =7491.3971-0.00058829*E5+0.30565*L5+54.6031*M5+0.0137554*N5-34.3283*V5 -> 5300.516 | AL5: =2192.59+2373.87*I5+0.0316653*N5-15.7623*V5+0.00202406*AA5-0.000740146*E5-0.00963493*(I5*N5) -> 2998.1305 | AM5: =5205.907083+122.0638992*I5+13.609808*(N5/1000)-1.245906883*AD5+0.7746840854*AE5-134.2474226*AC5-1547.125689*IF(AND(B5>=DATE(2020,3,20),B5<=DATE(2020,6,26)),1,0) -> 5148.6228 | AN5: =IF(ISNUMBER(C6),C6,AN6)-0.8328750492*(AD7-AD6)+3.274150872*(AE7-AE6)+0.7954612886*((IF(ISNUMBER(C6),C6,AN6)-IF(ISNUMBER(C5),C5,AN5))-(-0.8328750492*(AD6-AD5)+3.274150872*(AE6-AE5)))-1.394571582*AO6+0.4181414112*AO5 -> 6535.0658
A6: 5 | B6: 33305 | C6: 6875 | E6: 488000 | G6: 19.856 | H6: 19.77 | I6: 1.025 | L6: 1068 | M6: 11.829 | O6: 3841 | V6: 82.8 | AC6: 0 | AD6: 111.1 | AE6: 1.8 | AG6: =6753.47943187+0.36116788*I6+0.01252571*N6-22.85359542*V6+0.00407811*AA6-0.00067349*E6 -> 4532.9088 | AH6: =A6*'Simple Linear Regression'!$B$18+'Simple Linear Regression'!$B$17 -> 7889.6015 | AI6: =7491.3971+0.0137554*N6-0.00058829*E6-34.3283*V6+0.30565*L6+54.6031*M6 -> 5334.2626 | AJ6: =7491.3971-0.00058829*E6+0.30565*L6+54.6031*M6+0.0137554*N6-34.3283*V6 -> 5334.2626 | AL6: =2192.59+2373.87*I6+0.0316653*N6-15.7623*V6+0.00202406*AA6-0.000740146*E6-0.00963493*(I6*N6) -> 2959.4971 | AM6: =5205.907083+122.0638992*I6+13.609808*(N6/1000)-1.245906883*AD6+0.7746840854*AE6-134.2474226*AC6-1547.125689*IF(AND(B6>=DATE(2020,3,20),B6<=DATE(2020,6,26)),1,0) -> 5193.9968 | AN6: =IF(ISNUMBER(C7),C7,AN7)-0.8328750492*(AD8-AD7)+3.274150872*(AE8-AE7)+0.7954612886*((IF(ISNUMBER(C7),C7,AN7)-IF(ISNUMBER(C6),C6,AN6))-(-0.8328750492*(AD7-AD6)+3.274150872*(AE7-AE6)))-1.394571582*AO7+0.4181414112*AO6 -> 7075.9948
A7: 6 | B7: 33312 | C7: 6947 | E7: 499000 | G7: 19.894 | H7: 19.278 | I7: 1.045 | L7: 1068 | M7: 11.829 | O7: 3841 | V7: 82.8 | AC7: 0 | AD7: 148 | AE7: 0.7 | AG7: =6753.47943187+0.36116788*I7+0.01252571*N7-22.85359542*V7+0.00407811*AA7-0.00067349*E7 -> 4525.5076 | AH7: =A7*'Simple Linear Regression'!$B$18+'Simple Linear Regression'!$B$17 -> 7890.4546 | AI7: =7491.3971+0.0137554*N7-0.00058829*E7-34.3283*V7+0.30565*L7+54.6031*M7 -> 5327.7914 | AJ7: =7491.3971-0.00058829*E7+0.30565*L7+54.6031*M7+0.0137554*N7-34.3283*V7 -> 5327.7914 | AL7: =2192.59+2373.87*I7+0.0316653*N7-15.7623*V7+0.00202406*AA7-0.000740146*E7-0.00963493*(I7*N7) -> 2998.8329 | AM7: =5205.907083+122.0638992*I7+13.609808*(N7/1000)-1.245906883*AD7+0.7746840854*AE7-134.2474226*AC7-1547.125689*IF(AND(B7>=DATE(2020,3,20),B7<=DATE(2020,6,26)),1,0) -> 5149.6119 | AN7: =IF(ISNUMBER(C8),C8,AN8)-0.8328750492*(AD9-AD8)+3.274150872*(AE9-AE8)+0.7954612886*((IF(ISNUMBER(C8),C8,AN8)-IF(ISNUMBER(C7),C7,AN7))-(-0.8328750492*(AD8-AD7)+3.274150872*(AE8-AE7)))-1.394571582*AO8+0.4181414112*AO7 -> 7629.7578
A8: 7 | B8: 33319 | C8: 7328 | E8: 498000 | G8: 20.304 | H8: 18.796 | I8: 1.043 | L8: 1068 | M8: 12.409 | N8: 157889 | O8: 3841 | V8: 82.8 | AC8: 0 | AD8: 104.9 | AE8: 3.3 | AG8: =6753.47943187+0.36116788*I8+0.01252571*N8-22.85359542*V8+0.00407811*AA8-0.00067349*E8 -> 6503.8522 | AH8: =A8*'Simple Linear Regression'!$B$18+'Simple Linear Regression'!$B$17 -> 7891.3076 | AI8: =7491.3971+0.0137554*N8-0.00058829*E8-34.3283*V8+0.30565*L8+54.6031*M8 -> 7531.8759 | AJ8: =7491.3971-0.00058829*E8+0.30565*L8+54.6031*M8+0.0137554*N8-34.3283*V8 -> 7531.8759 | AL8: =2192.59+2373.87*I8+0.0316653*N8-15.7623*V8+0.00202406*AA8-0.000740146*E8-0.00963493*(I8*N8) -> 6407.7646 | AM8: =5205.907083+122.0638992*I8+13.609808*(N8/1000)-1.245906883*AD8+0.7746840854*AE8-134.2474226*AC8-1547.125689*IF(AND(B8>=DATE(2020,3,20),B8<=DATE(2020,6,26)),1,0) -> 7353.9195 | AN8: =IF(ISNUMBER(C9),C9,AN9)-0.8328750492*(AD10-AD9)+3.274150872*(AE10-AE9)+0.7954612886*((IF(ISNUMBER(C9),C9,AN9)-IF(ISNUMBER(C8),C8,AN8))-(-0.8328750492*(AD9-AD8)+3.274150872*(AE9-AE8)))-1.394571582*AO9+0.4181414112*AO8 -> 6286.4885 | AP8: =C8 -> 7328 | AQ8: ='ARIMAX(1,1,1) Model'!$C$6*I8+'ARIMAX(1,1,1) Model'!$C$7*N8/1000+'ARIMAX(1,1,1) Model'!$C$8*AD8+'ARIMAX(1,1,1) Model'!$C$9*AE8+'ARIMAX(1,1,1) Model'!$C$10*AC8+'ARIMAX(1,1,1) Model'!$C$11*IF(AND(B8>='ARIMAX(1,1,1) Model'!$C$25,B8<='ARIMAX(1,1,1) Model'!$C$26),1,0)+'ARIMAX(1,1,1) Model'!$C$12*E8/1000+'ARIMAX(1,1,1) Model'!$C$13*V8+'ARIMAX(1,1,1) Model'!$C$14*A8+'ARIMAX(1,1,1) Model'!$C$15*SIN(2*PI()*A8/'ARIMAX(1,1,1) Model'!$C$24)+'ARIMAX(1,1,1) Model'!$C$16*COS(2*PI()*A8/'ARIMAX(1,1,1) Model'!$C$24)+'ARIMAX(1,1,1) Model'!$C$17*SIN(4*PI()*A8/'ARIMAX(1,1,1) Model'!$C$24)+'ARIMAX(1,1,1) Model'!$C$18*COS(4*PI()*A8/'ARIMAX(1,1,1) Model'!$C$24) -> 840.57554 | AR8: =IF(ISNUMBER(C8),C8,AP8)-AQ8 -> 6487.4245 | AS8: =IF(ISNUMBER(C8),C8-AP8,0) -> 0
A9: 8 | B9: 33326 | C9: 6777 | E9: 509000 | G9: 19.5825 | H9: 18.275 | I9: 1.047 | L9: 1068 | M9: 12.409 | N9: 157889 | O9: 3841 | V9: 82.8 | AC9: 0 | AD9: 79 | AE9: 7.1 | AG9: =6753.47943187+0.36116788*I9+0.01252571*N9-22.85359542*V9+0.00407811*AA9-0.00067349*E9 -> 6496.4453 | AH9: =A9*'Simple Linear Regression'!$B$18+'Simple Linear Regression'!$B$17 -> 7892.1606 | AI9: =7491.3971+0.0137554*N9-0.00058829*E9-34.3283*V9+0.30565*L9+54.6031*M9 -> 7525.4047 | AJ9: =7491.3971-0.00058829*E9+0.30565*L9+54.6031*M9+0.0137554*N9-34.3283*V9 -> 7525.4047 | AL9: =2192.59+2373.87*I9+0.0316653*N9-15.7623*V9+0.00202406*AA9-0.000740146*E9-0.00963493*(I9*N9) -> 6403.0335 | AM9: =5205.907083+122.0638992*I9+13.609808*(N9/1000)-1.245906883*AD9+0.7746840854*AE9-134.2474226*AC9-1547.125689*IF(AND(B9>=DATE(2020,3,20),B9<=DATE(2020,6,26)),1,0) -> 7389.6206 | AN9: =IF(ISNUMBER(C10),C10,AN10)-0.8328750492*(AD11-AD10)+3.274150872*(AE11-AE10)+0.7954612886*((IF(ISNUMBER(C10),C10,AN10)-IF(ISNUMBER(C9),C9,AN9))-(-0.8328750492*(AD10-AD9)+3.274150872*(AE10-AE9)))-1.394571582*AO10+0.4181414112*AO9 -> 8183.7323 | AP9: =AQ9+AR8 -> 7371.8143 | AQ9: ='ARIMAX(1,1,1) Model'!$C$6*I9+'ARIMAX(1,1,1) Model'!$C$7*N9/1000+'ARIMAX(1,1,1) Model'!$C$8*AD9+'ARIMAX(1,1,1) Model'!$C$9*AE9+'ARIMAX(1,1,1) Model'!$C$10*AC9+'ARIMAX(1,1,1) Model'!$C$11*IF(AND(B9>='ARIMAX(1,1,1) Model'!$C$25,B9<='ARIMAX(1,1,1) Model'!$C$26),1,0)+'ARIMAX(1,1,1) Model'!$C$12*E9/1000+'ARIMAX(1,1,1) Model'!$C$13*V9+'ARIMAX(1,1,1) Model'!$C$14*A9+'ARIMAX(1,1,1) Model'!$C$15*SIN(2*PI()*A9/'ARIMAX(1,1,1) Model'!$C$24)+'ARIMAX(1,1,1) Model'!$C$16*COS(2*PI()*A9/'ARIMAX(1,1,1) Model'!$C$24)+'ARIMAX(1,1,1) Model'!$C$17*SIN(4*PI()*A9/'ARIMAX(1,1,1) Model'!$C$24)+'ARIMAX(1,1,1) Model'!$C$18*COS(4*PI()*A9/'ARIMAX(1,1,1) Model'!$C$24) -> 884.38984 | AR9: =IF(ISNUMBER(C9),C9,AP9)-AQ9 -> 5892.6102 | AS9: =IF(ISNUMBER(C9),C9-AP9,0) -> -594.8143
A10: 9 | B10: 33333 | C10: 7503 | E10: 499000 | G10: 19.63 | H10: 17.946 | I10: 1.052 | L10: 984 | M10: 12.409 | N10: 157889 | O10: 3866.7 | V10: 82.8 | AC10: 0 | AD10: 92.3 | AE10: 2.8 | AG10: =6753.47943187+0.36116788*I10+0.01252571*N10-22.85359542*V10+0.00407811*AA10-0.00067349*E10 -> 6503.182 | AH10: =A10*'Simple Linear Regression'!$B$18+'Simple Linear Regression'!$B$17 -> 7893.0137 | AI10: =7491.3971+0.0137554*N10-0.00058829*E10-34.3283*V10+0.30565*L10+54.6031*M10 -> 7505.613 | AJ10: =7491.3971-0.00058829*E10+0.30565*L10+54.6031*M10+0.0137554*N10-34.3283*V10 -> 7505.613 | AL10: =2192.59+2373.87*I10+0.0316653*N10-15.7623*V10+0.00202406*AA10-0.000740146*E10-0.00963493*(I10*N10) -> 6414.6981 | AM10: =5205.907083+122.0638992*I10+13.609808*(N10/1000)-1.245906883*AD10+0.7746840854*AE10-134.2474226*AC10-1547.125689*IF(AND(B10>=DATE(2020,3,20),B10<=DATE(2020,6,26)),1,0) -> 7370.3292 | AN10: =IF(ISNUMBER(C11),C11,AN11)-0.8328750492*(AD12-AD11)+3.274150872*(AE12-AE11)+0.7954612886*((IF(ISNUMBER(C11),C11,AN11)-IF(ISNUMBER(C10),C10,AN10))-(-0.8328750492*(AD11-AD10)+3.274150872*(AE11-AE10)))-1.394571582*AO11+0.4181414112*AO10 -> 6363.5229 | AP10: =AQ10+AR9+'ARIMAX(1,1,1) Model'!$C$19*(AR9-AR8)+'ARIMAX(1,1,1) Model'!$C$20*AS9 -> 7315.4054 | AQ10: ='ARIMAX(1,1,1) Model'!$C$6*I10+'ARIMAX(1,1,1) Model'!$C$7*N10/1000+'ARIMAX(1,1,1) Model'!$C$8*AD10+'ARIMAX(1,1,1) Model'!$C$9*AE10+'ARIMAX(1,1,1) Model'!$C$10*AC10+'ARIMAX(1,1,1) Model'!$C$11*IF(AND(B10>='ARIMAX(1,1,1) Model'!$C$25,B10<='ARIMAX(1,1,1) Model'!$C$26),1,0)+'ARIMAX(1,1,1) Model'!$C$12*E10/1000+'ARIMAX(1,1,1) Model'!$C$13*V10+'ARIMAX(1,1,1) Model'!$C$14*A10+'ARIMAX(1,1,1) Model'!$C$15*SIN(2*PI()*A10/'ARIMAX(1,1,1) Model'!$C$24)+'ARIMAX(1,1,1) Model'!$C$16*COS(2*PI()*A10/'ARIMAX(1,1,1) Model'!$C$24)+'ARIMAX(1,1,1) Model'!$C$17*SIN(4*PI()*A10/'ARIMAX(1,1,1) Model'!$C$24)+'ARIMAX(1,1,1) Model'!$C$18*COS(4*PI()*A10/'ARIMAX(1,1,1) Model'!$C$24) -> 945.42591 | AR10: =IF(ISNUMBER(C10),C10,AP10)-AQ10 -> 6557.5741 | AS10: =IF(ISNUMBER(C10),C10-AP10,0) -> 187.59462
A11: 10 | B11: 33340 | C11: 6916 | E11: 452000 | G11: 20.892 | H11: 19.172 | I11: 1.066 | L11: 984 | M11: 12.409 | N11: 157889 | O11: 3866.7 | V11: 82.5 | AC11: 0 | AD11: 37.2 | AE11: 14.2 | AG11: =6753.47943187+0.36116788*I11+0.01252571*N11-22.85359542*V11+0.00407811*AA11-0.00067349*E11 -> 6541.6972 | AH11: =A11*'Simple Linear Regression'!$B$18+'Simple Linear Regression'!$B$17 -> 7893.8667 | AI11: =7491.3971+0.0137554*N11-0.00058829*E11-34.3283*V11+0.30565*L11+54.6031*M11 -> 7543.5611 | AJ11: =7491.3971-0.00058829*E11+0.30565*L11+54.6031*M11+0.0137554*N11-34.3283*V11 -> 7543.5611 | AL11: =2192.59+2373.87*I11+0.0316653*N11-15.7623*V11+0.00202406*AA11-0.000740146*E11-0.00963493*(I11*N11) -> 6466.1503 | AM11: =5205.907083+122.0638992*I11+13.609808*(N11/1000)-1.245906883*AD11+0.7746840854*AE11-134.2474226*AC11-1547.125689*IF(AND(B11>=DATE(2020,3,20),B11<=DATE(2020,6,26)),1,0) -> 7449.519 | AN11: =IF(ISNUMBER(C12),C12,AN12)-0.8328750492*(AD13-AD12)+3.274150872*(AE13-AE12)+0.7954612886*((IF(ISNUMBER(C12),C12,AN12)-IF(ISNUMBER(C11),C11,AN11))-(-0.8328750492*(AD12-AD11)+3.274150872*(AE12-AE11)))-1.394571582*AO12+0.4181414112*AO11 -> 7145.1994 | AP11: =AQ11+AR10+'ARIMAX(1,1,1) Model'!$C$19*(AR10-AR9)+'ARIMAX(1,1,1) Model'!$C$20*AS10 -> 7481.8839 | AQ11: ='ARIMAX(1,1,1) Model'!$C$6*I11+'ARIMAX(1,1,1) Model'!$C$7*N11/1000+'ARIMAX(1,1,1) Model'!$C$8*AD11+'ARIMAX(1,1,1) Model'!$C$9*AE11+'ARIMAX(1,1,1) Model'!$C$10*AC11+'ARIMAX(1,1,1) Model'!$C$11*IF(AND(B11>='ARIMAX(1,1,1) Model'!$C$25,B11<='ARIMAX(1,1,1) Model'!$C$26),1,0)+'ARIMAX(1,1,1) Model'!$C$12*E11/1000+'ARIMAX(1,1,1) Model'!$C$13*V11+'ARIMAX(1,1,1) Model'!$C$14*A11+'ARIMAX(1,1,1) Model'!$C$15*SIN(2*PI()*A11/'ARIMAX(1,1,1) Model'!$C$24)+'ARIMAX(1,1,1) Model'!$C$16*COS(2*PI()*A11/'ARIMAX(1,1,1) Model'!$C$24)+'ARIMAX(1,1,1) Model'!$C$17*SIN(4*PI()*A11/'ARIMAX(1,1,1) Model'!$C$24)+'ARIMAX(1,1,1) Model'!$C$18*COS(4*PI()*A11/'ARIMAX(1,1,1) Model'!$C$24) -> 1028.3056 | AR11: =IF(ISNUMBER(C11),C11,AP11)-AQ11 -> 5887.6944 | AS11: =IF(ISNUMBER(C11),C11-AP11,0) -> -565.88388
A12: 11 | B12: 33347 | C12: 7045 | E12: 477000 | G12: 21.484 | H12: 19.712 | I12: 1.069 | L12: 984 | M12: 12.848 | N12: 153351 | O12: 3866.7 | V12: 82.5 | AC12: 0 | AD12: 62 | AE12: 14.6 | AG12: =6753.47943187+0.36116788*I12+0.01252571*N12-22.85359542*V12+0.00407811*AA12-0.00067349*E12 -> 6468.0193 | AH12: =A12*'Simple Linear Regression'!$B$18+'Simple Linear Regression'!$B$17 -> 7894.7198 | AI12: =7491.3971+0.0137554*N12-0.00058829*E12-34.3283*V12+0.30565*L12+54.6031*M12 -> 7490.4026 | AJ12: =7491.3971-0.00058829*E12+0.30565*L12+54.6031*M12+0.0137554*N12-34.3283*V12 -> 7490.4026 | AL12: =2192.59+2373.87*I12+0.0316653*N12-15.7623*V12+0.00202406*AA12-0.000740146*E12-0.00963493*(I12*N12) -> 6353.2476 | AM12: =5205.907083+122.0638992*I12+13.609808*(N12/1000)-1.245906883*AD12+0.7746840854*AE12-134.2474226*AC12-1547.125689*IF(AND(B12>=DATE(2020,3,20),B12<=DATE(2020,6,26)),1,0) -> 7357.5352 | AN12: =IF(ISNUMBER(C13),C13,AN13)-0.8328750492*(AD14-AD13)+3.274150872*(AE14-AE13)+0.7954612886*((IF(ISNUMBER(C13),C13,AN13)-IF(ISNUMBER(C12),C12,AN12))-(-0.8328750492*(AD13-AD12)+3.274150872*(AE13-AE12)))-1.394571582*AO13+0.4181414112*AO12 -> 6965.9197 | AP12: =AQ12+AR11+'ARIMAX(1,1,1) Model'!$C$19*(AR11-AR10)+'ARIMAX(1,1,1) Model'!$C$20*AS11 -> 7412.2866 | AQ12: ='ARIMAX(1,1,1) Model'!$C$6*I12+'ARIMAX(1,1,1) Model'!$C$7*N12/1000+'ARIMAX(1,1,1) Model'!$C$8*AD12+'ARIMAX(1,1,1) Model'!$C$9*AE12+'ARIMAX(1,1,1) Model'!$C$10*AC12+'ARIMAX(1,1,1) Model'!$C$11*IF(AND(B12>='ARIMAX(1,1,1) Model'!$C$25,B12<='ARIMAX(1,1,1) Model'!$C$26),1,0)+'ARIMAX(1,1,1) Model'!$C$12*E12/1000+'ARIMAX(1,1,1) Model'!$C$13*V12+'ARIMAX(1,1,1) Model'!$C$14*A12+'ARIMAX(1,1,1) Model'!$C$15*SIN(2*PI()*A12/'ARIMAX(1,1,1) Model'!$C$24)+'ARIMAX(1,1,1) Model'!$C$16*COS(2*PI()*A12/'ARIMAX(1,1,1) Model'!$C$24)+'ARIMAX(1,1,1) Model'!$C$17*SIN(4*PI()*A12/'ARIMAX(1,1,1) Model'!$C$24)+'ARIMAX(1,1,1) Model'!$C$18*COS(4*PI()*A12/'ARIMAX(1,1,1) Model'!$C$24) -> 1080.584 | AR12: =IF(ISNUMBER(C12),C12,AP12)-AQ12 -> 5964.416 | AS12: =IF(ISNUMBER(C12),C12-AP12,0) -> -367.28664
A13: 12 | B13: 33354 | C13: 6956 | E13: 478000 | G13: 21.188 | H13: 19.632 | I13: 1.09 | L13: 984 | M13: 12.848 | N13: 153351 | O13: 3866.7 | V13: 82.5 | AC13: 0 | AD13: 64.9 | AE13: 9.9 | AG13: =6753.47943187+0.36116788*I13+0.01252571*N13-22.85359542*V13+0.00407811*AA13-0.00067349*E13 -> 6467.3534 | AH13: =A13*'Simple Linear Regression'!$B$18+'Simple Linear Regression'!$B$17 -> 7895.5728 | AI13: =7491.3971+0.0137554*N13-0.00058829*E13-34.3283*V13+0.30565*L13+54.6031*M13 -> 7489.8143 | AJ13: =7491.3971-0.00058829*E13+0.30565*L13+54.6031*M13+0.0137554*N13-34.3283*V13 -> 7489.8143 | AL13: =2192.59+2373.87*I13+0.0316653*N13-15.7623*V13+0.00202406*AA13-0.000740146*E13-0.00963493*(I13*N13) -> 6371.3307 | AM13: =5205.907083+122.0638992*I13+13.609808*(N13/1000)-1.245906883*AD13+0.7746840854*AE13-134.2474226*AC13-1547.125689*IF(AND(B13>=DATE(2020,3,20),B13<=DATE(2020,6,26)),1,0) -> 7352.8444 | AN13: =IF(ISNUMBER(C14),C14,AN14)-0.8328750492*(AD15-AD14)+3.274150872*(AE15-AE14)+0.7954612886*((IF(ISNUMBER(C14),C14,AN14)-IF(ISNUMBER(C13),C13,AN13))-(-0.8328750492*(AD14-AD13)+3.274150872*(AE14-AE13)))-1.394571582*AO14+0.4181414112*AO13 -> 6934.3358 | AP13: =AQ13+AR12+'ARIMAX(1,1,1) Model'!$C$19*(AR12-AR11)+'ARIMAX(1,1,1) Model'!$C$20*AS12 -> 7418.0548 | AQ13: ='ARIMAX(1,1,1) Model'!$C$6*I13+'ARIMAX(1,1,1) Model'!$C$7*N13/1000+'ARIMAX(1,1,1) Model'!$C$8*AD13+'ARIMAX(1,1,1) Model'!$C$9*AE13+'ARIMAX(1,1,1) Model'!$C$10*AC13+'ARIMAX(1,1,1) Model'!$C$11*IF(AND(B13>='ARIMAX(1,1,1) Model'!$C$25,B13<='ARIMAX(1,1,1) Model'!$C$26),1,0)+'ARIMAX(1,1,1) Model'!$C$12*E13/1000+'ARIMAX(1,1,1) Model'!$C$13*V13+'ARIMAX(1,1,1) Model'!$C$14*A13+'ARIMAX(1,1,1) Model'!$C$15*SIN(2*PI()*A13/'ARIMAX(1,1,1) Model'!$C$24)+'ARIMAX(1,1,1) Model'!$C$16*COS(2*PI()*A13/'ARIMAX(1,1,1) Model'!$C$24)+'ARIMAX(1,1,1) Model'!$C$17*SIN(4*PI()*A13/'ARIMAX(1,1,1) Model'!$C$24)+'ARIMAX(1,1,1) Model'!$C$18*COS(4*PI()*A13/'ARIMAX(1,1,1) Model'!$C$24) -> 1115.5673 | AR13: =IF(ISNUMBER(C13),C13,AP13)-AQ13 -> 5840.4327 | AS13: =IF(ISNUMBER(C13),C13-AP13,0) -> -462.05481
A14: 13 | B14: 33361 | C14: 6976 | E14: 462000 | G14: 21.234 | H14: 19.72 | I14: 1.104 | L14: 984 | M14: 12.848 | N14: 153351 | O14: 3866.7 | V14: 82.5 | AC14: 0 | AD14: 30.2 | AE14: 21.4 | AG14: =6753.47943187+0.36116788*I14+0.01252571*N14-22.85359542*V14+0.00407811*AA14-0.00067349*E14 -> 6478.1343 | AH14: =A14*'Simple Linear Regression'!$B$18+'Simple Linear Regression'!$B$17 -> 7896.4258 | AI14: =7491.3971+0.0137554*N14-0.00058829*E14-34.3283*V14+0.30565*L14+54.6031*M14 -> 7499.2269 | AJ14: =7491.3971-0.00058829*E14+0.30565*L14+54.6031*M14+0.0137554*N14-34.3283*V14 -> 7499.2269 | AL14: =2192.59+2373.87*I14+0.0316653*N14-15.7623*V14+0.00202406*AA14-0.000740146*E14-0.00963493*(I14*N14) -> 6395.7218 | AM14: =5205.907083+122.0638992*I14+13.609808*(N14/1000)-1.245906883*AD14+0.7746840854*AE14-134.2474226*AC14-1547.125689*IF(AND(B14>=DATE(2020,3,20),B14<=DATE(2020,6,26)),1,0) -> 7406.6951 | AN14: =IF(ISNUMBER(C15),C15,AN15)-0.8328750492*(AD16-AD15)+3.274150872*(AE16-AE15)+0.7954612886*((IF(ISNUMBER(C15),C15,AN15)-IF(ISNUMBER(C14),C14,AN14))-(-0.8328750492*(AD15-AD14)+3.274150872*(AE15-AE14)))-1.394571582*AO15+0.4181414112*AO14 -> 7450.0587 | AP14: =AQ14+AR13+'ARIMAX(1,1,1) Model'!$C$19*(AR13-AR12)+'ARIMAX(1,1,1) Model'!$C$20*AS13 -> 7426.8074 | AQ14: ='ARIMAX(1,1,1) Model'!$C$6*I14+'ARIMAX(1,1,1) Model'!$C$7*N14/1000+'ARIMAX(1,1,1) Model'!$C$8*AD14+'ARIMAX(1,1,1) Model'!$C$9*AE14+'ARIMAX(1,1,1) Model'!$C$10*AC14+'ARIMAX(1,1,1) Model'!$C$11*IF(AND(B14>='ARIMAX(1,1,1) Model'!$C$25,B14<='ARIMAX(1,1,1) Model'!$C$26),1,0)+'ARIMAX(1,1,1) Model'!$C$12*E14/1000+'ARIMAX(1,1,1) Model'!$C$13*V14+'ARIMAX(1,1,1) Model'!$C$14*A14+'ARIMAX(1,1,1) Model'!$C$15*SIN(2*PI()*A14/'ARIMAX(1,1,1) Model'!$C$24)+'ARIMAX(1,1,1) Model'!$C$16*COS(2*PI()*A14/'ARIMAX(1,1,1) Model'!$C$24)+'ARIMAX(1,1,1) Model'!$C$17*SIN(4*PI()*A14/'ARIMAX(1,1,1) Model'!$C$24)+'ARIMAX(1,1,1) Model'!$C$18*COS(4*PI()*A14/'ARIMAX(1,1,1) Model'!$C$24) -> 1182.5791 | AR14: =IF(ISNUMBER(C14),C14,AP14)-AQ14 -> 5793.4209 | AS14: =IF(ISNUMBER(C14),C14-AP14,0) -> -450.80736
A15: 14 | B15: 33368 | C15: 7185 | E15: 451000 | G15: 21.69 | H15: 19.812 | I15: 1.113 | J15: 6035.178 | L15: 929 | M15: 12.848 | N15: 153351 | O15: 3913 | V15: 84.4 | AC15: 0 | AD15: 27.9 | AE15: 19.4 | AG15: =6753.47943187+0.36116788*I15+0.01252571*N15-22.85359542*V15+0.00407811*AA15-0.00067349*E15 -> 6442.1241 | AH15: =A15*'Simple Linear Regression'!$B$18+'Simple Linear Regression'!$B$17 -> 7897.2789 | AI15: =7491.3971+0.0137554*N15-0.00058829*E15-34.3283*V15+0.30565*L15+54.6031*M15 -> 7423.6636 | AJ15: =7491.3971-0.00058829*E15+0.30565*L15+54.6031*M15+0.0137554*N15-34.3283*V15 -> 7423.6636 | AL15: =2192.59+2373.87*I15+0.0316653*N15-15.7623*V15+0.00202406*AA15-0.000740146*E15-0.00963493*(I15*N15) -> 6381.9822 | AM15: =5205.907083+122.0638992*I15+13.609808*(N15/1000)-1.245906883*AD15+0.7746840854*AE15-134.2474226*AC15-1547.125689*IF(AND(B15>=DATE(2020,3,20),B15<=DATE(2020,6,26)),1,0) -> 7409.1099 | AN15: =IF(ISNUMBER(C16),C16,AN16)-0.8328750492*(AD17-AD16)+3.274150872*(AE17-AE16)+0.7954612886*((IF(ISNUMBER(C16),C16,AN16)-IF(ISNUMBER(C15),C15,AN15))-(-0.8328750492*(AD16-AD15)+3.274150872*(AE16-AE15)))-1.394571582*AO16+0.4181414112*AO15 -> 6551.7146 | AP15: =AQ15+AR14+'ARIMAX(1,1,1) Model'!$C$19*(AR14-AR13)+'ARIMAX(1,1,1) Model'!$C$20*AS14 -> 7445.1868 | AQ15: ='ARIMAX(1,1,1) Model'!$C$6*I15+'ARIMAX(1,1,1) Model'!$C$7*N15/1000+'ARIMAX(1,1,1) Model'!$C$8*AD15+'ARIMAX(1,1,1) Model'!$C$9*AE15+'ARIMAX(1,1,1) Model'!$C$10*AC15+'ARIMAX(1,1,1) Model'!$C$11*IF(AND(B15>='ARIMAX(1,1,1) Model'!$C$25,B15<='ARIMAX(1,1,1) Model'!$C$26),1,0)+'ARIMAX(1,1,1) Model'!$C$12*E15/1000+'ARIMAX(1,1,1) Model'!$C$13*V15+'ARIMAX(1,1,1) Model'!$C$14*A15+'ARIMAX(1,1,1) Model'!$C$15*SIN(2*PI()*A15/'ARIMAX(1,1,1) Model'!$C$24)+'ARIMAX(1,1,1) Model'!$C$16*COS(2*PI()*A15/'ARIMAX(1,1,1) Model'!$C$24)+'ARIMAX(1,1,1) Model'!$C$17*SIN(4*PI()*A15/'ARIMAX(1,1,1) Model'!$C$24)+'ARIMAX(1,1,1) Model'!$C$18*COS(4*PI()*A15/'ARIMAX(1,1,1) Model'!$C$24) -> 1250.5868 | AR15: =IF(ISNUMBER(C15),C15,AP15)-AQ15 -> 5934.4132 | AS15: =IF(ISNUMBER(C15),C15-AP15,0) -> -260.1868
A16: 15 | B16: 33375 | C16: 6899 | E16: 446000 | G16: 20.952 | H16: 18.9 | I16: 1.121 | J16: 6035.178 | L16: 929 | M16: 12.038 | N16: 179076 | O16: 3913 | V16: 84.4 | AC16: 0 | AD16: 4.5 | AE16: 42.5 | AG16: =6753.47943187+0.36116788*I16+0.01252571*N16-22.85359542*V16+0.00407811*AA16-0.00067349*E16 -> 6767.7184 | AH16: =A16*'Simple Linear Regression'!$B$18+'Simple Linear Regression'!$B$17 -> 7898.1319 | AI16: =7491.3971+0.0137554*N16-0.00058829*E16-34.3283*V16+0.30565*L16+54.6031*M16 -> 7736.2342 | AJ16: =7491.3971-0.00058829*E16+0.30565*L16+54.6031*M16+0.0137554*N16-34.3283*V16 -> 7736.2342 | AL16: =2192.59+2373.87*I16+0.0316653*N16-15.7623*V16+0.00202406*AA16-0.000740146*E16-0.00963493*(I16*N16) -> 6929.594 | AM16: =5205.907083+122.0638992*I16+13.609808*(N16/1000)-1.245906883*AD16+0.7746840854*AE16-134.2474226*AC16-1547.125689*IF(AND(B16>=DATE(2020,3,20),B16<=DATE(2020,6,26)),1,0) -> 7807.2482 | AN16: =IF(ISNUMBER(C17),C17,AN17)-0.8328750492*(AD18-AD17)+3.274150872*(AE18-AE17)+0.7954612886*((IF(ISNUMBER(C17),C17,AN17)-IF(ISNUMBER(C16),C16,AN16))-(-0.8328750492*(AD17-AD16)+3.274150872*(AE17-AE16)))-1.394571582*AO17+0.4181414112*AO16 -> 7957.9868 | AP16: =AQ16+AR15+'ARIMAX(1,1,1) Model'!$C$19*(AR15-AR14)+'ARIMAX(1,1,1) Model'!$C$20*AS15 -> 7541.1047 | AQ16: ='ARIMAX(1,1,1) Model'!$C$6*I16+'ARIMAX(1,1,1) Model'!$C$7*N16/1000+'ARIMAX(1,1,1) Model'!$C$8*AD16+'ARIMAX(1,1,1) Model'!$C$9*AE16+'ARIMAX(1,1,1) Model'!$C$10*AC16+'ARIMAX(1,1,1) Model'!$C$11*IF(AND(B16>='ARIMAX(1,1,1) Model'!$C$25,B16<='ARIMAX(1,1,1) Model'!$C$26),1,0)+'ARIMAX(1,1,1) Model'!$C$12*E16/1000+'ARIMAX(1,1,1) Model'!$C$13*V16+'ARIMAX(1,1,1) Model'!$C$14*A16+'ARIMAX(1,1,1) Model'!$C$15*SIN(2*PI()*A16/'ARIMAX(1,1,1) Model'!$C$24)+'ARIMAX(1,1,1) Model'!$C$16*COS(2*PI()*A16/'ARIMAX(1,1,1) Model'!$C$24)+'ARIMAX(1,1,1) Model'!$C$17*SIN(4*PI()*A16/'ARIMAX(1,1,1) Model'!$C$24)+'ARIMAX(1,1,1) Model'!$C$18*COS(4*PI()*A16/'ARIMAX(1,1,1) Model'!$C$24) -> 1358.7504 | AR16: =IF(ISNUMBER(C16),C16,AP16)-AQ16 -> 5540.2496 | AS16: =IF(ISNUMBER(C16),C16-AP16,0) -> -642.10473
A17: 16 | B17: 33382 | C17: 7396 | E17: 448000 | G17: 21.036 | H17: 18.824 | I17: 1.129 | J17: 6035.178 | L17: 929 | M17: 12.038 | N17: 179076 | O17: 3913 | V17: 84.4 | AC17: 0 | AD17: 15.8 | AE17: 31.9 | AG17: =6753.47943187+0.36116788*I17+0.01252571*N17-22.85359542*V17+0.00407811*AA17-0.00067349*E17 -> 6766.3743 | AH17: =A17*'Simple Linear Regression'!$B$18+'Simple Linear Regression'!$B$17 -> 7898.9849 | AI17: =7491.3971+0.0137554*N17-0.00058829*E17-34.3283*V17+0.30565*L17+54.6031*M17 -> 7735.0576 | AJ17: =7491.3971-0.00058829*E17+0.30565*L17+54.6031*M17+0.0137554*N17-34.3283*V17 -> 7735.0576 | AL17: =2192.59+2373.87*I17+0.0316653*N17-15.7623*V17+0.00202406*AA17-0.000740146*E17-0.00963493*(I17*N17) -> 6933.3016 | AM17: =5205.907083+122.0638992*I17+13.609808*(N17/1000)-1.245906883*AD17+0.7746840854*AE17-134.2474226*AC17-1547.125689*IF(AND(B17>=DATE(2020,3,20),B17<=DATE(2020,6,26)),1,0) -> 7785.9343 | AN17: =IF(ISNUMBER(C18),C18,AN18)-0.8328750492*(AD19-AD18)+3.274150872*(AE19-AE18)+0.7954612886*((IF(ISNUMBER(C18),C18,AN18)-IF(ISNUMBER(C17),C17,AN17))-(-0.8328750492*(AD18-AD17)+3.274150872*(AE18-AE17)))-1.394571582*AO18+0.4181414112*AO17 -> 7022.6392 | AP17: =AQ17+AR16+'ARIMAX(1,1,1) Model'!$C$19*(AR16-AR15)+'ARIMAX(1,1,1) Model'!$C$20*AS16 -> 7432.5921 | AQ17: ='ARIMAX(1,1,1) Model'!$C$6*I17+'ARIMAX(1,1,1) Model'!$C$7*N17/1000+'ARIMAX(1,1,1) Model'!$C$8*AD17+'ARIMAX(1,1,1) Model'!$C$9*AE17+'ARIMAX(1,1,1) Model'!$C$10*AC17+'ARIMAX(1,1,1) Model'!$C$11*IF(AND(B17>='ARIMAX(1,1,1) Model'!$C$25,B17<='ARIMAX(1,1,1) Model'!$C$26),1,0)+'ARIMAX(1,1,1) Model'!$C$12*E17/1000+'ARIMAX(1,1,1) Model'!$C$13*V17+'ARIMAX(1,1,1) Model'!$C$14*A17+'ARIMAX(1,1,1) Model'!$C$15*SIN(2*PI()*A17/'ARIMAX(1,1,1) Model'!$C$24)+'ARIMAX(1,1,1) Model'!$C$16*COS(2*PI()*A17/'ARIMAX(1,1,1) Model'!$C$24)+'ARIMAX(1,1,1) Model'!$C$17*SIN(4*PI()*A17/'ARIMAX(1,1,1) Model'!$C$24)+'ARIMAX(1,1,1) Model'!$C$18*COS(4*PI()*A17/'ARIMAX(1,1,1) Model'!$C$24) -> 1352.8381 | AR17: =IF(ISNUMBER(C17),C17,AP17)-AQ17 -> 6043.1619 | AS17: =IF(ISNUMBER(C17),C17-AP17,0) -> -36.592074
A18: 17 | B18: 33389 | C18: 7287 | E18: 443000 | G18: 21.21 | H18: 18.87 | I18: 1.14 | J18: 6035.178 | L18: 929 | M18: 12.038 | N18: 179076 | O18: 3913 | V18: 84.4 | AC18: 1 | AD18: 3.7 | AE18: 69 | AG18: =6753.47943187+0.36116788*I18+0.01252571*N18-22.85359542*V18+0.00407811*AA18-0.00067349*E18 -> 6769.7457 | AH18: =A18*'Simple Linear Regression'!$B$18+'Simple Linear Regression'!$B$17 -> 7899.838 | AI18: =7491.3971+0.0137554*N18-0.00058829*E18-34.3283*V18+0.30565*L18+54.6031*M18 -> 7737.9991 | AJ18: =7491.3971-0.00058829*E18+0.30565*L18+54.6031*M18+0.0137554*N18-34.3283*V18 -> 7737.9991 | AL18: =2192.59+2373.87*I18+0.0316653*N18-15.7623*V18+0.00202406*AA18-0.000740146*E18-0.00963493*(I18*N18) -> 6944.1357 | AM18: =5205.907083+122.0638992*I18+13.609808*(N18/1000)-1.245906883*AD18+0.7746840854*AE18-134.2474226*AC18-1547.125689*IF(AND(B18>=DATE(2020,3,20),B18<=DATE(2020,6,26)),1,0) -> 7696.8458 | AN18: =IF(ISNUMBER(C19),C19,AN19)-0.8328750492*(AD20-AD19)+3.274150872*(AE20-AE19)+0.7954612886*((IF(ISNUMBER(C19),C19,AN19)-IF(ISNUMBER(C18),C18,AN18))-(-0.8328750492*(AD19-AD18)+3.274150872*(AE19-AE18)))-1.394571582*AO19+0.4181414112*AO18 -> 7259.4579 | AP18: =AQ18+AR17+'ARIMAX(1,1,1) Model'!$C$19*(AR17-AR16)+'ARIMAX(1,1,1) Model'!$C$20*AS17 -> 7485.4494 | AQ18: ='ARIMAX(1,1,1) Model'!$C$6*I18+'ARIMAX(1,1,1) Model'!$C$7*N18/1000+'ARIMAX(1,1,1) Model'!$C$8*AD18+'ARIMAX(1,1,1) Model'!$C$9*AE18+'ARIMAX(1,1,1) Model'!$C$10*AC18+'ARIMAX(1,1,1) Model'!$C$11*IF(AND(B18>='ARIMAX(1,1,1) Model'!$C$25,B18<='ARIMAX(1,1,1) Model'!$C$26),1,0)+'ARIMAX(1,1,1) Model'!$C$12*E18/1000+'ARIMAX(1,1,1) Model'!$C$13*V18+'ARIMAX(1,1,1) Model'!$C$14*A18+'ARIMAX(1,1,1) Model'!$C$15*SIN(2*PI()*A18/'ARIMAX(1,1,1) Model'!$C$24)+'ARIMAX(1,1,1) Model'!$C$16*COS(2*PI()*A18/'ARIMAX(1,1,1) Model'!$C$24)+'ARIMAX(1,1,1) Model'!$C$17*SIN(4*PI()*A18/'ARIMAX(1,1,1) Model'!$C$24)+'ARIMAX(1,1,1) Model'!$C$18*COS(4*PI()*A18/'ARIMAX(1,1,1) Model'!$C$24) -> 1360.3016 | AR18: =IF(ISNUMBER(C18),C18,AP18)-AQ18 -> 5926.6984 | AS18: =IF(ISNUMBER(C18),C18-AP18,0) -> -198.44936
A19: 18 | B19: 33396 | C19: 7220 | E19: 432000 | G19: 20.634 | H19: 18.554 | I19: 1.138 | J19: 6035.178 | L19: 865 | M19: 12.038 | N19: 179076 | O19: 3907.1 | V19: 83.2 | AC19: 0 | AD19: 3.7 | AE19: 46.7 | AG19: =6753.47943187+0.36116788*I19+0.01252571*N19-22.85359542*V19+0.00407811*AA19-0.00067349*E19 -> 6804.5777 | AH19: =A19*'Simple Linear Regression'!$B$18+'Simple Linear Regression'!$B$17 -> 7900.691 | AI19: =7491.3971+0.0137554*N19-0.00058829*E19-34.3283*V19+0.30565*L19+54.6031*M19 -> 7766.1026 | AJ19: =7491.3971-0.00058829*E19+0.30565*L19+54.6031*M19+0.0137554*N19-34.3283*V19 -> 7766.1026 | AL19: =2192.59+2373.87*I19+0.0316653*N19-15.7623*V19+0.00202406*AA19-0.000740146*E19-0.00963493*(I19*N19) -> 6969.8951 | AM19: =5205.907083+122.0638992*I19+13.609808*(N19/1000)-1.245906883*AD19+0.7746840854*AE19-134.2474226*AC19-1547.125689*IF(AND(B19>=DATE(2020,3,20),B19<=DATE(2020,6,26)),1,0) -> 7813.5737 | AN19: =IF(ISNUMBER(C20),C20,AN20)-0.8328750492*(AD21-AD20)+3.274150872*(AE21-AE20)+0.7954612886*((IF(ISNUMBER(C20),C20,AN20)-IF(ISNUMBER(C19),C19,AN19))-(-0.8328750492*(AD20-AD19)+3.274150872*(AE20-AE19)))-1.394571582*AO20+0.4181414112*AO19 -> 8008.8257 | AP19: =AQ19+AR18+'ARIMAX(1,1,1) Model'!$C$19*(AR18-AR17)+'ARIMAX(1,1,1) Model'!$C$20*AS18 -> 7489.183 | AQ19: ='ARIMAX(1,1,1) Model'!$C$6*I19+'ARIMAX(1,1,1) Model'!$C$7*N19/1000+'ARIMAX(1,1,1) Model'!$C$8*AD19+'ARIMAX(1,1,1) Model'!$C$9*AE19+'ARIMAX(1,1,1) Model'!$C$10*AC19+'ARIMAX(1,1,1) Model'!$C$11*IF(AND(B19>='ARIMAX(1,1,1) Model'!$C$25,B19<='ARIMAX(1,1,1) Model'!$C$26),1,0)+'ARIMAX(1,1,1) Model'!$C$12*E19/1000+'ARIMAX(1,1,1) Model'!$C$13*V19+'ARIMAX(1,1,1) Model'!$C$14*A19+'ARIMAX(1,1,1) Model'!$C$15*SIN(2*PI()*A19/'ARIMAX(1,1,1) Model'!$C$24)+'ARIMAX(1,1,1) Model'!$C$16*COS(2*PI()*A19/'ARIMAX(1,1,1) Model'!$C$24)+'ARIMAX(1,1,1) Model'!$C$17*SIN(4*PI()*A19/'ARIMAX(1,1,1) Model'!$C$24)+'ARIMAX(1,1,1) Model'!$C$18*COS(4*PI()*A19/'ARIMAX(1,1,1) Model'!$C$24) -> 1395.2226 | AR19: =IF(ISNUMBER(C19),C19,AP19)-AQ19 -> 5824.7774 | AS19: =IF(ISNUMBER(C19),C19-AP19,0) -> -269.18305
A20: 19 | B20: 33403 | C20: 7651 | E20: 441000 | G20: 19.836 | H20: 17.856 | I20: 1.135 | J20: 6035.178 | L20: 865 | M20: 12.038 | N20: 179076 | O20: 3907.1 | V20: 83.2 | AC20: 0 | AD20: 0.2 | AE20: 56.4 | AG20: =6753.47943187+0.36116788*I20+0.01252571*N20-22.85359542*V20+0.00407811*AA20-0.00067349*E20 -> 6798.5152 | AH20: =A20*'Simple Linear Regression'!$B$18+'Simple Linear Regression'!$B$17 -> 7901.5441 | AI20: =7491.3971+0.0137554*N20-0.00058829*E20-34.3283*V20+0.30565*L20+54.6031*M20 -> 7760.808 | AJ20: =7491.3971-0.00058829*E20+0.30565*L20+54.6031*M20+0.0137554*N20-34.3283*V20 -> 7760.808 | AL20: =2192.59+2373.87*I20+0.0316653*N20-15.7623*V20+0.00202406*AA20-0.000740146*E20-0.00963493*(I20*N20) -> 6961.2883 | AM20: =5205.907083+122.0638992*I20+13.609808*(N20/1000)-1.245906883*AD20+0.7746840854*AE20-134.2474226*AC20-1547.125689*IF(AND(B20>=DATE(2020,3,20),B20<=DATE(2020,6,26)),1,0) -> 7825.0826 | AN20: =IF(ISNUMBER(C21),C21,AN21)-0.8328750492*(AD22-AD21)+3.274150872*(AE22-AE21)+0.7954612886*((IF(ISNUMBER(C21),C21,AN21)-IF(ISNUMBER(C20),C20,AN20))-(-0.8328750492*(AD21-AD20)+3.274150872*(AE21-AE20)))-1.394571582*AO21+0.4181414112*AO20 -> 7700.2571 | AP20: =AQ20+AR19+'ARIMAX(1,1,1) Model'!$C$19*(AR19-AR18)+'ARIMAX(1,1,1) Model'!$C$20*AS19 -> 7468.2031 | AQ20: ='ARIMAX(1,1,1) Model'!$C$6*I20+'ARIMAX(1,1,1) Model'!$C$7*N20/1000+'ARIMAX(1,1,1) Model'!$C$8*AD20+'ARIMAX(1,1,1) Model'!$C$9*AE20+'ARIMAX(1,1,1) Model'!$C$10*AC20+'ARIMAX(1,1,1) Model'!$C$11*IF(AND(B20>='ARIMAX(1,1,1) Model'!$C$25,B20<='ARIMAX(1,1,1) Model'!$C$26),1,0)+'ARIMAX(1,1,1) Model'!$C$12*E20/1000+'ARIMAX(1,1,1) Model'!$C$13*V20+'ARIMAX(1,1,1) Model'!$C$14*A20+'ARIMAX(1,1,1) Model'!$C$15*SIN(2*PI()*A20/'ARIMAX(1,1,1) Model'!$C$24)+'ARIMAX(1,1,1) Model'!$C$16*COS(2*PI()*A20/'ARIMAX(1,1,1) Model'!$C$24)+'ARIMAX(1,1,1) Model'!$C$17*SIN(4*PI()*A20/'ARIMAX(1,1,1) Model'!$C$24)+'ARIMAX(1,1,1) Model'!$C$18*COS(4*PI()*A20/'ARIMAX(1,1,1) Model'!$C$24) -> 1411.079 | AR20: =IF(ISNUMBER(C20),C20,AP20)-AQ20 -> 6239.921 | AS20: =IF(ISNUMBER(C20),C20-AP20,0) -> 182.79688
A21: 20 | B21: 33410 | C21: 7720 | E21: 429000 | G21: 20.078 | H21: 18.062 | I21: 1.126 | J21: 6035.178 | L21: 865 | M21: 12.487 | N21: 179538 | O21: 3907.1 | P21: 824860 | V21: 83.2 | AC21: 0 | AD21: 0.2 | AE21: 69.4 | AG21: =6753.47943187+0.36116788*I21+0.01252571*N21-22.85359542*V21+0.00407811*AA21-0.00067349*E21 -> 6812.3807 | AH21: =A21*'Simple Linear Regression'!$B$18+'Simple Linear Regression'!$B$17 -> 7902.3971 | AI21: =7491.3971+0.0137554*N21-0.00058829*E21-34.3283*V21+0.30565*L21+54.6031*M21 -> 7798.7393 | AJ21: =7491.3971-0.00058829*E21+0.30565*L21+54.6031*M21+0.0137554*N21-34.3283*V21 -> 7798.7393 | AL21: =2192.59+2373.87*I21+0.0316653*N21-15.7623*V21+0.00202406*AA21-0.000740146*E21-0.00963493*(I21*N21) -> 6973.9509 | AM21: =5205.907083+122.0638992*I21+13.609808*(N21/1000)-1.245906883*AD21+0.7746840854*AE21-134.2474226*AC21-1547.125689*IF(AND(B21>=DATE(2020,3,20),B21<=DATE(2020,6,26)),1,0) -> 7840.3426 | AN21: =IF(ISNUMBER(C22),C22,AN22)-0.8328750492*(AD23-AD22)+3.274150872*(AE23-AE22)+0.7954612886*((IF(ISNUMBER(C22),C22,AN22)-IF(ISNUMBER(C21),C21,AN21))-(-0.8328750492*(AD22-AD21)+3.274150872*(AE22-AE21)))-1.394571582*AO22+0.4181414112*AO21 -> 7538.7652 | AP21: =AQ21+AR20+'ARIMAX(1,1,1) Model'!$C$19*(AR20-AR19)+'ARIMAX(1,1,1) Model'!$C$20*AS20 -> 7563.6902 | AQ21: ='ARIMAX(1,1,1) Model'!$C$6*I21+'ARIMAX(1,1,1) Model'!$C$7*N21/1000+'ARIMAX(1,1,1) Model'!$C$8*AD21+'ARIMAX(1,1,1) Model'!$C$9*AE21+'ARIMAX(1,1,1) Model'!$C$10*AC21+'ARIMAX(1,1,1) Model'!$C$11*IF(AND(B21>='ARIMAX(1,1,1) Model'!$C$25,B21<='ARIMAX(1,1,1) Model'!$C$26),1,0)+'ARIMAX(1,1,1) Model'!$C$12*E21/1000+'ARIMAX(1,1,1) Model'!$C$13*V21+'ARIMAX(1,1,1) Model'!$C$14*A21+'ARIMAX(1,1,1) Model'!$C$15*SIN(2*PI()*A21/'ARIMAX(1,1,1) Model'!$C$24)+'ARIMAX(1,1,1) Model'!$C$16*COS(2*PI()*A21/'ARIMAX(1,1,1) Model'!$C$24)+'ARIMAX(1,1,1) Model'!$C$17*SIN(4*PI()*A21/'ARIMAX(1,1,1) Model'!$C$24)+'ARIMAX(1,1,1) Model'!$C$18*COS(4*PI()*A21/'ARIMAX(1,1,1) Model'!$C$24) -> 1447.812 | AR21: =IF(ISNUMBER(C21),C21,AP21)-AQ21 -> 6272.188 | AS21: =IF(ISNUMBER(C21),C21-AP21,0) -> 156.30983
A22: 21 | B22: 33417 | C22: 7543 | E22: 423000 | G22: 20.208 | H22: 18.198 | I22: 1.114 | J22: 6035.178 | L22: 865 | M22: 12.487 | N22: 179538 | O22: 3907.1 | P22: 824860 | V22: 83.2 | AC22: 0 | AD22: 0.8 | AE22: 57.1 | AG22: =6753.47943187+0.36116788*I22+0.01252571*N22-22.85359542*V22+0.00407811*AA22-0.00067349*E22 -> 6816.4173 | AH22: =A22*'Simple Linear Regression'!$B$18+'Simple Linear Regression'!$B$17 -> 7903.2501 | AI22: =7491.3971+0.0137554*N22-0.00058829*E22-34.3283*V22+0.30565*L22+54.6031*M22 -> 7802.269 | AJ22: =7491.3971-0.00058829*E22+0.30565*L22+54.6031*M22+0.0137554*N22-34.3283*V22 -> 7802.269 | AL22: =2192.59+2373.87*I22+0.0316653*N22-15.7623*V22+0.00202406*AA22-0.000740146*E22-0.00963493*(I22*N22) -> 6970.6633 | AM22: =5205.907083+122.0638992*I22+13.609808*(N22/1000)-1.245906883*AD22+0.7746840854*AE22-134.2474226*AC22-1547.125689*IF(AND(B22>=DATE(2020,3,20),B22<=DATE(2020,6,26)),1,0) -> 7828.6017 | AN22: =IF(ISNUMBER(C23),C23,AN23)-0.8328750492*(AD24-AD23)+3.274150872*(AE24-AE23)+0.7954612886*((IF(ISNUMBER(C23),C23,AN23)-IF(ISNUMBER(C22),C22,AN22))-(-0.8328750492*(AD23-AD22)+3.274150872*(AE23-AE22)))-1.394571582*AO23+0.4181414112*AO22 -> 8192.664 | AP22: =AQ22+AR21+'ARIMAX(1,1,1) Model'!$C$19*(AR21-AR20)+'ARIMAX(1,1,1) Model'!$C$20*AS21 -> 7533.0678 | AQ22: ='ARIMAX(1,1,1) Model'!$C$6*I22+'ARIMAX(1,1,1) Model'!$C$7*N22/1000+'ARIMAX(1,1,1) Model'!$C$8*AD22+'ARIMAX(1,1,1) Model'!$C$9*AE22+'ARIMAX(1,1,1) Model'!$C$10*AC22+'ARIMAX(1,1,1) Model'!$C$11*IF(AND(B22>='ARIMAX(1,1,1) Model'!$C$25,B22<='ARIMAX(1,1,1) Model'!$C$26),1,0)+'ARIMAX(1,1,1) Model'!$C$12*E22/1000+'ARIMAX(1,1,1) Model'!$C$13*V22+'ARIMAX(1,1,1) Model'!$C$14*A22+'ARIMAX(1,1,1) Model'!$C$15*SIN(2*PI()*A22/'ARIMAX(1,1,1) Model'!$C$24)+'ARIMAX(1,1,1) Model'!$C$16*COS(2*PI()*A22/'ARIMAX(1,1,1) Model'!$C$24)+'ARIMAX(1,1,1) Model'!$C$17*SIN(4*PI()*A22/'ARIMAX(1,1,1) Model'!$C$24)+'ARIMAX(1,1,1) Model'!$C$18*COS(4*PI()*A22/'ARIMAX(1,1,1) Model'!$C$24) -> 1398.4246 | AR22: =IF(ISNUMBER(C22),C22,AP22)-AQ22 -> 6144.5754 | AS22: =IF(ISNUMBER(C22),C22-AP22,0) -> 9.9322033
A23: 22 | B23: 33424 | C23: 7961 | E23: 418000 | G23: 20.798 | H23: 18.552 | I23: 1.104 | J23: 6035.178 | L23: 865 | M23: 12.487 | N23: 179538 | O23: 3907.1 | P23: 824860 | V23: 84.6 | AC23: 1 | AD23: 0 | AE23: 88.7 | AG23: =6753.47943187+0.36116788*I23+0.01252571*N23-22.85359542*V23+0.00407811*AA23-0.00067349*E23 -> 6787.7861 | AH23: =A23*'Simple Linear Regression'!$B$18+'Simple Linear Regression'!$B$17 -> 7904.1032 | AI23: =7491.3971+0.0137554*N23-0.00058829*E23-34.3283*V23+0.30565*L23+54.6031*M23 -> 7757.1509 | AJ23: =7491.3971-0.00058829*E23+0.30565*L23+54.6031*M23+0.0137554*N23-34.3283*V23 -> 7757.1509 | AL23: =2192.59+2373.87*I23+0.0316653*N23-15.7623*V23+0.00202406*AA23-0.000740146*E23-0.00963493*(I23*N23) -> 6945.8565 | AM23: =5205.907083+122.0638992*I23+13.609808*(N23/1000)-1.245906883*AD23+0.7746840854*AE23-134.2474226*AC23-1547.125689*IF(AND(B23>=DATE(2020,3,20),B23<=DATE(2020,6,26)),1,0) -> 7718.6104 | AN23: =IF(ISNUMBER(C24),C24,AN24)-0.8328750492*(AD25-AD24)+3.274150872*(AE25-AE24)+0.7954612886*((IF(ISNUMBER(C24),C24,AN24)-IF(ISNUMBER(C23),C23,AN23))-(-0.8328750492*(AD24-AD23)+3.274150872*(AE24-AE23)))-1.394571582*AO24+0.4181414112*AO23 -> 6838.9666 | AP23: =AQ23+AR22+'ARIMAX(1,1,1) Model'!$C$19*(AR22-AR21)+'ARIMAX(1,1,1) Model'!$C$20*AS22 -> 7509.6822 | AQ23: ='ARIMAX(1,1,1) Model'!$C$6*I23+'ARIMAX(1,1,1) Model'!$C$7*N23/1000+'ARIMAX(1,1,1) Model'!$C$8*AD23+'ARIMAX(1,1,1) Model'!$C$9*AE23+'ARIMAX(1,1,1) Model'!$C$10*AC23+'ARIMAX(1,1,1) Model'!$C$11*IF(AND(B23>='ARIMAX(1,1,1) Model'!$C$25,B23<='ARIMAX(1,1,1) Model'!$C$26),1,0)+'ARIMAX(1,1,1) Model'!$C$12*E23/1000+'ARIMAX(1,1,1) Model'!$C$13*V23+'ARIMAX(1,1,1) Model'!$C$14*A23+'ARIMAX(1,1,1) Model'!$C$15*SIN(2*PI()*A23/'ARIMAX(1,1,1) Model'!$C$24)+'ARIMAX(1,1,1) Model'!$C$16*COS(2*PI()*A23/'ARIMAX(1,1,1) Model'!$C$24)+'ARIMAX(1,1,1) Model'!$C$17*SIN(4*PI()*A23/'ARIMAX(1,1,1) Model'!$C$24)+'ARIMAX(1,1,1) Model'!$C$18*COS(4*PI()*A23/'ARIMAX(1,1,1) Model'!$C$24) -> 1386.4929 | AR23: =IF(ISNUMBER(C23),C23,AP23)-AQ23 -> 6574.5071 | AS23: =IF(ISNUMBER(C23),C23-AP23,0) -> 451.31777
A24: 23 | B24: 33431 | C24: 7327 | E24: 422000 | G24: 21.426 | H24: 19.244 | I24: 1.098 | J24: 6035.178 | L24: 819 | M24: 12.487 | N24: 179538 | O24: 3933.2 | P24: 824860 | V24: 84.6 | AC24: 0 | AD24: 0 | AE24: 83.2 | AG24: =6753.47943187+0.36116788*I24+0.01252571*N24-22.85359542*V24+0.00407811*AA24-0.00067349*E24 -> 6785.09 | AH24: =A24*'Simple Linear Regression'!$B$18+'Simple Linear Regression'!$B$17 -> 7904.9562 | AI24: =7491.3971+0.0137554*N24-0.00058829*E24-34.3283*V24+0.30565*L24+54.6031*M24 -> 7740.7378 | AJ24: =7491.3971-0.00058829*E24+0.30565*L24+54.6031*M24+0.0137554*N24-34.3283*V24 -> 7740.7378 | AL24: =2192.59+2373.87*I24+0.0316653*N24-15.7623*V24+0.00202406*AA24-0.000740146*E24-0.00963493*(I24*N24) -> 6939.0317 | AM24: =5205.907083+122.0638992*I24+13.609808*(N24/1000)-1.245906883*AD24+0.7746840854*AE24-134.2474226*AC24-1547.125689*IF(AND(B24>=DATE(2020,3,20),B24<=DATE(2020,6,26)),1,0) -> 7847.8647 | AN24: =IF(ISNUMBER(C25),C25,AN25)-0.8328750492*(AD26-AD25)+3.274150872*(AE26-AE25)+0.7954612886*((IF(ISNUMBER(C25),C25,AN25)-IF(ISNUMBER(C24),C24,AN24))-(-0.8328750492*(AD25-AD24)+3.274150872*(AE25-AE24)))-1.394571582*AO25+0.4181414112*AO24 -> 7442.861 | AP24: =AQ24+AR23+'ARIMAX(1,1,1) Model'!$C$19*(AR23-AR22)+'ARIMAX(1,1,1) Model'!$C$20*AS23 -> 7660.0718 | AQ24: ='ARIMAX(1,1,1) Model'!$C$6*I24+'ARIMAX(1,1,1) Model'!$C$7*N24/1000+'ARIMAX(1,1,1) Model'!$C$8*AD24+'ARIMAX(1,1,1) Model'!$C$9*AE24+'ARIMAX(1,1,1) Model'!$C$10*AC24+'ARIMAX(1,1,1) Model'!$C$11*IF(AND(B24>='ARIMAX(1,1,1) Model'!$C$25,B24<='ARIMAX(1,1,1) Model'!$C$26),1,0)+'ARIMAX(1,1,1) Model'!$C$12*E24/1000+'ARIMAX(1,1,1) Model'!$C$13*V24+'ARIMAX(1,1,1) Model'!$C$14*A24+'ARIMAX(1,1,1) Model'!$C$15*SIN(2*PI()*A24/'ARIMAX(1,1,1) Model'!$C$24)+'ARIMAX(1,1,1) Model'!$C$16*COS(2*PI()*A24/'ARIMAX(1,1,1) Model'!$C$24)+'ARIMAX(1,1,1) Model'!$C$17*SIN(4*PI()*A24/'ARIMAX(1,1,1) Model'!$C$24)+'ARIMAX(1,1,1) Model'!$C$18*COS(4*PI()*A24/'ARIMAX(1,1,1) Model'!$C$24) -> 1449.8565 | AR24: =IF(ISNUMBER(C24),C24,AP24)-AQ24 -> 5877.1435 | AS24: =IF(ISNUMBER(C24),C24-AP24,0) -> -333.07178
A25: 24 | B25: 33438 | C25: 7380 | E25: 420000 | G25: 21.906 | H25: 20.024 | I25: 1.094 | J25: 6035.178 | L25: 819 | M25: 12.719 | N25: 191929 | O25: 3933.2 | P25: 824860 | V25: 84.6 | AC25: 0 | AD25: 0 | AE25: 83.8 | AG25: =6753.47943187+0.36116788*I25+0.01252571*N25-22.85359542*V25+0.00407811*AA25-0.00067349*E25 -> 6941.6416 | AH25: =A25*'Simple Linear Regression'!$B$18+'Simple Linear Regression'!$B$17 -> 7905.8092 | AI25: =7491.3971+0.0137554*N25-0.00058829*E25-34.3283*V25+0.30565*L25+54.6031*M25 -> 7925.0255 | AJ25: =7491.3971-0.00058829*E25+0.30565*L25+54.6031*M25+0.0137554*N25-34.3283*V25 -> 7925.0255 | AL25: =2192.59+2373.87*I25+0.0316653*N25-15.7623*V25+0.00202406*AA25-0.000740146*E25-0.00963493*(I25*N25) -> 7199.6919 | AM25: =5205.907083+122.0638992*I25+13.609808*(N25/1000)-1.245906883*AD25+0.7746840854*AE25-134.2474226*AC25-1547.125689*IF(AND(B25>=DATE(2020,3,20),B25<=DATE(2020,6,26)),1,0) -> 8016.4804 | AN25: =IF(ISNUMBER(C26),C26,AN26)-0.8328750492*(AD27-AD26)+3.274150872*(AE27-AE26)+0.7954612886*((IF(ISNUMBER(C26),C26,AN26)-IF(ISNUMBER(C25),C25,AN25))-(-0.8328750492*(AD26-AD25)+3.274150872*(AE26-AE25)))-1.394571582*AO26+0.4181414112*AO25 -> 7547.1264 | AP25: =AQ25+AR24+'ARIMAX(1,1,1) Model'!$C$19*(AR24-AR23)+'ARIMAX(1,1,1) Model'!$C$20*AS24 -> 7542.7428 | AQ25: ='ARIMAX(1,1,1) Model'!$C$6*I25+'ARIMAX(1,1,1) Model'!$C$7*N25/1000+'ARIMAX(1,1,1) Model'!$C$8*AD25+'ARIMAX(1,1,1) Model'!$C$9*AE25+'ARIMAX(1,1,1) Model'!$C$10*AC25+'ARIMAX(1,1,1) Model'!$C$11*IF(AND(B25>='ARIMAX(1,1,1) Model'!$C$25,B25<='ARIMAX(1,1,1) Model'!$C$26),1,0)+'ARIMAX(1,1,1) Model'!$C$12*E25/1000+'ARIMAX(1,1,1) Model'!$C$13*V25+'ARIMAX(1,1,1) Model'!$C$14*A25+'ARIMAX(1,1,1) Model'!$C$15*SIN(2*PI()*A25/'ARIMAX(1,1,1) Model'!$C$24)+'ARIMAX(1,1,1) Model'!$C$16*COS(2*PI()*A25/'ARIMAX(1,1,1) Model'!$C$24)+'ARIMAX(1,1,1) Model'!$C$17*SIN(4*PI()*A25/'ARIMAX(1,1,1) Model'!$C$24)+'ARIMAX(1,1,1) Model'!$C$18*COS(4*PI()*A25/'ARIMAX(1,1,1) Model'!$C$24) -> 1433.8218 | AR25: =IF(ISNUMBER(C25),C25,AP25)-AQ25 -> 5946.1782 | AS25: =IF(ISNUMBER(C25),C25-AP25,0) -> -162.74277
A26: 25 | B26: 33445 | C26: 7501 | E26: 408000 | G26: 21.398 | H26: 19.664 | I26: 1.091 | J26: 6035.178 | L26: 819 | M26: 12.719 | N26: 191929 | O26: 3933.2 | P26: 824860 | V26: 84.6 | AC26: 0 | AD26: 0 | AE26: 90.6 | AG26: =6753.47943187+0.36116788*I26+0.01252571*N26-22.85359542*V26+0.00407811*AA26-0.00067349*E26 -> 6949.7224 | AH26: =A26*'Simple Linear Regression'!$B$18+'Simple Linear Regression'!$B$17 -> 7906.6623 | AI26: =7491.3971+0.0137554*N26-0.00058829*E26-34.3283*V26+0.30565*L26+54.6031*M26 -> 7932.0849 | AJ26: =7491.3971-0.00058829*E26+0.30565*L26+54.6031*M26+0.0137554*N26-34.3283*V26 -> 7932.0849 | AL26: =2192.59+2373.87*I26+0.0316653*N26-15.7623*V26+0.00202406*AA26-0.000740146*E26-0.00963493*(I26*N26) -> 7206.9997 | AM26: =5205.907083+122.0638992*I26+13.609808*(N26/1000)-1.245906883*AD26+0.7746840854*AE26-134.2474226*AC26-1547.125689*IF(AND(B26>=DATE(2020,3,20),B26<=DATE(2020,6,26)),1,0) -> 8021.382 | AN26: =IF(ISNUMBER(C27),C27,AN27)-0.8328750492*(AD28-AD27)+3.274150872*(AE28-AE27)+0.7954612886*((IF(ISNUMBER(C27),C27,AN27)-IF(ISNUMBER(C26),C26,AN26))-(-0.8328750492*(AD27-AD26)+3.274150872*(AE27-AE26)))-1.394571582*AO27+0.4181414112*AO26 -> 7694.1946 | AP26: =AQ26+AR25+'ARIMAX(1,1,1) Model'!$C$19*(AR25-AR24)+'ARIMAX(1,1,1) Model'!$C$20*AS25 -> 7532.0817 | AQ26: ='ARIMAX(1,1,1) Model'!$C$6*I26+'ARIMAX(1,1,1) Model'!$C$7*N26/1000+'ARIMAX(1,1,1) Model'!$C$8*AD26+'ARIMAX(1,1,1) Model'!$C$9*AE26+'ARIMAX(1,1,1) Model'!$C$10*AC26+'ARIMAX(1,1,1) Model'!$C$11*IF(AND(B26>='ARIMAX(1,1,1) Model'!$C$25,B26<='ARIMAX(1,1,1) Model'!$C$26),1,0)+'ARIMAX(1,1,1) Model'!$C$12*E26/1000+'ARIMAX(1,1,1) Model'!$C$13*V26+'ARIMAX(1,1,1) Model'!$C$14*A26+'ARIMAX(1,1,1) Model'!$C$15*SIN(2*PI()*A26/'ARIMAX(1,1,1) Model'!$C$24)+'ARIMAX(1,1,1) Model'!$C$16*COS(2*PI()*A26/'ARIMAX(1,1,1) Model'!$C$24)+'ARIMAX(1,1,1) Model'!$C$17*SIN(4*PI()*A26/'ARIMAX(1,1,1) Model'!$C$24)+'ARIMAX(1,1,1) Model'!$C$18*COS(4*PI()*A26/'ARIMAX(1,1,1) Model'!$C$24) -> 1432.6884 | AR26: =IF(ISNUMBER(C26),C26,AP26)-AQ26 -> 6068.3116 | AS26: =IF(ISNUMBER(C26),C26-AP26,0) -> -31.081718
A27: 26 | B27: 33452 | C27: 7605 | E27: 423000 | G27: 21.462 | H27: 19.568 | I27: 1.091 | J27: 6035.178 | L27: 819 | M27: 12.719 | N27: 191929 | O27: 3933.2 | P27: 824860 | V27: 84.6 | AC27: 0 | AD27: 0 | AE27: 80.7 | AG27: =6753.47943187+0.36116788*I27+0.01252571*N27-22.85359542*V27+0.00407811*AA27-0.00067349*E27 -> 6939.62 | AH27: =A27*'Simple Linear Regression'!$B$18+'Simple Linear Regression'!$B$17 -> 7907.5153 | AI27: =7491.3971+0.0137554*N27-0.00058829*E27-34.3283*V27+0.30565*L27+54.6031*M27 -> 7923.2606 | AJ27: =7491.3971-0.00058829*E27+0.30565*L27+54.6031*M27+0.0137554*N27-34.3283*V27 -> 7923.2606 | AL27: =2192.59+2373.87*I27+0.0316653*N27-15.7623*V27+0.00202406*AA27-0.000740146*E27-0.00963493*(I27*N27) -> 7195.8975 | AM27: =5205.907083+122.0638992*I27+13.609808*(N27/1000)-1.245906883*AD27+0.7746840854*AE27-134.2474226*AC27-1547.125689*IF(AND(B27>=DATE(2020,3,20),B27<=DATE(2020,6,26)),1,0) -> 8013.7126 | AN27: =IF(ISNUMBER(C28),C28,AN28)-0.8328750492*(AD29-AD28)+3.274150872*(AE29-AE28)+0.7954612886*((IF(ISNUMBER(C28),C28,AN28)-IF(ISNUMBER(C27),C27,AN27))-(-0.8328750492*(AD28-AD27)+3.274150872*(AE28-AE27)))-1.394571582*AO28+0.4181414112*AO27 -> 7583.9713 | AP27: =AQ27+AR26+'ARIMAX(1,1,1) Model'!$C$19*(AR26-AR25)+'ARIMAX(1,1,1) Model'!$C$20*AS26 -> 7471.0462 | AQ27: ='ARIMAX(1,1,1) Model'!$C$6*I27+'ARIMAX(1,1,1) Model'!$C$7*N27/1000+'ARIMAX(1,1,1) Model'!$C$8*AD27+'ARIMAX(1,1,1) Model'!$C$9*AE27+'ARIMAX(1,1,1) Model'!$C$10*AC27+'ARIMAX(1,1,1) Model'!$C$11*IF(AND(B27>='ARIMAX(1,1,1) Model'!$C$25,B27<='ARIMAX(1,1,1) Model'!$C$26),1,0)+'ARIMAX(1,1,1) Model'!$C$12*E27/1000+'ARIMAX(1,1,1) Model'!$C$13*V27+'ARIMAX(1,1,1) Model'!$C$14*A27+'ARIMAX(1,1,1) Model'!$C$15*SIN(2*PI()*A27/'ARIMAX(1,1,1) Model'!$C$24)+'ARIMAX(1,1,1) Model'!$C$16*COS(2*PI()*A27/'ARIMAX(1,1,1) Model'!$C$24)+'ARIMAX(1,1,1) Model'!$C$17*SIN(4*PI()*A27/'ARIMAX(1,1,1) Model'!$C$24)+'ARIMAX(1,1,1) Model'!$C$18*COS(4*PI()*A27/'ARIMAX(1,1,1) Model'!$C$24) -> 1362.8466 | AR27: =IF(ISNUMBER(C27),C27,AP27)-AQ27 -> 6242.1534 | AS27: =IF(ISNUMBER(C27),C27-AP27,0) -> 133.95378
A28: 27 | B28: 33459 | C28: 7584 | E28: 438000 | G28: 21.502 | H28: 19.516 | I28: 1.099 | J28: 6126.862 | L28: 867 | M28: 12.719 | N28: 191929 | O28: 3940.5 | P28: 824860 | V28: 87.5 | AC28: 0 | AD28: 0 | AE28: 74.8 | AG28: =6753.47943187+0.36116788*I28+0.01252571*N28-22.85359542*V28+0.00407811*AA28-0.00067349*E28 -> 6863.2451 | AH28: =A28*'Simple Linear Regression'!$B$18+'Simple Linear Regression'!$B$17 -> 7908.3683 | AI28: =7491.3971+0.0137554*N28-0.00058829*E28-34.3283*V28+0.30565*L28+54.6031*M28 -> 7829.5554 | AJ28: =7491.3971-0.00058829*E28+0.30565*L28+54.6031*M28+0.0137554*N28-34.3283*V28 -> 7829.5554 | AL28: =2192.59+2373.87*I28+0.0316653*N28-15.7623*V28+0.00202406*AA28-0.000740146*E28-0.00963493*(I28*N28) -> 7143.2818 | AM28: =5205.907083+122.0638992*I28+13.609808*(N28/1000)-1.245906883*AD28+0.7746840854*AE28-134.2474226*AC28-1547.125689*IF(AND(B28>=DATE(2020,3,20),B28<=DATE(2020,6,26)),1,0) -> 8010.1185 | AN28: =IF(ISNUMBER(C29),C29,AN29)-0.8328750492*(AD30-AD29)+3.274150872*(AE30-AE29)+0.7954612886*((IF(ISNUMBER(C29),C29,AN29)-IF(ISNUMBER(C28),C28,AN28))-(-0.8328750492*(AD29-AD28)+3.274150872*(AE29-AE28)))-1.394571582*AO29+0.4181414112*AO28 -> 7248.4953 | AP28: =AQ28+AR27+'ARIMAX(1,1,1) Model'!$C$19*(AR27-AR26)+'ARIMAX(1,1,1) Model'!$C$20*AS27 -> 7490.4253 | AQ28: ='ARIMAX(1,1,1) Model'!$C$6*I28+'ARIMAX(1,1,1) Model'!$C$7*N28/1000+'ARIMAX(1,1,1) Model'!$C$8*AD28+'ARIMAX(1,1,1) Model'!$C$9*AE28+'ARIMAX(1,1,1) Model'!$C$10*AC28+'ARIMAX(1,1,1) Model'!$C$11*IF(AND(B28>='ARIMAX(1,1,1) Model'!$C$25,B28<='ARIMAX(1,1,1) Model'!$C$26),1,0)+'ARIMAX(1,1,1) Model'!$C$12*E28/1000+'ARIMAX(1,1,1) Model'!$C$13*V28+'ARIMAX(1,1,1) Model'!$C$14*A28+'ARIMAX(1,1,1) Model'!$C$15*SIN(2*PI()*A28/'ARIMAX(1,1,1) Model'!$C$24)+'ARIMAX(1,1,1) Model'!$C$16*COS(2*PI()*A28/'ARIMAX(1,1,1) Model'!$C$24)+'ARIMAX(1,1,1) Model'!$C$17*SIN(4*PI()*A28/'ARIMAX(1,1,1) Model'!$C$24)+'ARIMAX(1,1,1) Model'!$C$18*COS(4*PI()*A28/'ARIMAX(1,1,1) Model'!$C$24) -> 1351.8864 | AR28: =IF(ISNUMBER(C28),C28,AP28)-AQ28 -> 6232.1136 | AS28: =IF(ISNUMBER(C28),C28-AP28,0) -> 93.57473
