Workbook

Sheet Model Notes
A1: Sunoco Weekly Gasoline Demand – Seasonal Index Model with Covariates
A3: Starting point
A4: Baseline | B4: The class ASI demo: linear trend on week number (2022–2024) × average seasonal index of the same week over those 3 years. It is rebuilt on the Data sheet (Baseline columns) only as a benchmark.
A6: How this model differs
A7: 1. Longer, cleaner time window | B7: Fits on 2015–2024 instead of 2022–2024, excluding 2020–2021 (COVID). That is 8 usable years (≈417 weeks) instead of 3 (156 weeks), so the seasonal pattern and trend are estimated from far more data.
A8: 2. Two covariates | B8: After removing seasonality, demand is regressed on week number plus two drivers from the new dataset (highway vehicle miles traveled and weekly jobless claims). Forecast = (intercept + b·Week# + c₁·X₁ + c₂·X₂) × Seasonal Index.
A9: 3. Calendar-based week matching | B9: Seasonal indices are matched on week-of-year from the date, so the model works across 53-week years (2026) and any window.
A10: 4. Normalized index | B10: The seasonal index is rescaled to average exactly 1.0, so seasonality doesn't shift the overall level.
A11: 5. Fully live estimation | B11: All coefficients are computed with formulas on the Regression sheet, including standard errors and t-stats. Pick different covariates or years on Inputs and everything re-estimates.
A13: Results
A14: 2025 validation (live) | B14: Baseline MAPE ≈ 3.57% → Covariate model ≈ 2.75% (see Accuracy). These are the predictions in sunoco_2025_forecast_covariate_model.csv (CSV Export sheet).
A15: 2024 holdout (static check) | B15: Refit through 2023: Baseline 3.02% → Covariate model 2.79%. Beating the baseline in both years means the gain isn't a one-year coincidence.
A17: How the covariates were chosen
A18: Search | B18: Tested every single covariate and pair from 12 candidates, across start years 2012, 2015, 2017, 2019, and 2022, scoring each on both 2024 and 2025. The 2015 start was clearly the best window.
A19: Vehicle miles traveled | B19: Strongest and most defensible driver: positive, as hypothesized (more driving → more gasoline), statistically significant (t ≈ 2.8), and it improves accuracy in both holdout years.
A20: Jobless claims | B20: Chosen as the second covariate because it is statistically significant (t ≈ −3.5) with the hypothesized negative sign: more layoffs, less driving. It costs a little accuracy versus VMT alone (2.75% vs 2.65% in 2025) but is far easier to justify.
A21: Cooling degree days – rejected | B21: Slightly more accurate (2.62% in 2025), but its sign is negative (hypothesis says positive) and it is not significant (t ≈ −1.5), so the gain is likely luck.
A22: US population – rejected | B22: Looks significant, but it is annual (10 distinct values) and correlates 0.99 with week number, so it duplicates the trend term; 2025 error rose to 3.04%.
A23: Gas price – alternative | B23: Regular gas price is highly significant with the hypothesized negative sign (t ≈ −7.5), but using it made 2025 forecasts worse (≈3.07%). It explains the past well yet predicts poorly, likely because price effects are already reflected in miles driven. Select it on Inputs to compare.
A24: Also tested, not helpful | B24: Holiday week flag (no gain; the week-of-year index already captures holidays), HDD, jobless claims, work-from-home share, S&P 500, refinery utilization.
A26: Caveats
A27: Covariates must be known | B27: The 2025/2026 forecasts use observed covariate values. In real forecasting you'd need forecasts of VMT and weather, which adds error. VMT is also released with a lag.
A28: Selection effect | B28: Choosing among many variants can flatter results a little; the two-year check limits but doesn't eliminate this.
A29: Weekly noise | B29: Weekly demand swings are large (about ±300–400 units, or 3–5%, from week to week), so individual weeks will still miss. The gains are in average accuracy.
A31: Color key
A32: Blue text | B32: Hard-coded data and inputs
A33: Black text | B33: Formulas
A34: Green text | B34: Links to other sheets
A35: Yellow fill | B35: Inputs you can change

Sheet Inputs
A1: Model Inputs
A2: Change the yellow cells. Everything else recalculates.
A4: Input | B4: Value | C4: Notes | F4: Covariate list
A5: First training year | B5: 2015 | D5: 2015 tested best across 2012/2015/2017/2019/2022 on both the 2024 and 2025 holdouts. | F5: sp500_weekly_avg
A6: Last training year | B6: 2024 | D6: Last year with known demand. The following year is scored as the validation year. | F6: initial_jobless_claims
A7: Excluded year #1 | B7: 2020 | D7: COVID lockdowns – excluded from fitting. | F7: tsa_passengers_weekly_avg
A8: Excluded year #2 | B8: 2021 | D8: COVID recovery – excluded from fitting. | F8: wti_spot_usd_per_bbl
C9: Column # | F9: brent_spot_usd_per_bbl
A10: Covariate 1 | B10: vehicle_miles_mil | C10: =MATCH(B10,Data!$E$1:$AF$1,0) -> 11 | D10: Highway vehicle miles traveled (FHWA). Pick from dropdown; list in column F. | F10: regular_gas_usd_per_gal
A11: Covariate 2 | B11: initial_jobless_claims | C11: =MATCH(B11,Data!$E$1:$AF$1,0) -> 2 | D11: Weekly initial jobless claims (seasonally adjusted). Significant, with the hypothesized negative sign. See Model Notes for alternatives. | F11: gdp_saar_bil_usd
F12: transit_unlinked_trips_thous
A13: Check: covariates must differ | B13: =IF(B10=B11,"ERROR – pick two different covariates","OK") -> OK | F13: rotary_rig_count
F14: vehicle_sales_saar_mil
A15: Training weeks used | B15: =SUM(Data!$AJ$2:$AJ$1857) -> 417 | F15: vehicle_miles_mil
A16: Validation year | B16: =B6+1 -> 2025 | F16: pce_saar_bil_usd
F17: consumer_credit_mil_usd
F18: ev_sales_vehicles
F19: regulated_afv_acquisitions
F20: household_debt_tril_usd
F21: eci_total_comp_index
F22: smoking_adults_pct
F23: refinery_utilization_pct
F24: fed_broad_dollar_index
F25: home_price_expectation_pct
F26: inflation_expectation_1y_pct
F27: mean_annual_earnings_thous_usd
F28: us_population_thous
... F32: cdd_pop_weighted

Sheet Accuracy
A1: Out-of-Sample Accuracy – Validation Year
A2: ="Scored on "&Inputs!B16&", a year excluded from fitting. Lower is better." -> Scored on 2025, a year excluded from fitting. Lower is better.
A4: Metric | B4: Baseline (class ASI demo) | C4: Covariate Model | D4: Change
A5: MAPE | B5: =AVERAGEIFS(Data!$BF$2:$BF$1857,Data!$AW$2:$AW$1857,"Validation") -> 0.035698798 | C5: =AVERAGEIFS(Data!$AY$2:$AY$1857,Data!$AW$2:$AW$1857,"Validation") -> 0.027467971 | D5: =IF(B5=0,"",C5/B5-1) -> -0.23056314
A6: MAE | B6: =SUMPRODUCT(ABS(Data!$BI$2:$BI$1857))/COUNT(Data!$AY$2:$AY$1857) -> 309.04318 | C6: =SUMPRODUCT(ABS(Data!$BH$2:$BH$1857))/COUNT(Data!$AY$2:$AY$1857) -> 243.85352 | D6: =IF(B6=0,"",C6/B6-1) -> -0.21094031
A7: RMSE | B7: =SQRT(SUMPRODUCT(Data!$BI$2:$BI$1857,Data!$BI$2:$BI$1857)/COUNT(Data!$AY$2:$AY$1857)) -> 384.22135 | C7: =SQRT(SUMPRODUCT(Data!$BH$2:$BH$1857,Data!$BH$2:$BH$1857)/COUNT(Data!$AY$2:$AY$1857)) -> 307.49367 | D7: =IF(B7=0,"",C7/B7-1) -> -0.19969656
A8: Bias (forecast − actual) | B8: =SUM(Data!$BI$2:$BI$1857)/COUNT(Data!$AY$2:$AY$1857) -> 176.24566 | C8: =SUM(Data!$BH$2:$BH$1857)/COUNT(Data!$AY$2:$AY$1857) -> -101.67609
A9: Weeks scored | B9: =COUNT(Data!$AY$2:$AY$1857) -> 52 | C9: =COUNT(Data!$AY$2:$AY$1857) -> 52
A11: 2024 holdout check (static, VMT + jobless claims)
A12: MAPE, both models refit through 2023 | B12: 0.0302 | C12: 0.0279 | D12: =C12/B12-1 -> -0.07615894
A13: Hardcoded from the Python backtest used to choose settings (VMT + jobless claims, 2015 start). Does not update if inputs change.
A15: Validation-year weekly detail
A16: Date | B16: Actual | C16: Baseline | D16: Covariate Model
A17: =Data!B1771 -> 45660 | B17: =Data!AX1771 -> 8481 | C17: =Data!BE1771 -> 8075.9313 | D17: =Data!AV1771 -> 8019.2615
A18: =Data!B1772 -> 45667 | B18: =Data!AX1772 -> 8325 | C18: =Data!BE1772 -> 8334.4438 | D18: =Data!AV1772 -> 8089.1826
A19: =Data!B1773 -> 45674 | B19: =Data!AX1773 -> 8086 | C19: =Data!BE1773 -> 8329.7326 | D19: =Data!AV1773 -> 8109.0838
A20: =Data!B1774 -> 45681 | B20: =Data!AX1774 -> 8302 | C20: =Data!BE1774 -> 8441.393 | D20: =Data!AV1774 -> 8299.1479
A21: =Data!B1775 -> 45688 | B21: =Data!AX1775 -> 8328 | C21: =Data!BE1775 -> 8951.4262 | D21: =Data!AV1775 -> 8396.2612
A22: =Data!B1776 -> 45695 | B22: =Data!AX1776 -> 8576 | C22: =Data!BE1776 -> 8493.6217 | D22: =Data!AV1776 -> 8166.7731
A23: =Data!B1777 -> 45702 | B23: =Data!AX1777 -> 8239 | C23: =Data!BE1777 -> 8750.1009 | D23: =Data!AV1777 -> 8377.5943
A24: =Data!B1778 -> 45709 | B24: =Data!AX1778 -> 8454 | C24: =Data!BE1778 -> 8937.9408 | D24: =Data!AV1778 -> 8493.6331
A25: =Data!B1779 -> 45716 | B25: =Data!AX1779 -> 8877 | C25: =Data!BE1779 -> 9009.8997 | D25: =Data!AV1779 -> 8513.596
A26: =Data!B1780 -> 45723 | B26: =Data!AX1780 -> 9182 | C26: =Data!BE1780 -> 9024.9945 | D26: =Data!AV1780 -> 8634.4886
A27: =Data!B1781 -> 45730 | B27: =Data!AX1781 -> 8817 | C27: =Data!BE1781 -> 8964.9699 | D27: =Data!AV1781 -> 8697.6961
A28: =Data!B1782 -> 45737 | B28: =Data!AX1782 -> 8643 | C28: =Data!BE1782 -> 8948.839 | D28: =Data!AV1782 -> 8583.8191 | F28: 2026 forecasts (covariate model)
A29: =Data!B1783 -> 45744 | B29: =Data!AX1783 -> 8495 | C29: =Data!BE1783 -> 9196.5836 | D29: =Data!AV1783 -> 8707.4551 | F29: Date | G29: Forecast
A30: =Data!B1784 -> 45751 | B30: =Data!AX1784 -> 8425 | C30: =Data!BE1784 -> 8924.3905 | D30: =Data!AV1784 -> 8612.6139 | F30: =Data!B1823 -> 46024 | G30: =Data!AV1823 -> 7970.2535
A31: =Data!B1785 -> 45758 | B31: =Data!AX1785 -> 8462 | C31: =Data!BE1785 -> 8844.8413 | D31: =Data!AV1785 -> 8675.0767 | F31: =Data!B1824 -> 46031 | G31: =Data!AV1824 -> 8015.372
A32: =Data!B1786 -> 45765 | B32: =Data!AX1786 -> 9414 | C32: =Data!BE1786 -> 9056.9958 | D32: =Data!AV1786 -> 8656.3031 | F32: =Data!B1825 -> 46038 | G32: =Data!AV1825 -> 8079.2269
A33: =Data!B1787 -> 45772 | B33: =Data!AX1787 -> 9098 | C33: =Data!BE1787 -> 8859.4809 | D33: =Data!AV1787 -> 8494.9722 | F33: =Data!B1826 -> 46045 | G33: =Data!AV1826 -> 8255.8615
A34: =Data!B1788 -> 45779 | B34: =Data!AX1788 -> 8717 | C34: =Data!BE1788 -> 9099.4511 | D34: =Data!AV1788 -> 8732.2314 | F34: =Data!B1827 -> 46052 | G34: =Data!AV1827 -> 8321.9006
A35: =Data!B1789 -> 45786 | B35: =Data!AX1789 -> 8794 | C35: =Data!BE1789 -> 9102.9247 | D35: =Data!AV1789 -> 8719.3429 | F35: =Data!B1828 -> 46059 | G35: =Data!AV1828 -> 8066.8049
A36: =Data!B1790 -> 45793 | B36: =Data!AX1790 -> 8644 | C36: =Data!BE1790 -> 9352.0287 | D36: =Data!AV1790 -> 8989.4188 | F36: =Data!B1829 -> 46066 | G36: =Data!AV1829 -> 8264.9233
A37: =Data!B1791 -> 45800 | B37: =Data!AX1791 -> 9452 | C37: =Data!BE1791 -> 9242.0698 | D37: =Data!AV1791 -> 8988.0557 | F37: =Data!B1830 -> 46073 | G37: =Data!AV1830 -> 8456.0396
A38: =Data!B1792 -> 45807 | B38: =Data!AX1792 -> 8263 | C38: =Data!BE1792 -> 9290.9 | D38: =Data!AV1792 -> 8772.4003 | F38: =Data!B1831 -> 46080 | G38: =Data!AV1831 -> 8514.9783
A39: =Data!B1793 -> 45814 | B39: =Data!AX1793 -> 9170 | C39: =Data!BE1793 -> 9277.6807 | D39: =Data!AV1793 -> 8952.7476 | F39: =Data!B1832 -> 46087 | G39: =Data!AV1832 -> 8583.0337
A40: =Data!B1794 -> 45821 | B40: =Data!AX1794 -> 9299 | C40: =Data!BE1794 -> 9254.3446 | D40: =Data!AV1794 -> 8918.817 | F40: =Data!B1833 -> 46094 | G40: =Data!AV1833 -> 8643.2262
A41: =Data!B1795 -> 45828 | B41: =Data!AX1795 -> 9688 | C41: =Data!BE1795 -> 9233.5056 | D41: =Data!AV1795 -> 8939.0314 | F41: =Data!B1834 -> 46101 | G41: =Data!AV1834 -> 8556.5249
... A64: =Data!B1818 -> 45989 | B64: =Data!AX1818 -> 8326 | C64: =Data!BE1818 -> 8676.7311 | D64: =Data!AV1818 -> 8441.4985 | F64: =Data!B1857 -> 46262 | G64: =Data!AV1857 -> 8851.4663
A65: =Data!B1819 -> 45996 | B65: =Data!AX1819 -> 8456 | C65: =Data!BE1819 -> 8799.0423 | D65: =Data!AV1819 -> 8493.1491
...

Sheet CSV Export
A1: date | B1: prediction | D1: Matches sunoco_2025_forecast_covariate_model.csv (same model, same settings).
A2: =Data!B1771 -> 45660 | B2: =Data!AV1771 -> 8019.2615 | D2: To export: File > Save As > CSV while this sheet is active (dates are formatted yyyy-mm-dd).
A3: =Data!B1772 -> 45667 | B3: =Data!AV1772 -> 8089.1826
A4: =Data!B1773 -> 45674 | B4: =Data!AV1773 -> 8109.0838
A5: =Data!B1774 -> 45681 | B5: =Data!AV1774 -> 8299.1479
A6: =Data!B1775 -> 45688 | B6: =Data!AV1775 -> 8396.2612
A7: =Data!B1776 -> 45695 | B7: =Data!AV1776 -> 8166.7731
A8: =Data!B1777 -> 45702 | B8: =Data!AV1777 -> 8377.5943
A9: =Data!B1778 -> 45709 | B9: =Data!AV1778 -> 8493.6331
A10: =Data!B1779 -> 45716 | B10: =Data!AV1779 -> 8513.596
A11: =Data!B1780 -> 45723 | B11: =Data!AV1780 -> 8634.4886
A12: =Data!B1781 -> 45730 | B12: =Data!AV1781 -> 8697.6961
A13: =Data!B1782 -> 45737 | B13: =Data!AV1782 -> 8583.8191
A14: =Data!B1783 -> 45744 | B14: =Data!AV1783 -> 8707.4551
... A53: =Data!B1822 -> 46017 | B53: =Data!AV1822 -> 8171.8017

Sheet Regression
A1: Two-Step Model Estimation
A2: Step 1: trend on Week # → seasonal index. Step 2: regress deseasonalized demand on Week # + 2 covariates.
B4: Step 1 – Trend (training weeks)
B5: Intercept | C5: =(C11-C6*C10)/C9 -> 10846.55
B6: Slope per week | C6: =(C9*C8-C10*C11)/(C9*C7-C10^2) -> -1.1726749
B7: Σt² (helper) | C7: =SUMPRODUCT((Data!$AJ$2:$AJ$1857=1)*Data!$A$2:$A$1857*Data!$A$2:$A$1857) -> 943749560
B8: Σty (helper) | C8: =SUMPRODUCT(Data!$AJ$2:$AJ$1857,Data!$A$2:$A$1857,Data!$BG$2:$BG$1857) -> 5656459557
B9: n | C9: =SUM(Data!$AJ$2:$AJ$1857) -> 417
B10: Σt | C10: =SUMIFS(Data!$A$2:$A$1857,Data!$AJ$2:$AJ$1857,1) -> 623532
B11: Σy | C11: =SUMIFS(Data!$C$2:$C$1857,Data!$AJ$2:$AJ$1857,1) -> 3791811
B13: Step 2 – Multiple regression on deseasonalized demand
C14: Week # | D14: =Inputs!B10 -> vehicle_miles_mil | E14: =Inputs!B11 -> initial_jobless_claims | F14: Deseas. Demand
B15: Training mean | C15: =AVERAGEIFS(Data!$A$2:$A$1857,Data!$AJ$2:$AJ$1857,1) -> 1495.2806 | D15: =AVERAGEIFS(Data!$AK$2:$AK$1857,Data!$AJ$2:$AJ$1857,1) -> 267402.98 | E15: =AVERAGEIFS(Data!$AL$2:$AL$1857,Data!$AJ$2:$AJ$1857,1) -> 235292.57 | F15: =AVERAGEIFS(Data!$AP$2:$AP$1857,Data!$AJ$2:$AJ$1857,1) -> 9094.5726
B16: Std. dev. | C16: =SQRT(SUMPRODUCT(Data!$AQ$2:$AQ$1857,Data!$AQ$2:$AQ$1857)/$C$9) -> 165.30092 | D16: =SQRT(SUMPRODUCT(Data!$AR$2:$AR$1857,Data!$AR$2:$AR$1857)/$C$9) -> 17922.091 | E16: =SQRT(SUMPRODUCT(Data!$AS$2:$AS$1857,Data!$AS$2:$AS$1857)/$C$9) -> 25481.187 | F16: =SQRT(SUMPRODUCT(Data!$AT$2:$AT$1857,Data!$AT$2:$AT$1857)/$C$9) -> 362.09315
B18: Correlation matrix (R) | G18: Corr with y
B19: Week # | C19: =SUMPRODUCT(Data!$AQ$2:$AQ$1857,Data!$AQ$2:$AQ$1857)/($C$9*C$16*C$16) -> 1 | D19: =SUMPRODUCT(Data!$AQ$2:$AQ$1857,Data!$AR$2:$AR$1857)/($C$9*C$16*D$16) -> 0.26030889 | E19: =SUMPRODUCT(Data!$AQ$2:$AQ$1857,Data!$AS$2:$AS$1857)/($C$9*C$16*E$16) -> -0.67618286 | G19: =SUMPRODUCT(Data!$AQ$2:$AQ$1857,Data!$AT$2:$AT$1857)/($C$9*C$16*$F$16) -> -0.56337162
B20: Covariate 1 | C20: =SUMPRODUCT(Data!$AR$2:$AR$1857,Data!$AQ$2:$AQ$1857)/($C$9*D$16*C$16) -> 0.26030889 | D20: =SUMPRODUCT(Data!$AR$2:$AR$1857,Data!$AR$2:$AR$1857)/($C$9*D$16*D$16) -> 1 | E20: =SUMPRODUCT(Data!$AR$2:$AR$1857,Data!$AS$2:$AS$1857)/($C$9*D$16*E$16) -> -0.22243198 | G20: =SUMPRODUCT(Data!$AR$2:$AR$1857,Data!$AT$2:$AT$1857)/($C$9*D$16*$F$16) -> -0.053784489
B21: Covariate 2 | C21: =SUMPRODUCT(Data!$AS$2:$AS$1857,Data!$AQ$2:$AQ$1857)/($C$9*E$16*C$16) -> -0.67618286 | D21: =SUMPRODUCT(Data!$AS$2:$AS$1857,Data!$AR$2:$AR$1857)/($C$9*E$16*D$16) -> -0.22243198 | E21: =SUMPRODUCT(Data!$AS$2:$AS$1857,Data!$AS$2:$AS$1857)/($C$9*E$16*E$16) -> 1 | G21: =SUMPRODUCT(Data!$AS$2:$AS$1857,Data!$AT$2:$AT$1857)/($C$9*E$16*$F$16) -> 0.27533768
B23: det(R) | C23: =MDETERM(C19:E21) -> 0.50384339
B25: Cramer matrices (column k replaced by corr-with-y)
C26: k = Week # | G26: k = Cov 1 | K26: k = Cov 2
C27: =$G$19 -> -0.56337162 | D27: =D19 -> 0.26030889 | E27: =E19 -> -0.67618286 | G27: =C19 -> 1 | H27: =$G$19 -> -0.56337162 | I27: =E19 -> -0.67618286 | K27: =C19 -> 1 | L27: =D19 -> 0.26030889 | M27: =$G$19 -> -0.56337162
C28: =$G$20 -> -0.053784489 | D28: =D20 -> 1 | E28: =E20 -> -0.22243198 | G28: =C20 -> 0.26030889 | H28: =$G$20 -> -0.053784489 | I28: =E20 -> -0.22243198 | K28: =C20 -> 0.26030889 | L28: =D20 -> 1 | M28: =$G$20 -> -0.053784489
C29: =$G$21 -> 0.27533768 | D29: =D21 -> -0.22243198 | E29: =E21 -> 1 | G29: =C21 -> -0.67618286 | H29: =$G$21 -> 0.27533768 | I29: =E21 -> 1 | K29: =C21 -> -0.67618286 | L29: =D21 -> -0.22243198 | M29: =$G$21 -> 0.27533768
B31: Standardized beta | C31: =MDETERM(C27:E29)/$C$23 -> -0.71321927 | G31: =MDETERM(G27:I29)/$C$23 -> 0.090313563 | K31: =MDETERM(K27:M29)/$C$23 -> -0.18684034
C34: Intercept | D34: Week # | E34: Covariate 1 | F34: Covariate 2
B35: Variable | C35: (constant) | D35: Week # | E35: =Inputs!B10 -> vehicle_miles_mil | F35: =Inputs!B11 -> initial_jobless_claims
B36: Std. beta | D36: =C31 -> -0.71321927 | E36: =G31 -> 0.090313563 | F36: =K31 -> -0.18684034
B38: Coefficient | C38: =F15-D38*C15-E38*D15-F38*E15 -> 11567.458 | D38: =D36*$F$16/C16 -> -1.5623132 | E38: =E36*$F$16/D16 -> 0.0018246711 | F38: =F36*$F$16/E16 -> -0.0026550414
B39: Inverse-diag (R⁻¹) | D39: =(D20*E21-E20*D21)/$C$23 -> 1.8865465 | E39: =(C19*E21-E19*C21)/$C$23 -> 1.0772727 | F39: =(C19*D20-D19*C20)/$C$23 -> 1.850256
B40: Standard error | D40: =SQRT($C$49*D39/($C$9*C16^2)) -> 0.11977237 | E40: =SQRT($C$49*E39/($C$9*D16^2)) -> 0.00083478054 | F40: =SQRT($C$49*F39/($C$9*E16^2)) -> 0.00076947484
B41: t Stat | D41: =D38/D40 -> -13.04402 | E41: =E38/E40 -> 2.1858094 | F41: =F38/F40 -> -3.450459
B42: Sign matches hypothesis? | D42: n/a | E42: =IFERROR(IF(INDEX(Hyp!$D:$D,MATCH(E35,Hyp!$A:$A,0))="Positive",IF(E38>0,"Yes","No"),IF(INDEX(Hyp!$D:$D,MATCH(E35,Hyp!$A:$A,0))="Negative",IF(E38<0,"Yes","No"),"Conditional")),"n/a") -> Yes | F42: =IFERROR(IF(INDEX(Hyp!$D:$D,MATCH(F35,Hyp!$A:$A,0))="Positive",IF(F38>0,"Yes","No"),IF(INDEX(Hyp!$D:$D,MATCH(F35,Hyp!$A:$A,0))="Negative",IF(F38<0,"Yes","No"),"Conditional")),"n/a") -> Yes
B43: |t| > 2 means the coefficient is statistically significant at roughly the 5% level.
B44: Baseline (class ASI demo) trend, 2022–2024
B45: Intercept | C45: =(SUMPRODUCT((Data!$AH$2:$AH$1857>=2022)*(Data!$AH$2:$AH$1857<=2024)*Data!$BG$2:$BG$1857)-C46*SUMPRODUCT((Data!$AH$2:$AH$1857>=2022)*(Data!$AH$2:$AH$1857<=2024)*Data!$A$2:$A$1857))/C47 -> 6144.2795
B46: Slope per week | C46: =(C47*SUMPRODUCT((Data!$AH$2:$AH$1857>=2022)*(Data!$AH$2:$AH$1857<=2024)*Data!$A$2:$A$1857*Data!$BG$2:$BG$1857)-SUMPRODUCT((Data!$AH$2:$AH$1857>=2022)*(Data!$AH$2:$AH$1857<=2024)*Data!$A$2:$A$1857)*SUMPRODUCT((Data!$AH$2:$AH$1857>=2022)*(Data!$AH$2:$AH$1857<=2024)*Data!$BG$2:$BG$1857))/(C47*SUMPRODUCT((Data!$AH$2:$AH$1857>=2022)*(Data!$AH$2:$AH$1857<=2024)*Data!$A$2:$A$1857^2)-SUMPRODUCT((Data!$AH$2:$AH$1857>=2022)*(Data!$AH$2:$AH$1857<=2024)*Data!$A$2:$A$1857)^2) -> 1.5594996
B47: n | C47: =SUMPRODUCT((Data!$AH$2:$AH$1857>=2022)*(Data!$AH$2:$AH$1857<=2024)) -> 156
B49: Residual variance (s²) | C49: =SUMPRODUCT(Data!$AZ$2:$AZ$1857,Data!$AZ$2:$AZ$1857)/(C9-4) -> 86642.781
B50: R² (deseasonalized) | C50: =1-SUMPRODUCT(Data!$AZ$2:$AZ$1857,Data!$AZ$2:$AZ$1857)/SUMPRODUCT(Data!$AT$2:$AT$1857,Data!$AT$2:$AT$1857) -> 0.34550584
...

Sheet Seasonal Index
A1: Week of Year | B1: Avg SI (training) | C1: # Weeks | D1: Sum Check | E1: Seasonal Index (normalized) | G1: Baseline avg SI (2022–24) | H1: Baseline ASI
A2: 1 | B2: =AVERAGEIFS(Data!$AN$2:$AN$1857,Data!$AI$2:$AI$1857,A2,Data!$AJ$2:$AJ$1857,1) -> 0.91478473 | C2: =COUNTIFS(Data!$AI$2:$AI$1857,A2,Data!$AJ$2:$AJ$1857,1) -> 8 | E2: =B2/AVERAGE($B$2:$B$53) -> 0.91465819 | G2: =AVERAGEIFS(Data!$BC$2:$BC$1857,Data!$AI$2:$AI$1857,A2,Data!$AH$2:$AH$1857,">=2022",Data!$AH$2:$AH$1857,"<=2024") -> 0.90693989 | H2: =G2 -> 0.90693989
A3: 2 | B3: =AVERAGEIFS(Data!$AN$2:$AN$1857,Data!$AI$2:$AI$1857,A3,Data!$AJ$2:$AJ$1857,1) -> 0.92125116 | C3: =COUNTIFS(Data!$AI$2:$AI$1857,A3,Data!$AJ$2:$AJ$1857,1) -> 8 | E3: =B3/AVERAGE($B$2:$B$53) -> 0.92112372 | G3: =AVERAGEIFS(Data!$BC$2:$BC$1857,Data!$AI$2:$AI$1857,A3,Data!$AH$2:$AH$1857,">=2022",Data!$AH$2:$AH$1857,"<=2024") -> 0.93580736 | H3: =G3 -> 0.93580736
A4: 3 | B4: =AVERAGEIFS(Data!$AN$2:$AN$1857,Data!$AI$2:$AI$1857,A4,Data!$AJ$2:$AJ$1857,1) -> 0.93260472 | C4: =COUNTIFS(Data!$AI$2:$AI$1857,A4,Data!$AJ$2:$AJ$1857,1) -> 8 | E4: =B4/AVERAGE($B$2:$B$53) -> 0.93247571 | G4: =AVERAGEIFS(Data!$BC$2:$BC$1857,Data!$AI$2:$AI$1857,A4,Data!$AH$2:$AH$1857,">=2022",Data!$AH$2:$AH$1857,"<=2024") -> 0.93511464 | H4: =G4 -> 0.93511464
A5: 4 | B5: =AVERAGEIFS(Data!$AN$2:$AN$1857,Data!$AI$2:$AI$1857,A5,Data!$AJ$2:$AJ$1857,1) -> 0.95580246 | C5: =COUNTIFS(Data!$AI$2:$AI$1857,A5,Data!$AJ$2:$AJ$1857,1) -> 8 | E5: =B5/AVERAGE($B$2:$B$53) -> 0.95567024 | G5: =AVERAGEIFS(Data!$BC$2:$BC$1857,Data!$AI$2:$AI$1857,A5,Data!$AH$2:$AH$1857,">=2022",Data!$AH$2:$AH$1857,"<=2024") -> 0.947484 | H5: =G5 -> 0.947484
A6: 5 | B6: =AVERAGEIFS(Data!$AN$2:$AN$1857,Data!$AI$2:$AI$1857,A6,Data!$AJ$2:$AJ$1857,1) -> 0.96391855 | C6: =COUNTIFS(Data!$AI$2:$AI$1857,A6,Data!$AJ$2:$AJ$1857,1) -> 8 | E6: =B6/AVERAGE($B$2:$B$53) -> 0.96378521 | G6: =AVERAGEIFS(Data!$BC$2:$BC$1857,Data!$AI$2:$AI$1857,A6,Data!$AH$2:$AH$1857,">=2022",Data!$AH$2:$AH$1857,"<=2024") -> 1.0045556 | H6: =G6 -> 1.0045556
A7: 6 | B7: =AVERAGEIFS(Data!$AN$2:$AN$1857,Data!$AI$2:$AI$1857,A7,Data!$AJ$2:$AJ$1857,1) -> 0.94003306 | C7: =COUNTIFS(Data!$AI$2:$AI$1857,A7,Data!$AJ$2:$AJ$1857,1) -> 8 | E7: =B7/AVERAGE($B$2:$B$53) -> 0.93990302 | G7: =AVERAGEIFS(Data!$BC$2:$BC$1857,Data!$AI$2:$AI$1857,A7,Data!$AH$2:$AH$1857,">=2022",Data!$AH$2:$AH$1857,"<=2024") -> 0.95301266 | H7: =G7 -> 0.95301266
A8: 7 | B8: =AVERAGEIFS(Data!$AN$2:$AN$1857,Data!$AI$2:$AI$1857,A8,Data!$AJ$2:$AJ$1857,1) -> 0.96329535 | C8: =COUNTIFS(Data!$AI$2:$AI$1857,A8,Data!$AJ$2:$AJ$1857,1) -> 8 | E8: =B8/AVERAGE($B$2:$B$53) -> 0.96316209 | G8: =AVERAGEIFS(Data!$BC$2:$BC$1857,Data!$AI$2:$AI$1857,A8,Data!$AH$2:$AH$1857,">=2022",Data!$AH$2:$AH$1857,"<=2024") -> 0.98161871 | H8: =G8 -> 0.98161871
A9: 8 | B9: =AVERAGEIFS(Data!$AN$2:$AN$1857,Data!$AI$2:$AI$1857,A9,Data!$AJ$2:$AJ$1857,1) -> 0.97852242 | C9: =COUNTIFS(Data!$AI$2:$AI$1857,A9,Data!$AJ$2:$AJ$1857,1) -> 8 | E9: =B9/AVERAGE($B$2:$B$53) -> 0.97838706 | G9: =AVERAGEIFS(Data!$BC$2:$BC$1857,Data!$AI$2:$AI$1857,A9,Data!$AH$2:$AH$1857,">=2022",Data!$AH$2:$AH$1857,"<=2024") -> 1.0025159 | H9: =G9 -> 1.0025159
A10: 9 | B10: =AVERAGEIFS(Data!$AN$2:$AN$1857,Data!$AI$2:$AI$1857,A10,Data!$AJ$2:$AJ$1857,1) -> 0.98643013 | C10: =COUNTIFS(Data!$AI$2:$AI$1857,A10,Data!$AJ$2:$AJ$1857,1) -> 8 | E10: =B10/AVERAGE($B$2:$B$53) -> 0.98629368 | G10: =AVERAGEIFS(Data!$BC$2:$BC$1857,Data!$AI$2:$AI$1857,A10,Data!$AH$2:$AH$1857,">=2022",Data!$AH$2:$AH$1857,"<=2024") -> 1.0104104 | H10: =G10 -> 1.0104104
A11: 10 | B11: =AVERAGEIFS(Data!$AN$2:$AN$1857,Data!$AI$2:$AI$1857,A11,Data!$AJ$2:$AJ$1857,1) -> 0.99541261 | C11: =COUNTIFS(Data!$AI$2:$AI$1857,A11,Data!$AJ$2:$AJ$1857,1) -> 8 | E11: =B11/AVERAGE($B$2:$B$53) -> 0.99527491 | G11: =AVERAGEIFS(Data!$BC$2:$BC$1857,Data!$AI$2:$AI$1857,A11,Data!$AH$2:$AH$1857,">=2022",Data!$AH$2:$AH$1857,"<=2024") -> 1.0119262 | H11: =G11 -> 1.0119262
A12: 11 | B12: =AVERAGEIFS(Data!$AN$2:$AN$1857,Data!$AI$2:$AI$1857,A12,Data!$AJ$2:$AJ$1857,1) -> 1.0022664 | C12: =COUNTIFS(Data!$AI$2:$AI$1857,A12,Data!$AJ$2:$AJ$1857,1) -> 8 | E12: =B12/AVERAGE($B$2:$B$53) -> 1.0021278 | G12: =AVERAGEIFS(Data!$BC$2:$BC$1857,Data!$AI$2:$AI$1857,A12,Data!$AH$2:$AH$1857,">=2022",Data!$AH$2:$AH$1857,"<=2024") -> 1.0050202 | H12: =G12 -> 1.0050202
A13: 12 | B13: =AVERAGEIFS(Data!$AN$2:$AN$1857,Data!$AI$2:$AI$1857,A13,Data!$AJ$2:$AJ$1857,1) -> 0.99268835 | C13: =COUNTIFS(Data!$AI$2:$AI$1857,A13,Data!$AJ$2:$AJ$1857,1) -> 8 | E13: =B13/AVERAGE($B$2:$B$53) -> 0.99255102 | G13: =AVERAGEIFS(Data!$BC$2:$BC$1857,Data!$AI$2:$AI$1857,A13,Data!$AH$2:$AH$1857,">=2022",Data!$AH$2:$AH$1857,"<=2024") -> 1.0030365 | H13: =G13 -> 1.0030365
... A53: 52 | B53: =AVERAGEIFS(Data!$AN$2:$AN$1857,Data!$AI$2:$AI$1857,A53,Data!$AJ$2:$AJ$1857,1) -> 0.9411899 | C53: =COUNTIFS(Data!$AI$2:$AI$1857,A53,Data!$AJ$2:$AJ$1857,1) -> 9 | E53: =B53/AVERAGE($B$2:$B$53) -> 0.9410597 | G53: =AVERAGEIFS(Data!$BC$2:$BC$1857,Data!$AI$2:$AI$1857,A53,Data!$AH$2:$AH$1857,">=2022",Data!$AH$2:$AH$1857,"<=2024") -> 0.8928993 | H53: =G53 -> 0.8928993
A55: Average of index (should be 1.0000) | E55: =AVERAGE(E2:E53) -> 1
A57: The improved index is normalized so it averages exactly 1; the baseline ASI is left unnormalized, as in the class demo.

Sheet Data
A1: Week # | B1: Date | C1: Demand | D1: Actual 2025 | E1: sp500_weekly_avg | F1: initial_jobless_claims | G1: tsa_passengers_weekly_avg | H1: wti_spot_usd_per_bbl | I1: brent_spot_usd_per_bbl | J1: regular_gas_usd_per_gal | K1: gdp_saar_bil_usd | L1: transit_unlinked_trips_thous | M1: rotary_rig_count | N1: vehicle_sales_saar_mil | O1: vehicle_miles_mil | P1: pce_saar_bil_usd | Q1: consumer_credit_mil_usd | R1: ev_sales_vehicles | S1: regulated_afv_acquisitions | T1: household_debt_tril_usd | U1: eci_total_comp_index | V1: smoking_adults_pct | W1: refinery_utilization_pct | X1: fed_broad_dollar_index | Y1: home_price_expectation_pct | Z1: inflation_expectation_1y_pct | AA1: mean_annual_earnings_thous_usd | AB1: us_population_thous | AC1: wfh_share_paid_days_pct | AD1: major_holiday_week | AE1: hdd_pop_weighted | AF1: cdd_pop_weighted | AH1: Year | AI1: Week of Year | AJ1: In Training (1/0) | AK1: Covariate 1 | AL1: Covariate 2 | AM1: Trend | AN1: SI | AO1: Seasonal Index | AP1: Deseasonalized Demand | AQ1: dev t | AR1: dev X1 | AS1: dev X2 | AT1: dev y | AU1: Fitted Deseasonalized | AV1: Forecast | AW1: Set | AX1: Actual (scoring) | AY1: Abs % Err | AZ1: Residual (train) | BB1: Baseline Trend (2022–24) | BC1: Baseline SI | BD1: Baseline ASI | BE1: Baseline Forecast | BF1: Baseline Abs % Err | BG1: Demand (0 if blank) | BH1: Signed Err – Model | BI1: Signed Err – Baseline
A2: 1 | B2: 33277 | C2: 6621 | F2: 483000 | H2: 21.304 | I2: 20.626 | J2: 1.139 | M2: 1136 | W2: 84.2 | AD2: 0 | AE2: 18.5 | AF2: 0 | AH2: =YEAR(B2) -> 1991 | AI2: =MIN(52,INT((B2-DATE(AH2,1,1))/7)+1) -> 6 | AJ2: =IF(AND(ISNUMBER(C2),ISNUMBER(AK2),ISNUMBER(AL2),AH2>=Inputs!$B$5,AH2<=Inputs!$B$6,AH2<>Inputs!$B$7,AH2<>Inputs!$B$8),1,0) -> 0 | AK2: =IF(INDEX($E2:$AF2,Inputs!$C$10)="","",INDEX($E2:$AF2,Inputs!$C$10)) | AL2: =IF(INDEX($E2:$AF2,Inputs!$C$11)="","",INDEX($E2:$AF2,Inputs!$C$11)) -> 483000 | AM2: =Regression!$C$5+Regression!$C$6*A2 -> 10845.377 | AN2: =IF(AJ2=1,C2/AM2,"") | AO2: =INDEX('Seasonal Index'!$E$2:$E$53,AI2) -> 0.93990302 | AP2: =IF(AJ2=1,C2/AO2,"") | AQ2: =IF(AJ2=1,A2-Regression!$C$15,0) -> 0 | AR2: =IF(AJ2=1,AK2-Regression!$D$15,0) -> 0 | AS2: =IF(AJ2=1,AL2-Regression!$E$15,0) -> 0 | AT2: =IF(AJ2=1,AP2-Regression!$F$15,0) -> 0 | AU2: =IF(AND(ISNUMBER(AK2),ISNUMBER(AL2)),Regression!$C$38+Regression!$D$38*A2+Regression!$E$38*AK2+Regression!$F$38*AL2,"") | AV2: =IF(ISNUMBER(AU2),AU2*AO2,"") | AW2: =IF(AJ2=1,"Train",IF(AH2=Inputs!$B$6+1,"Validation",IF(AH2>Inputs!$B$6+1,"Forecast","Not used"))) -> Not used | AX2: =IF(ISNUMBER(C2),C2,IF(ISNUMBER(D2),D2,"")) -> 6621 | AY2: =IF(AND(AW2="Validation",ISNUMBER(AX2),ISNUMBER(AV2)),ABS(AX2-AV2)/AX2,"") | AZ2: =IF(AJ2=1,AP2-AU2,0) -> 0 | BB2: =Regression!$C$45+Regression!$C$46*A2 -> 6145.839 | BC2: =IF(AND(AH2>=2022,AH2<=2024),C2/BB2,"") | BD2: =INDEX('Seasonal Index'!$H$2:$H$53,AI2) -> 0.95301266 | BE2: =IF(AH2>=2022,BB2*BD2,"") | BF2: =IF(AND(AW2="Validation",ISNUMBER(AX2),ISNUMBER(BE2)),ABS(AX2-BE2)/AX2,"") | BG2: =IF(ISNUMBER(C2),C2,0) -> 6621 | BH2: =IF(ISNUMBER(AY2),AV2-AX2,0) -> 0 | BI2: =IF(ISNUMBER(AY2),BE2-AX2,0) -> 0
A3: 2 | B3: 33284 | C3: 6433 | F3: 480000 | H3: 22.116 | I3: 20.436 | J3: 1.106 | M3: 1136 | W3: 84.2 | AD3: 0 | AE3: 145.9 | AF3: 0.7 | AH3: =YEAR(B3) -> 1991 | AI3: =MIN(52,INT((B3-DATE(AH3,1,1))/7)+1) -> 7 | AJ3: =IF(AND(ISNUMBER(C3),ISNUMBER(AK3),ISNUMBER(AL3),AH3>=Inputs!$B$5,AH3<=Inputs!$B$6,AH3<>Inputs!$B$7,AH3<>Inputs!$B$8),1,0) -> 0 | AK3: =IF(INDEX($E3:$AF3,Inputs!$C$10)="","",INDEX($E3:$AF3,Inputs!$C$10)) | AL3: =IF(INDEX($E3:$AF3,Inputs!$C$11)="","",INDEX($E3:$AF3,Inputs!$C$11)) -> 480000 | AM3: =Regression!$C$5+Regression!$C$6*A3 -> 10844.205 | AN3: =IF(AJ3=1,C3/AM3,"") | AO3: =INDEX('Seasonal Index'!$E$2:$E$53,AI3) -> 0.96316209 | AP3: =IF(AJ3=1,C3/AO3,"") | AQ3: =IF(AJ3=1,A3-Regression!$C$15,0) -> 0 | AR3: =IF(AJ3=1,AK3-Regression!$D$15,0) -> 0 | AS3: =IF(AJ3=1,AL3-Regression!$E$15,0) -> 0 | AT3: =IF(AJ3=1,AP3-Regression!$F$15,0) -> 0 | AU3: =IF(AND(ISNUMBER(AK3),ISNUMBER(AL3)),Regression!$C$38+Regression!$D$38*A3+Regression!$E$38*AK3+Regression!$F$38*AL3,"") | AV3: =IF(ISNUMBER(AU3),AU3*AO3,"") | AW3: =IF(AJ3=1,"Train",IF(AH3=Inputs!$B$6+1,"Validation",IF(AH3>Inputs!$B$6+1,"Forecast","Not used"))) -> Not used | AX3: =IF(ISNUMBER(C3),C3,IF(ISNUMBER(D3),D3,"")) -> 6433 | AY3: =IF(AND(AW3="Validation",ISNUMBER(AX3),ISNUMBER(AV3)),ABS(AX3-AV3)/AX3,"") | AZ3: =IF(AJ3=1,AP3-AU3,0) -> 0 | BB3: =Regression!$C$45+Regression!$C$46*A3 -> 6147.3985 | BC3: =IF(AND(AH3>=2022,AH3<=2024),C3/BB3,"") | BD3: =INDEX('Seasonal Index'!$H$2:$H$53,AI3) -> 0.98161871 | BE3: =IF(AH3>=2022,BB3*BD3,"") | BF3: =IF(AND(AW3="Validation",ISNUMBER(AX3),ISNUMBER(BE3)),ABS(AX3-BE3)/AX3,"") | BG3: =IF(ISNUMBER(C3),C3,0) -> 6433 | BH3: =IF(ISNUMBER(AY3),AV3-AX3,0) -> 0 | BI3: =IF(ISNUMBER(AY3),BE3-AX3,0) -> 0
A4: 3 | B4: 33291 | C4: 6582 | F4: 474000 | H4: 19.38 | I4: 18.126 | J4: 1.078 | M4: 1136 | N4: 11.829 | W4: 84.2 | AD4: 0 | AE4: 130.1 | AF4: 1.5 | AH4: =YEAR(B4) -> 1991 | AI4: =MIN(52,INT((B4-DATE(AH4,1,1))/7)+1) -> 8 | AJ4: =IF(AND(ISNUMBER(C4),ISNUMBER(AK4),ISNUMBER(AL4),AH4>=Inputs!$B$5,AH4<=Inputs!$B$6,AH4<>Inputs!$B$7,AH4<>Inputs!$B$8),1,0) -> 0 | AK4: =IF(INDEX($E4:$AF4,Inputs!$C$10)="","",INDEX($E4:$AF4,Inputs!$C$10)) | AL4: =IF(INDEX($E4:$AF4,Inputs!$C$11)="","",INDEX($E4:$AF4,Inputs!$C$11)) -> 474000 | AM4: =Regression!$C$5+Regression!$C$6*A4 -> 10843.032 | AN4: =IF(AJ4=1,C4/AM4,"") | AO4: =INDEX('Seasonal Index'!$E$2:$E$53,AI4) -> 0.97838706 | AP4: =IF(AJ4=1,C4/AO4,"") | AQ4: =IF(AJ4=1,A4-Regression!$C$15,0) -> 0 | AR4: =IF(AJ4=1,AK4-Regression!$D$15,0) -> 0 | AS4: =IF(AJ4=1,AL4-Regression!$E$15,0) -> 0 | AT4: =IF(AJ4=1,AP4-Regression!$F$15,0) -> 0 | AU4: =IF(AND(ISNUMBER(AK4),ISNUMBER(AL4)),Regression!$C$38+Regression!$D$38*A4+Regression!$E$38*AK4+Regression!$F$38*AL4,"") | AV4: =IF(ISNUMBER(AU4),AU4*AO4,"") | AW4: =IF(AJ4=1,"Train",IF(AH4=Inputs!$B$6+1,"Validation",IF(AH4>Inputs!$B$6+1,"Forecast","Not used"))) -> Not used | AX4: =IF(ISNUMBER(C4),C4,IF(ISNUMBER(D4),D4,"")) -> 6582 | AY4: =IF(AND(AW4="Validation",ISNUMBER(AX4),ISNUMBER(AV4)),ABS(AX4-AV4)/AX4,"") | AZ4: =IF(AJ4=1,AP4-AU4,0) -> 0 | BB4: =Regression!$C$45+Regression!$C$46*A4 -> 6148.958 | BC4: =IF(AND(AH4>=2022,AH4<=2024),C4/BB4,"") | BD4: =INDEX('Seasonal Index'!$H$2:$H$53,AI4) -> 1.0025159 | BE4: =IF(AH4>=2022,BB4*BD4,"") | BF4: =IF(AND(AW4="Validation",ISNUMBER(AX4),ISNUMBER(BE4)),ABS(AX4-BE4)/AX4,"") | BG4: =IF(ISNUMBER(C4),C4,0) -> 6582 | BH4: =IF(ISNUMBER(AY4),AV4-AX4,0) -> 0 | BI4: =IF(ISNUMBER(AY4),BE4-AX4,0) -> 0
A5: 4 | B5: 33298 | C5: 7224 | F5: 499000 | H5: 18.73 | I5: 18.662 | J5: 1.054 | M5: 1136 | N5: 11.829 | W5: 84.2 | AD5: 0 | AE5: 149.8 | AF5: 0.9 | AH5: =YEAR(B5) -> 1991 | AI5: =MIN(52,INT((B5-DATE(AH5,1,1))/7)+1) -> 9 | AJ5: =IF(AND(ISNUMBER(C5),ISNUMBER(AK5),ISNUMBER(AL5),AH5>=Inputs!$B$5,AH5<=Inputs!$B$6,AH5<>Inputs!$B$7,AH5<>Inputs!$B$8),1,0) -> 0 | AK5: =IF(INDEX($E5:$AF5,Inputs!$C$10)="","",INDEX($E5:$AF5,Inputs!$C$10)) | AL5: =IF(INDEX($E5:$AF5,Inputs!$C$11)="","",INDEX($E5:$AF5,Inputs!$C$11)) -> 499000 | AM5: =Regression!$C$5+Regression!$C$6*A5 -> 10841.859 | AN5: =IF(AJ5=1,C5/AM5,"") | AO5: =INDEX('Seasonal Index'!$E$2:$E$53,AI5) -> 0.98629368 | AP5: =IF(AJ5=1,C5/AO5,"") | AQ5: =IF(AJ5=1,A5-Regression!$C$15,0) -> 0 | AR5: =IF(AJ5=1,AK5-Regression!$D$15,0) -> 0 | AS5: =IF(AJ5=1,AL5-Regression!$E$15,0) -> 0 | AT5: =IF(AJ5=1,AP5-Regression!$F$15,0) -> 0 | AU5: =IF(AND(ISNUMBER(AK5),ISNUMBER(AL5)),Regression!$C$38+Regression!$D$38*A5+Regression!$E$38*AK5+Regression!$F$38*AL5,"") | AV5: =IF(ISNUMBER(AU5),AU5*AO5,"") | AW5: =IF(AJ5=1,"Train",IF(AH5=Inputs!$B$6+1,"Validation",IF(AH5>Inputs!$B$6+1,"Forecast","Not used"))) -> Not used | AX5: =IF(ISNUMBER(C5),C5,IF(ISNUMBER(D5),D5,"")) -> 7224 | AY5: =IF(AND(AW5="Validation",ISNUMBER(AX5),ISNUMBER(AV5)),ABS(AX5-AV5)/AX5,"") | AZ5: =IF(AJ5=1,AP5-AU5,0) -> 0 | BB5: =Regression!$C$45+Regression!$C$46*A5 -> 6150.5175 | BC5: =IF(AND(AH5>=2022,AH5<=2024),C5/BB5,"") | BD5: =INDEX('Seasonal Index'!$H$2:$H$53,AI5) -> 1.0104104 | BE5: =IF(AH5>=2022,BB5*BD5,"") | BF5: =IF(AND(AW5="Validation",ISNUMBER(AX5),ISNUMBER(BE5)),ABS(AX5-BE5)/AX5,"") | BG5: =IF(ISNUMBER(C5),C5,0) -> 7224 | BH5: =IF(ISNUMBER(AY5),AV5-AX5,0) -> 0 | BI5: =IF(ISNUMBER(AY5),BE5-AX5,0) -> 0
A6: 5 | B6: 33305 | C6: 6875 | F6: 488000 | H6: 19.856 | I6: 19.77 | J6: 1.025 | M6: 1068 | N6: 11.829 | P6: 3841 | W6: 82.8 | AD6: 0 | AE6: 111.1 | AF6: 1.8 | AH6: =YEAR(B6) -> 1991 | AI6: =MIN(52,INT((B6-DATE(AH6,1,1))/7)+1) -> 10 | AJ6: =IF(AND(ISNUMBER(C6),ISNUMBER(AK6),ISNUMBER(AL6),AH6>=Inputs!$B$5,AH6<=Inputs!$B$6,AH6<>Inputs!$B$7,AH6<>Inputs!$B$8),1,0) -> 0 | AK6: =IF(INDEX($E6:$AF6,Inputs!$C$10)="","",INDEX($E6:$AF6,Inputs!$C$10)) | AL6: =IF(INDEX($E6:$AF6,Inputs!$C$11)="","",INDEX($E6:$AF6,Inputs!$C$11)) -> 488000 | AM6: =Regression!$C$5+Regression!$C$6*A6 -> 10840.687 | AN6: =IF(AJ6=1,C6/AM6,"") | AO6: =INDEX('Seasonal Index'!$E$2:$E$53,AI6) -> 0.99527491 | AP6: =IF(AJ6=1,C6/AO6,"") | AQ6: =IF(AJ6=1,A6-Regression!$C$15,0) -> 0 | AR6: =IF(AJ6=1,AK6-Regression!$D$15,0) -> 0 | AS6: =IF(AJ6=1,AL6-Regression!$E$15,0) -> 0 | AT6: =IF(AJ6=1,AP6-Regression!$F$15,0) -> 0 | AU6: =IF(AND(ISNUMBER(AK6),ISNUMBER(AL6)),Regression!$C$38+Regression!$D$38*A6+Regression!$E$38*AK6+Regression!$F$38*AL6,"") | AV6: =IF(ISNUMBER(AU6),AU6*AO6,"") | AW6: =IF(AJ6=1,"Train",IF(AH6=Inputs!$B$6+1,"Validation",IF(AH6>Inputs!$B$6+1,"Forecast","Not used"))) -> Not used | AX6: =IF(ISNUMBER(C6),C6,IF(ISNUMBER(D6),D6,"")) -> 6875 | AY6: =IF(AND(AW6="Validation",ISNUMBER(AX6),ISNUMBER(AV6)),ABS(AX6-AV6)/AX6,"") | AZ6: =IF(AJ6=1,AP6-AU6,0) -> 0 | BB6: =Regression!$C$45+Regression!$C$46*A6 -> 6152.077 | BC6: =IF(AND(AH6>=2022,AH6<=2024),C6/BB6,"") | BD6: =INDEX('Seasonal Index'!$H$2:$H$53,AI6) -> 1.0119262 | BE6: =IF(AH6>=2022,BB6*BD6,"") | BF6: =IF(AND(AW6="Validation",ISNUMBER(AX6),ISNUMBER(BE6)),ABS(AX6-BE6)/AX6,"") | BG6: =IF(ISNUMBER(C6),C6,0) -> 6875 | BH6: =IF(ISNUMBER(AY6),AV6-AX6,0) -> 0 | BI6: =IF(ISNUMBER(AY6),BE6-AX6,0) -> 0
A7: 6 | B7: 33312 | C7: 6947 | F7: 499000 | H7: 19.894 | I7: 19.278 | J7: 1.045 | M7: 1068 | N7: 11.829 | P7: 3841 | W7: 82.8 | AD7: 0 | AE7: 148 | AF7: 0.7 | AH7: =YEAR(B7) -> 1991 | AI7: =MIN(52,INT((B7-DATE(AH7,1,1))/7)+1) -> 11 | AJ7: =IF(AND(ISNUMBER(C7),ISNUMBER(AK7),ISNUMBER(AL7),AH7>=Inputs!$B$5,AH7<=Inputs!$B$6,AH7<>Inputs!$B$7,AH7<>Inputs!$B$8),1,0) -> 0 | AK7: =IF(INDEX($E7:$AF7,Inputs!$C$10)="","",INDEX($E7:$AF7,Inputs!$C$10)) | AL7: =IF(INDEX($E7:$AF7,Inputs!$C$11)="","",INDEX($E7:$AF7,Inputs!$C$11)) -> 499000 | AM7: =Regression!$C$5+Regression!$C$6*A7 -> 10839.514 | AN7: =IF(AJ7=1,C7/AM7,"") | AO7: =INDEX('Seasonal Index'!$E$2:$E$53,AI7) -> 1.0021278 | AP7: =IF(AJ7=1,C7/AO7,"") | AQ7: =IF(AJ7=1,A7-Regression!$C$15,0) -> 0 | AR7: =IF(AJ7=1,AK7-Regression!$D$15,0) -> 0 | AS7: =IF(AJ7=1,AL7-Regression!$E$15,0) -> 0 | AT7: =IF(AJ7=1,AP7-Regression!$F$15,0) -> 0 | AU7: =IF(AND(ISNUMBER(AK7),ISNUMBER(AL7)),Regression!$C$38+Regression!$D$38*A7+Regression!$E$38*AK7+Regression!$F$38*AL7,"") | AV7: =IF(ISNUMBER(AU7),AU7*AO7,"") | AW7: =IF(AJ7=1,"Train",IF(AH7=Inputs!$B$6+1,"Validation",IF(AH7>Inputs!$B$6+1,"Forecast","Not used"))) -> Not used | AX7: =IF(ISNUMBER(C7),C7,IF(ISNUMBER(D7),D7,"")) -> 6947 | AY7: =IF(AND(AW7="Validation",ISNUMBER(AX7),ISNUMBER(AV7)),ABS(AX7-AV7)/AX7,"") | AZ7: =IF(AJ7=1,AP7-AU7,0) -> 0 | BB7: =Regression!$C$45+Regression!$C$46*A7 -> 6153.6365 | BC7: =IF(AND(AH7>=2022,AH7<=2024),C7/BB7,"") | BD7: =INDEX('Seasonal Index'!$H$2:$H$53,AI7) -> 1.0050202 | BE7: =IF(AH7>=2022,BB7*BD7,"") | BF7: =IF(AND(AW7="Validation",ISNUMBER(AX7),ISNUMBER(BE7)),ABS(AX7-BE7)/AX7,"") | BG7: =IF(ISNUMBER(C7),C7,0) -> 6947 | BH7: =IF(ISNUMBER(AY7),AV7-AX7,0) -> 0 | BI7: =IF(ISNUMBER(AY7),BE7-AX7,0) -> 0
A8: 7 | B8: 33319 | C8: 7328 | F8: 498000 | H8: 20.304 | I8: 18.796 | J8: 1.043 | M8: 1068 | N8: 12.409 | O8: 157889 | P8: 3841 | W8: 82.8 | AD8: 0 | AE8: 104.9 | AF8: 3.3 | AH8: =YEAR(B8) -> 1991 | AI8: =MIN(52,INT((B8-DATE(AH8,1,1))/7)+1) -> 12 | AJ8: =IF(AND(ISNUMBER(C8),ISNUMBER(AK8),ISNUMBER(AL8),AH8>=Inputs!$B$5,AH8<=Inputs!$B$6,AH8<>Inputs!$B$7,AH8<>Inputs!$B$8),1,0) -> 0 | AK8: =IF(INDEX($E8:$AF8,Inputs!$C$10)="","",INDEX($E8:$AF8,Inputs!$C$10)) -> 157889 | AL8: =IF(INDEX($E8:$AF8,Inputs!$C$11)="","",INDEX($E8:$AF8,Inputs!$C$11)) -> 498000 | AM8: =Regression!$C$5+Regression!$C$6*A8 -> 10838.341 | AN8: =IF(AJ8=1,C8/AM8,"") | AO8: =INDEX('Seasonal Index'!$E$2:$E$53,AI8) -> 0.99255102 | AP8: =IF(AJ8=1,C8/AO8,"") | AQ8: =IF(AJ8=1,A8-Regression!$C$15,0) -> 0 | AR8: =IF(AJ8=1,AK8-Regression!$D$15,0) -> 0 | AS8: =IF(AJ8=1,AL8-Regression!$E$15,0) -> 0 | AT8: =IF(AJ8=1,AP8-Regression!$F$15,0) -> 0 | AU8: =IF(AND(ISNUMBER(AK8),ISNUMBER(AL8)),Regression!$C$38+Regression!$D$38*A8+Regression!$E$38*AK8+Regression!$F$38*AL8,"") -> 10522.407 | AV8: =IF(ISNUMBER(AU8),AU8*AO8,"") -> 10444.026 | AW8: =IF(AJ8=1,"Train",IF(AH8=Inputs!$B$6+1,"Validation",IF(AH8>Inputs!$B$6+1,"Forecast","Not used"))) -> Not used | AX8: =IF(ISNUMBER(C8),C8,IF(ISNUMBER(D8),D8,"")) -> 7328 | AY8: =IF(AND(AW8="Validation",ISNUMBER(AX8),ISNUMBER(AV8)),ABS(AX8-AV8)/AX8,"") | AZ8: =IF(AJ8=1,AP8-AU8,0) -> 0 | BB8: =Regression!$C$45+Regression!$C$46*A8 -> 6155.196 | BC8: =IF(AND(AH8>=2022,AH8<=2024),C8/BB8,"") | BD8: =INDEX('Seasonal Index'!$H$2:$H$53,AI8) -> 1.0030365 | BE8: =IF(AH8>=2022,BB8*BD8,"") | BF8: =IF(AND(AW8="Validation",ISNUMBER(AX8),ISNUMBER(BE8)),ABS(AX8-BE8)/AX8,"") | BG8: =IF(ISNUMBER(C8),C8,0) -> 7328 | BH8: =IF(ISNUMBER(AY8),AV8-AX8,0) -> 0 | BI8: =IF(ISNUMBER(AY8),BE8-AX8,0) -> 0
A9: 8 | B9: 33326 | C9: 6777 | F9: 509000 | H9: 19.5825 | I9: 18.275 | J9: 1.047 | M9: 1068 | N9: 12.409 | O9: 157889 | P9: 3841 | W9: 82.8 | AD9: 0 | AE9: 79 | AF9: 7.1 | AH9: =YEAR(B9) -> 1991 | AI9: =MIN(52,INT((B9-DATE(AH9,1,1))/7)+1) -> 13 | AJ9: =IF(AND(ISNUMBER(C9),ISNUMBER(AK9),ISNUMBER(AL9),AH9>=Inputs!$B$5,AH9<=Inputs!$B$6,AH9<>Inputs!$B$7,AH9<>Inputs!$B$8),1,0) -> 0 | AK9: =IF(INDEX($E9:$AF9,Inputs!$C$10)="","",INDEX($E9:$AF9,Inputs!$C$10)) -> 157889 | AL9: =IF(INDEX($E9:$AF9,Inputs!$C$11)="","",INDEX($E9:$AF9,Inputs!$C$11)) -> 509000 | AM9: =Regression!$C$5+Regression!$C$6*A9 -> 10837.169 | AN9: =IF(AJ9=1,C9/AM9,"") | AO9: =INDEX('Seasonal Index'!$E$2:$E$53,AI9) -> 1.0067199 | AP9: =IF(AJ9=1,C9/AO9,"") | AQ9: =IF(AJ9=1,A9-Regression!$C$15,0) -> 0 | AR9: =IF(AJ9=1,AK9-Regression!$D$15,0) -> 0 | AS9: =IF(AJ9=1,AL9-Regression!$E$15,0) -> 0 | AT9: =IF(AJ9=1,AP9-Regression!$F$15,0) -> 0 | AU9: =IF(AND(ISNUMBER(AK9),ISNUMBER(AL9)),Regression!$C$38+Regression!$D$38*A9+Regression!$E$38*AK9+Regression!$F$38*AL9,"") -> 10491.639 | AV9: =IF(ISNUMBER(AU9),AU9*AO9,"") -> 10562.142 | AW9: =IF(AJ9=1,"Train",IF(AH9=Inputs!$B$6+1,"Validation",IF(AH9>Inputs!$B$6+1,"Forecast","Not used"))) -> Not used | AX9: =IF(ISNUMBER(C9),C9,IF(ISNUMBER(D9),D9,"")) -> 6777 | AY9: =IF(AND(AW9="Validation",ISNUMBER(AX9),ISNUMBER(AV9)),ABS(AX9-AV9)/AX9,"") | AZ9: =IF(AJ9=1,AP9-AU9,0) -> 0 | BB9: =Regression!$C$45+Regression!$C$46*A9 -> 6156.7555 | BC9: =IF(AND(AH9>=2022,AH9<=2024),C9/BB9,"") | BD9: =INDEX('Seasonal Index'!$H$2:$H$53,AI9) -> 1.0306249 | BE9: =IF(AH9>=2022,BB9*BD9,"") | BF9: =IF(AND(AW9="Validation",ISNUMBER(AX9),ISNUMBER(BE9)),ABS(AX9-BE9)/AX9,"") | BG9: =IF(ISNUMBER(C9),C9,0) -> 6777 | BH9: =IF(ISNUMBER(AY9),AV9-AX9,0) -> 0 | BI9: =IF(ISNUMBER(AY9),BE9-AX9,0) -> 0
A10: 9 | B10: 33333 | C10: 7503 | F10: 499000 | H10: 19.63 | I10: 17.946 | J10: 1.052 | M10: 984 | N10: 12.409 | O10: 157889 | P10: 3866.7 | W10: 82.8 | AD10: 0 | AE10: 92.3 | AF10: 2.8 | AH10: =YEAR(B10) -> 1991 | AI10: =MIN(52,INT((B10-DATE(AH10,1,1))/7)+1) -> 14 | AJ10: =IF(AND(ISNUMBER(C10),ISNUMBER(AK10),ISNUMBER(AL10),AH10>=Inputs!$B$5,AH10<=Inputs!$B$6,AH10<>Inputs!$B$7,AH10<>Inputs!$B$8),1,0) -> 0 | AK10: =IF(INDEX($E10:$AF10,Inputs!$C$10)="","",INDEX($E10:$AF10,Inputs!$C$10)) -> 157889 | AL10: =IF(INDEX($E10:$AF10,Inputs!$C$11)="","",INDEX($E10:$AF10,Inputs!$C$11)) -> 499000 | AM10: =Regression!$C$5+Regression!$C$6*A10 -> 10835.996 | AN10: =IF(AJ10=1,C10/AM10,"") | AO10: =INDEX('Seasonal Index'!$E$2:$E$53,AI10) -> 0.99471307 | AP10: =IF(AJ10=1,C10/AO10,"") | AQ10: =IF(AJ10=1,A10-Regression!$C$15,0) -> 0 | AR10: =IF(AJ10=1,AK10-Regression!$D$15,0) -> 0 | AS10: =IF(AJ10=1,AL10-Regression!$E$15,0) -> 0 | AT10: =IF(AJ10=1,AP10-Regression!$F$15,0) -> 0 | AU10: =IF(AND(ISNUMBER(AK10),ISNUMBER(AL10)),Regression!$C$38+Regression!$D$38*A10+Regression!$E$38*AK10+Regression!$F$38*AL10,"") -> 10516.627 | AV10: =IF(ISNUMBER(AU10),AU10*AO10,"") -> 10461.027 | AW10: =IF(AJ10=1,"Train",IF(AH10=Inputs!$B$6+1,"Validation",IF(AH10>Inputs!$B$6+1,"Forecast","Not used"))) -> Not used | AX10: =IF(ISNUMBER(C10),C10,IF(ISNUMBER(D10),D10,"")) -> 7503 | AY10: =IF(AND(AW10="Validation",ISNUMBER(AX10),ISNUMBER(AV10)),ABS(AX10-AV10)/AX10,"") | AZ10: =IF(AJ10=1,AP10-AU10,0) -> 0 | BB10: =Regression!$C$45+Regression!$C$46*A10 -> 6158.315 | BC10: =IF(AND(AH10>=2022,AH10<=2024),C10/BB10,"") | BD10: =INDEX('Seasonal Index'!$H$2:$H$53,AI10) -> 0.99994657 | BE10: =IF(AH10>=2022,BB10*BD10,"") | BF10: =IF(AND(AW10="Validation",ISNUMBER(AX10),ISNUMBER(BE10)),ABS(AX10-BE10)/AX10,"") | BG10: =IF(ISNUMBER(C10),C10,0) -> 7503 | BH10: =IF(ISNUMBER(AY10),AV10-AX10,0) -> 0 | BI10: =IF(ISNUMBER(AY10),BE10-AX10,0) -> 0
A11: 10 | B11: 33340 | C11: 6916 | F11: 452000 | H11: 20.892 | I11: 19.172 | J11: 1.066 | M11: 984 | N11: 12.409 | O11: 157889 | P11: 3866.7 | W11: 82.5 | AD11: 0 | AE11: 37.2 | AF11: 14.2 | AH11: =YEAR(B11) -> 1991 | AI11: =MIN(52,INT((B11-DATE(AH11,1,1))/7)+1) -> 15 | AJ11: =IF(AND(ISNUMBER(C11),ISNUMBER(AK11),ISNUMBER(AL11),AH11>=Inputs!$B$5,AH11<=Inputs!$B$6,AH11<>Inputs!$B$7,AH11<>Inputs!$B$8),1,0) -> 0 | AK11: =IF(INDEX($E11:$AF11,Inputs!$C$10)="","",INDEX($E11:$AF11,Inputs!$C$10)) -> 157889 | AL11: =IF(INDEX($E11:$AF11,Inputs!$C$11)="","",INDEX($E11:$AF11,Inputs!$C$11)) -> 452000 | AM11: =Regression!$C$5+Regression!$C$6*A11 -> 10834.823 | AN11: =IF(AJ11=1,C11/AM11,"") | AO11: =INDEX('Seasonal Index'!$E$2:$E$53,AI11) -> 1.0030309 | AP11: =IF(AJ11=1,C11/AO11,"") | AQ11: =IF(AJ11=1,A11-Regression!$C$15,0) -> 0 | AR11: =IF(AJ11=1,AK11-Regression!$D$15,0) -> 0 | AS11: =IF(AJ11=1,AL11-Regression!$E$15,0) -> 0 | AT11: =IF(AJ11=1,AP11-Regression!$F$15,0) -> 0 | AU11: =IF(AND(ISNUMBER(AK11),ISNUMBER(AL11)),Regression!$C$38+Regression!$D$38*A11+Regression!$E$38*AK11+Regression!$F$38*AL11,"") -> 10639.852 | AV11: =IF(ISNUMBER(AU11),AU11*AO11,"") -> 10672.1 | AW11: =IF(AJ11=1,"Train",IF(AH11=Inputs!$B$6+1,"Validation",IF(AH11>Inputs!$B$6+1,"Forecast","Not used"))) -> Not used | AX11: =IF(ISNUMBER(C11),C11,IF(ISNUMBER(D11),D11,"")) -> 6916 | AY11: =IF(AND(AW11="Validation",ISNUMBER(AX11),ISNUMBER(AV11)),ABS(AX11-AV11)/AX11,"") | AZ11: =IF(AJ11=1,AP11-AU11,0) -> 0 | BB11: =Regression!$C$45+Regression!$C$46*A11 -> 6159.8745 | BC11: =IF(AND(AH11>=2022,AH11<=2024),C11/BB11,"") | BD11: =INDEX('Seasonal Index'!$H$2:$H$53,AI11) -> 0.99086023 | BE11: =IF(AH11>=2022,BB11*BD11,"") | BF11: =IF(AND(AW11="Validation",ISNUMBER(AX11),ISNUMBER(BE11)),ABS(AX11-BE11)/AX11,"") | BG11: =IF(ISNUMBER(C11),C11,0) -> 6916 | BH11: =IF(ISNUMBER(AY11),AV11-AX11,0) -> 0 | BI11: =IF(ISNUMBER(AY11),BE11-AX11,0) -> 0
A12: 11 | B12: 33347 | C12: 7045 | F12: 477000 | H12: 21.484 | I12: 19.712 | J12: 1.069 | M12: 984 | N12: 12.848 | O12: 153351 | P12: 3866.7 | W12: 82.5 | AD12: 0 | AE12: 62 | AF12: 14.6 | AH12: =YEAR(B12) -> 1991 | AI12: =MIN(52,INT((B12-DATE(AH12,1,1))/7)+1) -> 16 | AJ12: =IF(AND(ISNUMBER(C12),ISNUMBER(AK12),ISNUMBER(AL12),AH12>=Inputs!$B$5,AH12<=Inputs!$B$6,AH12<>Inputs!$B$7,AH12<>Inputs!$B$8),1,0) -> 0 | AK12: =IF(INDEX($E12:$AF12,Inputs!$C$10)="","",INDEX($E12:$AF12,Inputs!$C$10)) -> 153351 | AL12: =IF(INDEX($E12:$AF12,Inputs!$C$11)="","",INDEX($E12:$AF12,Inputs!$C$11)) -> 477000 | AM12: =Regression!$C$5+Regression!$C$6*A12 -> 10833.651 | AN12: =IF(AJ12=1,C12/AM12,"") | AO12: =INDEX('Seasonal Index'!$E$2:$E$53,AI12) -> 1.0020974 | AP12: =IF(AJ12=1,C12/AO12,"") | AQ12: =IF(AJ12=1,A12-Regression!$C$15,0) -> 0 | AR12: =IF(AJ12=1,AK12-Regression!$D$15,0) -> 0 | AS12: =IF(AJ12=1,AL12-Regression!$E$15,0) -> 0 | AT12: =IF(AJ12=1,AP12-Regression!$F$15,0) -> 0 | AU12: =IF(AND(ISNUMBER(AK12),ISNUMBER(AL12)),Regression!$C$38+Regression!$D$38*A12+Regression!$E$38*AK12+Regression!$F$38*AL12,"") -> 10563.633 | AV12: =IF(ISNUMBER(AU12),AU12*AO12,"") -> 10585.789 | AW12: =IF(AJ12=1,"Train",IF(AH12=Inputs!$B$6+1,"Validation",IF(AH12>Inputs!$B$6+1,"Forecast","Not used"))) -> Not used | AX12: =IF(ISNUMBER(C12),C12,IF(ISNUMBER(D12),D12,"")) -> 7045 | AY12: =IF(AND(AW12="Validation",ISNUMBER(AX12),ISNUMBER(AV12)),ABS(AX12-AV12)/AX12,"") | AZ12: =IF(AJ12=1,AP12-AU12,0) -> 0 | BB12: =Regression!$C$45+Regression!$C$46*A12 -> 6161.434 | BC12: =IF(AND(AH12>=2022,AH12<=2024),C12/BB12,"") | BD12: =INDEX('Seasonal Index'!$H$2:$H$53,AI12) -> 1.01445 | BE12: =IF(AH12>=2022,BB12*BD12,"") | BF12: =IF(AND(AW12="Validation",ISNUMBER(AX12),ISNUMBER(BE12)),ABS(AX12-BE12)/AX12,"") | BG12: =IF(ISNUMBER(C12),C12,0) -> 7045 | BH12: =IF(ISNUMBER(AY12),AV12-AX12,0) -> 0 | BI12: =IF(ISNUMBER(AY12),BE12-AX12,0) -> 0
A13: 12 | B13: 33354 | C13: 6956 | F13: 478000 | H13: 21.188 | I13: 19.632 | J13: 1.09 | M13: 984 | N13: 12.848 | O13: 153351 | P13: 3866.7 | W13: 82.5 | AD13: 0 | AE13: 64.9 | AF13: 9.9 | AH13: =YEAR(B13) -> 1991 | AI13: =MIN(52,INT((B13-DATE(AH13,1,1))/7)+1) -> 17 | AJ13: =IF(AND(ISNUMBER(C13),ISNUMBER(AK13),ISNUMBER(AL13),AH13>=Inputs!$B$5,AH13<=Inputs!$B$6,AH13<>Inputs!$B$7,AH13<>Inputs!$B$8),1,0) -> 0 | AK13: =IF(INDEX($E13:$AF13,Inputs!$C$10)="","",INDEX($E13:$AF13,Inputs!$C$10)) -> 153351 | AL13: =IF(INDEX($E13:$AF13,Inputs!$C$11)="","",INDEX($E13:$AF13,Inputs!$C$11)) -> 478000 | AM13: =Regression!$C$5+Regression!$C$6*A13 -> 10832.478 | AN13: =IF(AJ13=1,C13/AM13,"") | AO13: =INDEX('Seasonal Index'!$E$2:$E$53,AI13) -> 0.98572001 | AP13: =IF(AJ13=1,C13/AO13,"") | AQ13: =IF(AJ13=1,A13-Regression!$C$15,0) -> 0 | AR13: =IF(AJ13=1,AK13-Regression!$D$15,0) -> 0 | AS13: =IF(AJ13=1,AL13-Regression!$E$15,0) -> 0 | AT13: =IF(AJ13=1,AP13-Regression!$F$15,0) -> 0 | AU13: =IF(AND(ISNUMBER(AK13),ISNUMBER(AL13)),Regression!$C$38+Regression!$D$38*A13+Regression!$E$38*AK13+Regression!$F$38*AL13,"") -> 10559.416 | AV13: =IF(ISNUMBER(AU13),AU13*AO13,"") -> 10408.627 | AW13: =IF(AJ13=1,"Train",IF(AH13=Inputs!$B$6+1,"Validation",IF(AH13>Inputs!$B$6+1,"Forecast","Not used"))) -> Not used | AX13: =IF(ISNUMBER(C13),C13,IF(ISNUMBER(D13),D13,"")) -> 6956 | AY13: =IF(AND(AW13="Validation",ISNUMBER(AX13),ISNUMBER(AV13)),ABS(AX13-AV13)/AX13,"") | AZ13: =IF(AJ13=1,AP13-AU13,0) -> 0 | BB13: =Regression!$C$45+Regression!$C$46*A13 -> 6162.9935 | BC13: =IF(AND(AH13>=2022,AH13<=2024),C13/BB13,"") | BD13: =INDEX('Seasonal Index'!$H$2:$H$53,AI13) -> 0.99215359 | BE13: =IF(AH13>=2022,BB13*BD13,"") | BF13: =IF(AND(AW13="Validation",ISNUMBER(AX13),ISNUMBER(BE13)),ABS(AX13-BE13)/AX13,"") | BG13: =IF(ISNUMBER(C13),C13,0) -> 6956 | BH13: =IF(ISNUMBER(AY13),AV13-AX13,0) -> 0 | BI13: =IF(ISNUMBER(AY13),BE13-AX13,0) -> 0
A14: 13 | B14: 33361 | C14: 6976 | F14: 462000 | H14: 21.234 | I14: 19.72 | J14: 1.104 | M14: 984 | N14: 12.848 | O14: 153351 | P14: 3866.7 | W14: 82.5 | AD14: 0 | AE14: 30.2 | AF14: 21.4 | AH14: =YEAR(B14) -> 1991 | AI14: =MIN(52,INT((B14-DATE(AH14,1,1))/7)+1) -> 18 | AJ14: =IF(AND(ISNUMBER(C14),ISNUMBER(AK14),ISNUMBER(AL14),AH14>=Inputs!$B$5,AH14<=Inputs!$B$6,AH14<>Inputs!$B$7,AH14<>Inputs!$B$8),1,0) -> 0 | AK14: =IF(INDEX($E14:$AF14,Inputs!$C$10)="","",INDEX($E14:$AF14,Inputs!$C$10)) -> 153351 | AL14: =IF(INDEX($E14:$AF14,Inputs!$C$11)="","",INDEX($E14:$AF14,Inputs!$C$11)) -> 462000 | AM14: =Regression!$C$5+Regression!$C$6*A14 -> 10831.305 | AN14: =IF(AJ14=1,C14/AM14,"") | AO14: =INDEX('Seasonal Index'!$E$2:$E$53,AI14) -> 1.0181402 | AP14: =IF(AJ14=1,C14/AO14,"") | AQ14: =IF(AJ14=1,A14-Regression!$C$15,0) -> 0 | AR14: =IF(AJ14=1,AK14-Regression!$D$15,0) -> 0 | AS14: =IF(AJ14=1,AL14-Regression!$E$15,0) -> 0 | AT14: =IF(AJ14=1,AP14-Regression!$F$15,0) -> 0 | AU14: =IF(AND(ISNUMBER(AK14),ISNUMBER(AL14)),Regression!$C$38+Regression!$D$38*A14+Regression!$E$38*AK14+Regression!$F$38*AL14,"") -> 10600.334 | AV14: =IF(ISNUMBER(AU14),AU14*AO14,"") -> 10792.626 | AW14: =IF(AJ14=1,"Train",IF(AH14=Inputs!$B$6+1,"Validation",IF(AH14>Inputs!$B$6+1,"Forecast","Not used"))) -> Not used | AX14: =IF(ISNUMBER(C14),C14,IF(ISNUMBER(D14),D14,"")) -> 6976 | AY14: =IF(AND(AW14="Validation",ISNUMBER(AX14),ISNUMBER(AV14)),ABS(AX14-AV14)/AX14,"") | AZ14: =IF(AJ14=1,AP14-AU14,0) -> 0 | BB14: =Regression!$C$45+Regression!$C$46*A14 -> 6164.553 | BC14: =IF(AND(AH14>=2022,AH14<=2024),C14/BB14,"") | BD14: =INDEX('Seasonal Index'!$H$2:$H$53,AI14) -> 1.0188494 | BE14: =IF(AH14>=2022,BB14*BD14,"") | BF14: =IF(AND(AW14="Validation",ISNUMBER(AX14),ISNUMBER(BE14)),ABS(AX14-BE14)/AX14,"") | BG14: =IF(ISNUMBER(C14),C14,0) -> 6976 | BH14: =IF(ISNUMBER(AY14),AV14-AX14,0) -> 0 | BI14: =IF(ISNUMBER(AY14),BE14-AX14,0) -> 0
A15: 14 | B15: 33368 | C15: 7185 | F15: 451000 | H15: 21.69 | I15: 19.812 | J15: 1.113 | K15: 6035.178 | M15: 929 | N15: 12.848 | O15: 153351 | P15: 3913 | W15: 84.4 | AD15: 0 | AE15: 27.9 | AF15: 19.4 | AH15: =YEAR(B15) -> 1991 | AI15: =MIN(52,INT((B15-DATE(AH15,1,1))/7)+1) -> 19 | AJ15: =IF(AND(ISNUMBER(C15),ISNUMBER(AK15),ISNUMBER(AL15),AH15>=Inputs!$B$5,AH15<=Inputs!$B$6,AH15<>Inputs!$B$7,AH15<>Inputs!$B$8),1,0) -> 0 | AK15: =IF(INDEX($E15:$AF15,Inputs!$C$10)="","",INDEX($E15:$AF15,Inputs!$C$10)) -> 153351 | AL15: =IF(INDEX($E15:$AF15,Inputs!$C$11)="","",INDEX($E15:$AF15,Inputs!$C$11)) -> 451000 | AM15: =Regression!$C$5+Regression!$C$6*A15 -> 10830.133 | AN15: =IF(AJ15=1,C15/AM15,"") | AO15: =INDEX('Seasonal Index'!$E$2:$E$53,AI15) -> 1.0133712 | AP15: =IF(AJ15=1,C15/AO15,"") | AQ15: =IF(AJ15=1,A15-Regression!$C$15,0) -> 0 | AR15: =IF(AJ15=1,AK15-Regression!$D$15,0) -> 0 | AS15: =IF(AJ15=1,AL15-Regression!$E$15,0) -> 0 | AT15: =IF(AJ15=1,AP15-Regression!$F$15,0) -> 0 | AU15: =IF(AND(ISNUMBER(AK15),ISNUMBER(AL15)),Regression!$C$38+Regression!$D$38*A15+Regression!$E$38*AK15+Regression!$F$38*AL15,"") -> 10627.977 | AV15: =IF(ISNUMBER(AU15),AU15*AO15,"") -> 10770.087 | AW15: =IF(AJ15=1,"Train",IF(AH15=Inputs!$B$6+1,"Validation",IF(AH15>Inputs!$B$6+1,"Forecast","Not used"))) -> Not used | AX15: =IF(ISNUMBER(C15),C15,IF(ISNUMBER(D15),D15,"")) -> 7185 | AY15: =IF(AND(AW15="Validation",ISNUMBER(AX15),ISNUMBER(AV15)),ABS(AX15-AV15)/AX15,"") | AZ15: =IF(AJ15=1,AP15-AU15,0) -> 0 | BB15: =Regression!$C$45+Regression!$C$46*A15 -> 6166.1125 | BC15: =IF(AND(AH15>=2022,AH15<=2024),C15/BB15,"") | BD15: =INDEX('Seasonal Index'!$H$2:$H$53,AI15) -> 1.0190604 | BE15: =IF(AH15>=2022,BB15*BD15,"") | BF15: =IF(AND(AW15="Validation",ISNUMBER(AX15),ISNUMBER(BE15)),ABS(AX15-BE15)/AX15,"") | BG15: =IF(ISNUMBER(C15),C15,0) -> 7185 | BH15: =IF(ISNUMBER(AY15),AV15-AX15,0) -> 0 | BI15: =IF(ISNUMBER(AY15),BE15-AX15,0) -> 0
A16: 15 | B16: 33375 | C16: 6899 | F16: 446000 | H16: 20.952 | I16: 18.9 | J16: 1.121 | K16: 6035.178 | M16: 929 | N16: 12.038 | O16: 179076 | P16: 3913 | W16: 84.4 | AD16: 0 | AE16: 4.5 | AF16: 42.5 | AH16: =YEAR(B16) -> 1991 | AI16: =MIN(52,INT((B16-DATE(AH16,1,1))/7)+1) -> 20 | AJ16: =IF(AND(ISNUMBER(C16),ISNUMBER(AK16),ISNUMBER(AL16),AH16>=Inputs!$B$5,AH16<=Inputs!$B$6,AH16<>Inputs!$B$7,AH16<>Inputs!$B$8),1,0) -> 0 | AK16: =IF(INDEX($E16:$AF16,Inputs!$C$10)="","",INDEX($E16:$AF16,Inputs!$C$10)) -> 179076 | AL16: =IF(INDEX($E16:$AF16,Inputs!$C$11)="","",INDEX($E16:$AF16,Inputs!$C$11)) -> 446000 | AM16: =Regression!$C$5+Regression!$C$6*A16 -> 10828.96 | AN16: =IF(AJ16=1,C16/AM16,"") | AO16: =INDEX('Seasonal Index'!$E$2:$E$53,AI16) -> 1.0355119 | AP16: =IF(AJ16=1,C16/AO16,"") | AQ16: =IF(AJ16=1,A16-Regression!$C$15,0) -> 0 | AR16: =IF(AJ16=1,AK16-Regression!$D$15,0) -> 0 | AS16: =IF(AJ16=1,AL16-Regression!$E$15,0) -> 0 | AT16: =IF(AJ16=1,AP16-Regression!$F$15,0) -> 0 | AU16: =IF(AND(ISNUMBER(AK16),ISNUMBER(AL16)),Regression!$C$38+Regression!$D$38*A16+Regression!$E$38*AK16+Regression!$F$38*AL16,"") -> 10686.63 | AV16: =IF(ISNUMBER(AU16),AU16*AO16,"") -> 11066.133 | AW16: =IF(AJ16=1,"Train",IF(AH16=Inputs!$B$6+1,"Validation",IF(AH16>Inputs!$B$6+1,"Forecast","Not used"))) -> Not used | AX16: =IF(ISNUMBER(C16),C16,IF(ISNUMBER(D16),D16,"")) -> 6899 | AY16: =IF(AND(AW16="Validation",ISNUMBER(AX16),ISNUMBER(AV16)),ABS(AX16-AV16)/AX16,"") | AZ16: =IF(AJ16=1,AP16-AU16,0) -> 0 | BB16: =Regression!$C$45+Regression!$C$46*A16 -> 6167.672 | BC16: =IF(AND(AH16>=2022,AH16<=2024),C16/BB16,"") | BD16: =INDEX('Seasonal Index'!$H$2:$H$53,AI16) -> 1.0467645 | BE16: =IF(AH16>=2022,BB16*BD16,"") | BF16: =IF(AND(AW16="Validation",ISNUMBER(AX16),ISNUMBER(BE16)),ABS(AX16-BE16)/AX16,"") | BG16: =IF(ISNUMBER(C16),C16,0) -> 6899 | BH16: =IF(ISNUMBER(AY16),AV16-AX16,0) -> 0 | BI16: =IF(ISNUMBER(AY16),BE16-AX16,0) -> 0
A17: 16 | B17: 33382 | C17: 7396 | F17: 448000 | H17: 21.036 | I17: 18.824 | J17: 1.129 | K17: 6035.178 | M17: 929 | N17: 12.038 | O17: 179076 | P17: 3913 | W17: 84.4 | AD17: 0 | AE17: 15.8 | AF17: 31.9 | AH17: =YEAR(B17) -> 1991 | AI17: =MIN(52,INT((B17-DATE(AH17,1,1))/7)+1) -> 21 | AJ17: =IF(AND(ISNUMBER(C17),ISNUMBER(AK17),ISNUMBER(AL17),AH17>=Inputs!$B$5,AH17<=Inputs!$B$6,AH17<>Inputs!$B$7,AH17<>Inputs!$B$8),1,0) -> 0 | AK17: =IF(INDEX($E17:$AF17,Inputs!$C$10)="","",INDEX($E17:$AF17,Inputs!$C$10)) -> 179076 | AL17: =IF(INDEX($E17:$AF17,Inputs!$C$11)="","",INDEX($E17:$AF17,Inputs!$C$11)) -> 448000 | AM17: =Regression!$C$5+Regression!$C$6*A17 -> 10827.787 | AN17: =IF(AJ17=1,C17/AM17,"") | AO17: =INDEX('Seasonal Index'!$E$2:$E$53,AI17) -> 1.0352246 | AP17: =IF(AJ17=1,C17/AO17,"") | AQ17: =IF(AJ17=1,A17-Regression!$C$15,0) -> 0 | AR17: =IF(AJ17=1,AK17-Regression!$D$15,0) -> 0 | AS17: =IF(AJ17=1,AL17-Regression!$E$15,0) -> 0 | AT17: =IF(AJ17=1,AP17-Regression!$F$15,0) -> 0 | AU17: =IF(AND(ISNUMBER(AK17),ISNUMBER(AL17)),Regression!$C$38+Regression!$D$38*A17+Regression!$E$38*AK17+Regression!$F$38*AL17,"") -> 10679.758 | AV17: =IF(ISNUMBER(AU17),AU17*AO17,"") -> 11055.947 | AW17: =IF(AJ17=1,"Train",IF(AH17=Inputs!$B$6+1,"Validation",IF(AH17>Inputs!$B$6+1,"Forecast","Not used"))) -> Not used | AX17: =IF(ISNUMBER(C17),C17,IF(ISNUMBER(D17),D17,"")) -> 7396 | AY17: =IF(AND(AW17="Validation",ISNUMBER(AX17),ISNUMBER(AV17)),ABS(AX17-AV17)/AX17,"") | AZ17: =IF(AJ17=1,AP17-AU17,0) -> 0 | BB17: =Regression!$C$45+Regression!$C$46*A17 -> 6169.2315 | BC17: =IF(AND(AH17>=2022,AH17<=2024),C17/BB17,"") | BD17: =INDEX('Seasonal Index'!$H$2:$H$53,AI17) -> 1.0342763 | BE17: =IF(AH17>=2022,BB17*BD17,"") | BF17: =IF(AND(AW17="Validation",ISNUMBER(AX17),ISNUMBER(BE17)),ABS(AX17-BE17)/AX17,"") | BG17: =IF(ISNUMBER(C17),C17,0) -> 7396 | BH17: =IF(ISNUMBER(AY17),AV17-AX17,0) -> 0 | BI17: =IF(ISNUMBER(AY17),BE17-AX17,0) -> 0
A18: 17 | B18: 33389 | C18: 7287 | F18: 443000 | H18: 21.21 | I18: 18.87 | J18: 1.14 | K18: 6035.178 | M18: 929 | N18: 12.038 | O18: 179076 | P18: 3913 | W18: 84.4 | AD18: 1 | AE18: 3.7 | AF18: 69 | AH18: =YEAR(B18) -> 1991 | AI18: =MIN(52,INT((B18-DATE(AH18,1,1))/7)+1) -> 22 | AJ18: =IF(AND(ISNUMBER(C18),ISNUMBER(AK18),ISNUMBER(AL18),AH18>=Inputs!$B$5,AH18<=Inputs!$B$6,AH18<>Inputs!$B$7,AH18<>Inputs!$B$8),1,0) -> 0 | AK18: =IF(INDEX($E18:$AF18,Inputs!$C$10)="","",INDEX($E18:$AF18,Inputs!$C$10)) -> 179076 | AL18: =IF(INDEX($E18:$AF18,Inputs!$C$11)="","",INDEX($E18:$AF18,Inputs!$C$11)) -> 443000 | AM18: =Regression!$C$5+Regression!$C$6*A18 -> 10826.615 | AN18: =IF(AJ18=1,C18/AM18,"") | AO18: =INDEX('Seasonal Index'!$E$2:$E$53,AI18) -> 1.0139792 | AP18: =IF(AJ18=1,C18/AO18,"") | AQ18: =IF(AJ18=1,A18-Regression!$C$15,0) -> 0 | AR18: =IF(AJ18=1,AK18-Regression!$D$15,0) -> 0 | AS18: =IF(AJ18=1,AL18-Regression!$E$15,0) -> 0 | AT18: =IF(AJ18=1,AP18-Regression!$F$15,0) -> 0 | AU18: =IF(AND(ISNUMBER(AK18),ISNUMBER(AL18)),Regression!$C$38+Regression!$D$38*A18+Regression!$E$38*AK18+Regression!$F$38*AL18,"") -> 10691.47 | AV18: =IF(ISNUMBER(AU18),AU18*AO18,"") -> 10840.928 | AW18: =IF(AJ18=1,"Train",IF(AH18=Inputs!$B$6+1,"Validation",IF(AH18>Inputs!$B$6+1,"Forecast","Not used"))) -> Not used | AX18: =IF(ISNUMBER(C18),C18,IF(ISNUMBER(D18),D18,"")) -> 7287 | AY18: =IF(AND(AW18="Validation",ISNUMBER(AX18),ISNUMBER(AV18)),ABS(AX18-AV18)/AX18,"") | AZ18: =IF(AJ18=1,AP18-AU18,0) -> 0 | BB18: =Regression!$C$45+Regression!$C$46*A18 -> 6170.791 | BC18: =IF(AND(AH18>=2022,AH18<=2024),C18/BB18,"") | BD18: =INDEX('Seasonal Index'!$H$2:$H$53,AI18) -> 1.0395595 | BE18: =IF(AH18>=2022,BB18*BD18,"") | BF18: =IF(AND(AW18="Validation",ISNUMBER(AX18),ISNUMBER(BE18)),ABS(AX18-BE18)/AX18,"") | BG18: =IF(ISNUMBER(C18),C18,0) -> 7287 | BH18: =IF(ISNUMBER(AY18),AV18-AX18,0) -> 0 | BI18: =IF(ISNUMBER(AY18),BE18-AX18,0) -> 0
A19: 18 | B19: 33396 | C19: 7220 | F19: 432000 | H19: 20.634 | I19: 18.554 | J19: 1.138 | K19: 6035.178 | M19: 865 | N19: 12.038 | O19: 179076 | P19: 3907.1 | W19: 83.2 | AD19: 0 | AE19: 3.7 | AF19: 46.7 | AH19: =YEAR(B19) -> 1991 | AI19: =MIN(52,INT((B19-DATE(AH19,1,1))/7)+1) -> 23 | AJ19: =IF(AND(ISNUMBER(C19),ISNUMBER(AK19),ISNUMBER(AL19),AH19>=Inputs!$B$5,AH19<=Inputs!$B$6,AH19<>Inputs!$B$7,AH19<>Inputs!$B$8),1,0) -> 0 | AK19: =IF(INDEX($E19:$AF19,Inputs!$C$10)="","",INDEX($E19:$AF19,Inputs!$C$10)) -> 179076 | AL19: =IF(INDEX($E19:$AF19,Inputs!$C$11)="","",INDEX($E19:$AF19,Inputs!$C$11)) -> 432000 | AM19: =Regression!$C$5+Regression!$C$6*A19 -> 10825.442 | AN19: =IF(AJ19=1,C19/AM19,"") | AO19: =INDEX('Seasonal Index'!$E$2:$E$53,AI19) -> 1.0375597 | AP19: =IF(AJ19=1,C19/AO19,"") | AQ19: =IF(AJ19=1,A19-Regression!$C$15,0) -> 0 | AR19: =IF(AJ19=1,AK19-Regression!$D$15,0) -> 0 | AS19: =IF(AJ19=1,AL19-Regression!$E$15,0) -> 0 | AT19: =IF(AJ19=1,AP19-Regression!$F$15,0) -> 0 | AU19: =IF(AND(ISNUMBER(AK19),ISNUMBER(AL19)),Regression!$C$38+Regression!$D$38*A19+Regression!$E$38*AK19+Regression!$F$38*AL19,"") -> 10719.114 | AV19: =IF(ISNUMBER(AU19),AU19*AO19,"") -> 11121.721 | AW19: =IF(AJ19=1,"Train",IF(AH19=Inputs!$B$6+1,"Validation",IF(AH19>Inputs!$B$6+1,"Forecast","Not used"))) -> Not used | AX19: =IF(ISNUMBER(C19),C19,IF(ISNUMBER(D19),D19,"")) -> 7220 | AY19: =IF(AND(AW19="Validation",ISNUMBER(AX19),ISNUMBER(AV19)),ABS(AX19-AV19)/AX19,"") | AZ19: =IF(AJ19=1,AP19-AU19,0) -> 0 | BB19: =Regression!$C$45+Regression!$C$46*A19 -> 6172.3505 | BC19: =IF(AND(AH19>=2022,AH19<=2024),C19/BB19,"") | BD19: =INDEX('Seasonal Index'!$H$2:$H$53,AI19) -> 1.0378993 | BE19: =IF(AH19>=2022,BB19*BD19,"") | BF19: =IF(AND(AW19="Validation",ISNUMBER(AX19),ISNUMBER(BE19)),ABS(AX19-BE19)/AX19,"") | BG19: =IF(ISNUMBER(C19),C19,0) -> 7220 | BH19: =IF(ISNUMBER(AY19),AV19-AX19,0) -> 0 | BI19: =IF(ISNUMBER(AY19),BE19-AX19,0) -> 0
