Workbook

Sheet Variables
A1: Variable | B1: Description | C1: Time Frame | D1: Time Unit | E1: Links
A2: S&P 500 Index | B2: A stock market index that may influence investment decisions and consumer confidence, impacting gasoline demand. | C2: 2016 - 2026 | D2: Daily except weekends | E2: S&P 500® | S&P Dow Jones Indices (spglobal.com)
A3: Weekly Jobless Claims | B3: A measure of unemployment trends, which can affect consumer spending on gasoline. | C3: 1967 - 2026 | D3: Weekly | E3: Initial Claims (ICSA) | FRED | St. Louis Fed (stlouisfed.org)
A4: TSA Passenger Throughput | B4: Indicates air travel activity and its impact on airport gasoline sales. | C4: 2019 - 2026 | D4: Daily | E4: Travel Passenger Throughputs
A5: US Spot Market Prices of Crude Oil | B5: The cost of crude oil in the United States, influencing gasoline production costs and prices. | C5: 1986 - 2026 | D5: Weekly | E5: Weekly Cushing, OK WTI Spot Price FOB (Dollars per Barrel) (eia.gov)
A6: Europe Spot Market Prices of Crude Oil | B6: Crude oil prices in Europe, affecting international oil markets and gasoline pricing. | C6: 1987 - 2026 | D6: Weekly | E6: Weekly Europe Brent Spot Price FOB (Dollars per Barrel) (eia.gov)
A7: Regular (87 Octane) Gasoline Prices | B7: The cost of regular gasoline, a key factor in consumer gasoline purchasing decisions. | C7: 1990 - 2026 | D7: Weekly | E7: Weekly U.S. Regular All Formulations Retail Gasoline Prices (Dollars per Gallon) (eia.gov)
A8: USA GDP | B8: The overall economic output of the United States, influencing gasoline consumption patterns. | C8: 1947 - 2026 | D8: Quarterly | E8: Gross Domestic Product (GDP) | FRED | St. Louis Fed (stlouisfed.org)
A9: Public Transport Ridership | B9: Trends in the use of public transportation, which can affect gasoline demand. | C9: 1990 - 2026 | D9: Quarterly | E9: Ridership Data Archives - APTA
A10: Rig Count | B10: The number of active drilling rigs, providing insight into future oil and gasoline supply. | C10: 1973 - 2026 | D10: Monthly | E10: U.S. Crude Oil and Natural Gas Drilling Activity
A11: Automobile Sales | B11: Sales of vehicles, impacting gasoline consumption through vehicle ownership. | C11: 1976 - 2026 | D11: Monthly | E11: Total Vehicle Sales (TOTALSA) | FRED | St. Louis Fed (stlouisfed.org)
A12: Highway Traffic Data | B12: Data on road traffic and congestion levels, influencing gasoline usage patterns. | C12: 2002 - 2026 | D12: Monthly | E12: Office of Highway Policy Information - Policy | Federal Highway Administration (dot.gov)
... A30: Daylight Hours | B30: Hours of daylight at the U.S. population center for each week, a deterministic seasonal term added because the demand series is not seasonally adjusted and no other variable captures the regular spring-summer rise in driving. | C30: 1991 - 2026 | D30: Weekly (Ending Friday) | E30: NOAA solar declination approximation (computed in-sheet)

Sheet Hypotheses
A1: Predictor | B1: Hypothesis | C1: Magnitude | D1: Direction
A2: US Spot Market Prices of Crude Oil | B2: Higher crude prices often deter gasoline consumption due to price elasticity. | C2: High | D2: Negative | F2: Karina's personal hypotheses: you can challenge or disagree.
A3: Regular (87 Octane) Gasoline Prices | B3: Higher gasoline prices generally deter consumption. | C3: High | D3: Negative
A4: EV Sales | B4: Increased EV sales may decrease gasoline demand as more people use electric vehicles. | C4: High | D4: Negative
A5: EV Regulations | B5: Higher EV regulations decrease gasoline demand as fleet companies are forced to transition away from gasoline vehicles. | C5: High | D5: Negative
A6: Highway Traffic Data | B6: Increased highway traffic indicates greater vehicle usage, leading to higher gasoline demand. | C6: High | D6: Positive
A7: S&P 500 Index | B7: Higher stock market performance may indicate a booming economy, leading to increased gasoline demand. | C7: Medium | D7: Positive
A8: Weekly Jobless Claims | B8: Higher jobless claims indicate economic downturns, which may result in decreased gasoline demand. | C8: Medium | D8: Negative
A9: Europe Spot Market Prices of Crude Oil | B9: If European crude prices rise and the US follows, it could deter gasoline demand. | C9: Medium | D9: Negative
A10: USA GDP | B10: Higher GDP indicates a robust economy, potentially driving up gasoline demand. | C10: Medium | D10: Positive
A11: Public Transport Ridership | B11: Increased public transport ridership may lead to decreased gasoline demand. | C11: Medium | D11: Negative
A12: Automobile Sales | B12: Higher sales, especially of gasoline-based vehicles, indicate potential increased gasoline demand. | C12: Medium | D12: Positive
A13: Personal Consumption Expenditures | B13: Higher consumer spending can suggest increased economic activity and gasoline demand. | C13: Medium | D13: Positive
A14: Refinery Utilization | B14: Higher refinery utilization can lead to increased gasoline supply, potentially affecting demand balance. | C14: Medium | D14: Positive
... A16: Inflation Expectations | B16: Higher inflation expectations could deter spending, potentially reducing gasoline demand. | C16: Medium | D16: Negative
A17: Employee Earnings | B17: Higher earnings boost disposable income, possibly increasing gasoline demand due to increased travel. | C17: Medium | D17: Positive | O17: -
A18: TSA Passenger Throughput | B18: An increase in passenger throughput may indicate higher air travel, potentially reducing gasoline demand. | C18: Low | D18: Negative
A19: Rig Count | B19: A higher rig count suggests increased domestic production, potentially influencing gasoline demand. | C19: Low | D19: Positive
A20: Consumer Credit Data | B20: Higher consumer credit indicates more spending, including on vehicles and travel, potentially driving gasoline demand. | C20: Low | D20: Positive
A21: Household Debt and Credit | B21: Higher household debt may deter spending, including on travel, potentially reducing gasoline demand. | C21: Low | D21: Negative
A22: Labor Costs | B22: Rising labor costs could affect gasoline production costs, potentially affecting gasoline demand. | C22: Low | D22: Negative
A23: Smoking Consumption | B23: Decrease in smoking might indicate health-conscious decisions, including eco-friendly transportation choices. | C23: Low | D23: Negative
A24: Housing Market Expectations | B24: A booming housing market might lead to increased travel, potentially driving up gasoline demand. | C24: Low | D24: Positive
A25: Major Driving Holiday Week | B25: Weeks containing Memorial Day, July 4, Labor Day, Thanksgiving, Christmas, or New Year's Day see a surge in road trips and family travel, which should raise gasoline demand relative to an ordinary week. But Thanksgiving and Christmas weeks also carry days when many people don't commute or run errands at all, so the net effect could go either way depending on which force dominates. | C25: High | D25: Conditional
A26: Work From Home Share | B26: A higher share of work-from-home days should lower gasoline demand, since commuting is a large and regular share of vehicle miles driven and this trip disappears entirely on remote days. This is a structural shift rather than a short-term fluctuation, and expected to matter most in explaining why demand hasn't returned to pre-2020 levels rather than in explaining week-to-week noise. | C26: High | D26: Negative
A27: US Population-Weighted HDD | B27: Severe winter cold and winter storms reduce vehicle miles traveled and suppress gasoline demand. | C27: Medium | D27: Negative
A28: US Population-Weighted CDD | B28: Warmer summer temperatures increase vacation driving trips and air conditioning load. | C28: Medium | D28: Positive
A29: Daylight Hours | B29: Longer days support more evening and discretionary driving and coincide with the summer travel season, so demand should rise with daylight. Part of this overlaps with temperature (HDD/CDD), but daylight tracks the calendar cycle itself rather than weather surprises. | C29: Medium | D29: Positive

Sheet Simple Linear Regression
A1: SUMMARY OUTPUT
A3: Regression Statistics
A4: Multiple R | B4: 0.59469786
A5: R Square | B5: 0.35366554
A6: Adjusted R Square | B6: 0.35329976
A7: Standard Error | B7: 589.22746
A8: Observations | B8: 1769
A10: ANOVA
B11: df | C11: SS | D11: MS | E11: F | F11: Significance F
A12: Regression | B12: 1 | C12: 3.3568964e+08 | D12: 3.3568964e+08 | E12: 966.87869 | F12: 1.1029353e-169
A13: Residual | B13: 1767 | C13: 6.1348295e+08 | D13: 347188.99
A14: Total | B14: 1768 | C14: 9.4917259e+08
B16: Coefficients | C16: Standard Error | D16: t Stat | E16: P-value | F16: Lower 95% | G16: Upper 95% | H16: Lower 95.0% | I16: Upper 95.0%
A17: Intercept | B17: 7885.3363 | C17: 28.030652 | D17: 281.31119 | E17: 0 | F17: 7830.3596 | G17: 7940.3131 | H17: 7830.3596 | I17: 7940.3131
A18: X Variable 1 | B18: 0.85303708 | C18: 0.027433544 | D18: 31.094673 | E18: 1.1029353e-169 | F18: 0.79923147 | G18: 0.9068427 | H18: 0.79923147 | I18: 0.9068427

Sheet Target
A1: Week # | B1: Date | C1: Demand | D1: sp500_weekly_avg | E1: initial_jobless_claims | F1: tsa_passengers_weekly_avg | G1: wti_spot_usd_per_bbl | H1: brent_spot_usd_per_bbl | I1: regular_gas_usd_per_gal | J1: gdp_saar_bil_usd | K1: transit_unlinked_trips_thous | L1: rotary_rig_count | M1: vehicle_sales_saar_mil | N1: vehicle_miles_mil | O1: pce_saar_bil_usd | P1: consumer_credit_mil_usd | Q1: ev_sales_vehicles | R1: regulated_afv_acquisitions | S1: household_debt_tril_usd | T1: eci_total_comp_index | U1: smoking_adults_pct | V1: refinery_utilization_pct | W1: fed_broad_dollar_index | X1: home_price_expectation_pct | Y1: inflation_expectation_1y_pct | Z1: mean_annual_earnings_thous_usd | AA1: us_population_thous | AB1: wfh_share_paid_days_pct | AC1: major_holiday_week | AD1: hdd_pop_weighted | AE1: cdd_pop_weighted | AF1: daylight_hours | AG1: Model C | AH1: Simple Linear Regression Model | AI1: forward selection | AJ1: backward selection | AK1: Restricted Model C | AL1: gas*VMT interaction | AM1: M1 Weather + Holiday | AN1: major holiday week and daylgiht hours interaction | AO1: gas*VMT interaction 2 | AP1: gas*vmt interaction traine on 08-24 | AQ1: INT1 term: Gas×VMT (I×N) | AR1: INT2 term: Gas×Jobless (I×E) | AS1: INT3 term: Holiday×Daylight (AC×AF) | AT1: Pred Demand – Base | AU1: Pred Demand – Int1: Gas x VMT | AV1: Pred Demand – Int2: Gas x Jobless | AW1: Pred Demand – Int3: Holiday x Daylight | AX1: Pred Demand – Final: Gas x VMT (refit 1991-2024) | AY1: Gas * Jobless | AZ1: Holiday*Daylight | BA1: Gas*VMT
A2: 1 | B2: 33277 | C2: 6621 | E2: 483000 | G2: 21.304 | H2: 20.626 | I2: 1.139 | L2: 1136 | V2: 84.2 | AC2: 0 | AD2: 18.5 | AE2: 0 | AF2: 10.2996 | AG2: =6753.47943187+0.36116788*I2+0.01252571*N2-22.85359542*V2+0.00407811*AA2-0.00067349*E2 -> 4504.3224 | AH2: =A2*'Simple Linear Regression'!$B$18+'Simple Linear Regression'!$B$17 -> 7886.1894 | AI2: =7491.3971+0.0137554*N2-0.00058829*E2-34.3283*V2+0.30565*L2+54.6031*M2 -> 4664.0286 | AJ2: =7491.3971-0.00058829*E2+0.30565*L2+54.6031*M2+0.0137554*N2-34.3283*V2 -> 4664.0286 | AL2: =2192.59+2373.87*I2+0.0316653*N2-15.7623*V2+0.00202406*AA2-0.000740146*E2-0.00963493*(I2*N2) -> 3211.7518 | AM2: =5205.907083+122.0638992*I2+13.609808*(N2/1000)-1.245906883*AD2+0.7746840854*AE2-134.2474226*AC2-1547.125689*IF(AND(B2>=DATE(2020,3,20),B2<=DATE(2020,6,26)),1,0) -> 5321.8886 | AN2: =7707.2178-144.397321*AC2+139.5614087*AF2-0.0008594506251*E2-265.7105668*I2-0.02506176117*J2+0.004708026652*N2 -> 8426.8855 | AO2: =IF(N2="","",2190.39 + 2739.06*I2 + 0.034693*N2 - 16.722*V2 - 0.000802*E2 - 1.3691*AD2 + 1.8691*AE2 - 121.7*AC2 + 209.88*IF(AND(B2>=DATE(2020,3,20),B2<=DATE(2020,6,26)),1,0) - 0.011049*(I2*N2)) | AP2: =IF(B2<DATE(2008,1,1),"",3929.06 + 1212.53*I2 - 0.0003097*N2 + 59.426*V2 - 0.0006734*E2 - 1.036*AD2 + 1.2076*AE2 + 94.923*AF2 - 131.43*AC2 - 759.61*IF(AND(B2>=DATE(2020,3,20),B2<=DATE(2020,6,26)),1,0) - 17.324*(I2*V2)) | AQ2: =IF(N2="","",I2*N2) | AR2: =I2*E2 -> 550137 | AS2: =AC2*AF2 -> 0 | AT2: =IF(N2="","",2413.3773+89.103503*I2+0.018847679*N2-5.0917058*V2-0.00064564578*E2+1.4315076*AD2-3.1976817*AE2-66.972905*AC2-217.08397*IF(AND(B2>=DATE(2020,3,20),B2<=DATE(2020,6,26)),1,0)+190.76803*AF2) | AU2: =IF(N2="","",-480.76297+2186.3009*I2+0.033368804*N2-5.3903106*V2-0.00073731439*E2+0.93396876*AD2-1.6242981*AE2-61.304389*AC2-95.472727*IF(AND(B2>=DATE(2020,3,20),B2<=DATE(2020,6,26)),1,0)+156.04851*AF2-0.0087322858*AQ2) | AV2: =IF(N2="","",2518.0489-204.66184*I2+0.019354281*N2-2.3328708*V2-0.0022533804*E2+1.5259709*AD2-3.5842757*AE2-65.580099*AC2-62.828483*IF(AND(B2>=DATE(2020,3,20),B2<=DATE(2020,6,26)),1,0)+200.94286*AF2+0.00080379976*AR2) | AW2: =IF(N2="","",2361.7153+89.223162*I2+0.018847054*N2-5.0210815*V2-0.0006437347*E2+1.4213619*AD2-3.2156123*AE2+167.41121*AC2-224.35191*IF(AND(B2>=DATE(2020,3,20),B2<=DATE(2020,6,26)),1,0)+194.56435*AF2-19.897843*AS2) | AX2: =IF(N2="","",-654.03928+2464.5589*I2+0.035956453*N2-8.0754527*V2-0.00069441316*E2+0.69511606*AD2-1.1669613*AE2-90.724569*AC2-211.24919*IF(AND(B2>=DATE(2020,3,20),B2<=DATE(2020,6,26)),1,0)+147.22132*AF2-0.010108087*AQ2) | AY2: MAPE = 8.3505 | AZ2: MAPE = 9.6655 | BA2: MAPE =4.6201
A3: 2 | B3: 33284 | C3: 6433 | E3: 480000 | G3: 22.116 | H3: 20.436 | I3: 1.106 | L3: 1136 | V3: 84.2 | AC3: 0 | AD3: 145.9 | AE3: 0.7 | AF3: 10.5413 | AG3: =6753.47943187+0.36116788*I3+0.01252571*N3-22.85359542*V3+0.00407811*AA3-0.00067349*E3 -> 4506.3309 | AH3: =A3*'Simple Linear Regression'!$B$18+'Simple Linear Regression'!$B$17 -> 7887.0424 | AI3: =7491.3971+0.0137554*N3-0.00058829*E3-34.3283*V3+0.30565*L3+54.6031*M3 -> 4665.7934 | AJ3: =7491.3971-0.00058829*E3+0.30565*L3+54.6031*M3+0.0137554*N3-34.3283*V3 -> 4665.7934 | AL3: =2192.59+2373.87*I3+0.0316653*N3-15.7623*V3+0.00202406*AA3-0.000740146*E3-0.00963493*(I3*N3) -> 3135.6345 | AM3: =5205.907083+122.0638992*I3+13.609808*(N3/1000)-1.245906883*AD3+0.7746840854*AE3-134.2474226*AC3-1547.125689*IF(AND(B3>=DATE(2020,3,20),B3<=DATE(2020,6,26)),1,0) -> 5159.6742 | AN3: =7707.2178-144.397321*AC3+139.5614087*AF3-0.0008594506251*E3-265.7105668*I3-0.02506176117*J3+0.004708026652*N3 -> 8471.9643 | AO3: =IF(N3="","",2190.39 + 2739.06*I3 + 0.034693*N3 - 16.722*V3 - 0.000802*E3 - 1.3691*AD3 + 1.8691*AE3 - 121.7*AC3 + 209.88*IF(AND(B3>=DATE(2020,3,20),B3<=DATE(2020,6,26)),1,0) - 0.011049*(I3*N3)) | AP3: =IF(B3<DATE(2008,1,1),"",3929.06 + 1212.53*I3 - 0.0003097*N3 + 59.426*V3 - 0.0006734*E3 - 1.036*AD3 + 1.2076*AE3 + 94.923*AF3 - 131.43*AC3 - 759.61*IF(AND(B3>=DATE(2020,3,20),B3<=DATE(2020,6,26)),1,0) - 17.324*(I3*V3)) | AQ3: =IF(N3="","",I3*N3) | AR3: =I3*E3 -> 530880 | AS3: =AC3*AF3 -> 0 | AT3: =IF(N3="","",2413.3773+89.103503*I3+0.018847679*N3-5.0917058*V3-0.00064564578*E3+1.4315076*AD3-3.1976817*AE3-66.972905*AC3-217.08397*IF(AND(B3>=DATE(2020,3,20),B3<=DATE(2020,6,26)),1,0)+190.76803*AF3) | AU3: =IF(N3="","",-480.76297+2186.3009*I3+0.033368804*N3-5.3903106*V3-0.00073731439*E3+0.93396876*AD3-1.6242981*AE3-61.304389*AC3-95.472727*IF(AND(B3>=DATE(2020,3,20),B3<=DATE(2020,6,26)),1,0)+156.04851*AF3-0.0087322858*AQ3) | AV3: =IF(N3="","",2518.0489-204.66184*I3+0.019354281*N3-2.3328708*V3-0.0022533804*E3+1.5259709*AD3-3.5842757*AE3-65.580099*AC3-62.828483*IF(AND(B3>=DATE(2020,3,20),B3<=DATE(2020,6,26)),1,0)+200.94286*AF3+0.00080379976*AR3) | AW3: =IF(N3="","",2361.7153+89.223162*I3+0.018847054*N3-5.0210815*V3-0.0006437347*E3+1.4213619*AD3-3.2156123*AE3+167.41121*AC3-224.35191*IF(AND(B3>=DATE(2020,3,20),B3<=DATE(2020,6,26)),1,0)+194.56435*AF3-19.897843*AS3) | AX3: =IF(N3="","",-654.03928+2464.5589*I3+0.035956453*N3-8.0754527*V3-0.00069441316*E3+0.69511606*AD3-1.1669613*AE3-90.724569*AC3-211.24919*IF(AND(B3>=DATE(2020,3,20),B3<=DATE(2020,6,26)),1,0)+147.22132*AF3-0.010108087*AQ3) | AY3: RMSLE = 0.0871 | AZ3: RMSLE = 0.0977 | BA3: RMSLE = 0.0536
A4: 3 | B4: 33291 | C4: 6582 | E4: 474000 | G4: 19.38 | H4: 18.126 | I4: 1.078 | L4: 1136 | M4: 11.829 | V4: 84.2 | AC4: 0 | AD4: 130.1 | AE4: 1.5 | AF4: 10.7989 | AG4: =6753.47943187+0.36116788*I4+0.01252571*N4-22.85359542*V4+0.00407811*AA4-0.00067349*E4 -> 4510.3618 | AH4: =A4*'Simple Linear Regression'!$B$18+'Simple Linear Regression'!$B$17 -> 7887.8955 | AI4: =7491.3971+0.0137554*N4-0.00058829*E4-34.3283*V4+0.30565*L4+54.6031*M4 -> 5315.2232 | AJ4: =7491.3971-0.00058829*E4+0.30565*L4+54.6031*M4+0.0137554*N4-34.3283*V4 -> 5315.2232 | AL4: =2192.59+2373.87*I4+0.0316653*N4-15.7623*V4+0.00202406*AA4-0.000740146*E4-0.00963493*(I4*N4) -> 3073.607 | AM4: =5205.907083+122.0638992*I4+13.609808*(N4/1000)-1.245906883*AD4+0.7746840854*AE4-134.2474226*AC4-1547.125689*IF(AND(B4>=DATE(2020,3,20),B4<=DATE(2020,6,26)),1,0) -> 5176.5615 | AN4: =7707.2178-144.397321*AC4+139.5614087*AF4-0.0008594506251*E4-265.7105668*I4-0.02506176117*J4+0.004708026652*N4 -> 8520.5119 | AO4: =IF(N4="","",2190.39 + 2739.06*I4 + 0.034693*N4 - 16.722*V4 - 0.000802*E4 - 1.3691*AD4 + 1.8691*AE4 - 121.7*AC4 + 209.88*IF(AND(B4>=DATE(2020,3,20),B4<=DATE(2020,6,26)),1,0) - 0.011049*(I4*N4)) | AP4: =IF(B4<DATE(2008,1,1),"",3929.06 + 1212.53*I4 - 0.0003097*N4 + 59.426*V4 - 0.0006734*E4 - 1.036*AD4 + 1.2076*AE4 + 94.923*AF4 - 131.43*AC4 - 759.61*IF(AND(B4>=DATE(2020,3,20),B4<=DATE(2020,6,26)),1,0) - 17.324*(I4*V4)) | AQ4: =IF(N4="","",I4*N4) | AR4: =I4*E4 -> 510972 | AS4: =AC4*AF4 -> 0 | AT4: =IF(N4="","",2413.3773+89.103503*I4+0.018847679*N4-5.0917058*V4-0.00064564578*E4+1.4315076*AD4-3.1976817*AE4-66.972905*AC4-217.08397*IF(AND(B4>=DATE(2020,3,20),B4<=DATE(2020,6,26)),1,0)+190.76803*AF4) | AU4: =IF(N4="","",-480.76297+2186.3009*I4+0.033368804*N4-5.3903106*V4-0.00073731439*E4+0.93396876*AD4-1.6242981*AE4-61.304389*AC4-95.472727*IF(AND(B4>=DATE(2020,3,20),B4<=DATE(2020,6,26)),1,0)+156.04851*AF4-0.0087322858*AQ4) | AV4: =IF(N4="","",2518.0489-204.66184*I4+0.019354281*N4-2.3328708*V4-0.0022533804*E4+1.5259709*AD4-3.5842757*AE4-65.580099*AC4-62.828483*IF(AND(B4>=DATE(2020,3,20),B4<=DATE(2020,6,26)),1,0)+200.94286*AF4+0.00080379976*AR4) | AW4: =IF(N4="","",2361.7153+89.223162*I4+0.018847054*N4-5.0210815*V4-0.0006437347*E4+1.4213619*AD4-3.2156123*AE4+167.41121*AC4-224.35191*IF(AND(B4>=DATE(2020,3,20),B4<=DATE(2020,6,26)),1,0)+194.56435*AF4-19.897843*AS4) | AX4: =IF(N4="","",-654.03928+2464.5589*I4+0.035956453*N4-8.0754527*V4-0.00069441316*E4+0.69511606*AD4-1.1669613*AE4-90.724569*AC4-211.24919*IF(AND(B4>=DATE(2020,3,20),B4<=DATE(2020,6,26)),1,0)+147.22132*AF4-0.010108087*AQ4) | AY4: RSE = 789.5686 | AZ4: RSE = 910.3424 | BA4: RSE = 910.3424
A5: 4 | B5: 33298 | C5: 7224 | E5: 499000 | G5: 18.73 | H5: 18.662 | I5: 1.054 | L5: 1136 | M5: 11.829 | V5: 84.2 | AC5: 0 | AD5: 149.8 | AE5: 0.9 | AF5: 11.0684 | AG5: =6753.47943187+0.36116788*I5+0.01252571*N5-22.85359542*V5+0.00407811*AA5-0.00067349*E5 -> 4493.5159 | AH5: =A5*'Simple Linear Regression'!$B$18+'Simple Linear Regression'!$B$17 -> 7888.7485 | AI5: =7491.3971+0.0137554*N5-0.00058829*E5-34.3283*V5+0.30565*L5+54.6031*M5 -> 5300.516 | AJ5: =7491.3971-0.00058829*E5+0.30565*L5+54.6031*M5+0.0137554*N5-34.3283*V5 -> 5300.516 | AL5: =2192.59+2373.87*I5+0.0316653*N5-15.7623*V5+0.00202406*AA5-0.000740146*E5-0.00963493*(I5*N5) -> 2998.1305 | AM5: =5205.907083+122.0638992*I5+13.609808*(N5/1000)-1.245906883*AD5+0.7746840854*AE5-134.2474226*AC5-1547.125689*IF(AND(B5>=DATE(2020,3,20),B5<=DATE(2020,6,26)),1,0) -> 5148.6228 | AN5: =7707.2178-144.397321*AC5+139.5614087*AF5-0.0008594506251*E5-265.7105668*I5-0.02506176117*J5+0.004708026652*N5 -> 8543.0145 | AO5: =IF(N5="","",2190.39 + 2739.06*I5 + 0.034693*N5 - 16.722*V5 - 0.000802*E5 - 1.3691*AD5 + 1.8691*AE5 - 121.7*AC5 + 209.88*IF(AND(B5>=DATE(2020,3,20),B5<=DATE(2020,6,26)),1,0) - 0.011049*(I5*N5)) | AP5: =IF(B5<DATE(2008,1,1),"",3929.06 + 1212.53*I5 - 0.0003097*N5 + 59.426*V5 - 0.0006734*E5 - 1.036*AD5 + 1.2076*AE5 + 94.923*AF5 - 131.43*AC5 - 759.61*IF(AND(B5>=DATE(2020,3,20),B5<=DATE(2020,6,26)),1,0) - 17.324*(I5*V5)) | AQ5: =IF(N5="","",I5*N5) | AR5: =I5*E5 -> 525946 | AS5: =AC5*AF5 -> 0 | AT5: =IF(N5="","",2413.3773+89.103503*I5+0.018847679*N5-5.0917058*V5-0.00064564578*E5+1.4315076*AD5-3.1976817*AE5-66.972905*AC5-217.08397*IF(AND(B5>=DATE(2020,3,20),B5<=DATE(2020,6,26)),1,0)+190.76803*AF5) | AU5: =IF(N5="","",-480.76297+2186.3009*I5+0.033368804*N5-5.3903106*V5-0.00073731439*E5+0.93396876*AD5-1.6242981*AE5-61.304389*AC5-95.472727*IF(AND(B5>=DATE(2020,3,20),B5<=DATE(2020,6,26)),1,0)+156.04851*AF5-0.0087322858*AQ5) | AV5: =IF(N5="","",2518.0489-204.66184*I5+0.019354281*N5-2.3328708*V5-0.0022533804*E5+1.5259709*AD5-3.5842757*AE5-65.580099*AC5-62.828483*IF(AND(B5>=DATE(2020,3,20),B5<=DATE(2020,6,26)),1,0)+200.94286*AF5+0.00080379976*AR5) | AW5: =IF(N5="","",2361.7153+89.223162*I5+0.018847054*N5-5.0210815*V5-0.0006437347*E5+1.4213619*AD5-3.2156123*AE5+167.41121*AC5-224.35191*IF(AND(B5>=DATE(2020,3,20),B5<=DATE(2020,6,26)),1,0)+194.56435*AF5-19.897843*AS5) | AX5: =IF(N5="","",-654.03928+2464.5589*I5+0.035956453*N5-8.0754527*V5-0.00069441316*E5+0.69511606*AD5-1.1669613*AE5-90.724569*AC5-211.24919*IF(AND(B5>=DATE(2020,3,20),B5<=DATE(2020,6,26)),1,0)+147.22132*AF5-0.010108087*AQ5)
A6: 5 | B6: 33305 | C6: 6875 | E6: 488000 | G6: 19.856 | H6: 19.77 | I6: 1.025 | L6: 1068 | M6: 11.829 | O6: 3841 | V6: 82.8 | AC6: 0 | AD6: 111.1 | AE6: 1.8 | AF6: 11.3467 | AG6: =6753.47943187+0.36116788*I6+0.01252571*N6-22.85359542*V6+0.00407811*AA6-0.00067349*E6 -> 4532.9088 | AH6: =A6*'Simple Linear Regression'!$B$18+'Simple Linear Regression'!$B$17 -> 7889.6015 | AI6: =7491.3971+0.0137554*N6-0.00058829*E6-34.3283*V6+0.30565*L6+54.6031*M6 -> 5334.2626 | AJ6: =7491.3971-0.00058829*E6+0.30565*L6+54.6031*M6+0.0137554*N6-34.3283*V6 -> 5334.2626 | AL6: =2192.59+2373.87*I6+0.0316653*N6-15.7623*V6+0.00202406*AA6-0.000740146*E6-0.00963493*(I6*N6) -> 2959.4971 | AM6: =5205.907083+122.0638992*I6+13.609808*(N6/1000)-1.245906883*AD6+0.7746840854*AE6-134.2474226*AC6-1547.125689*IF(AND(B6>=DATE(2020,3,20),B6<=DATE(2020,6,26)),1,0) -> 5193.9968 | AN6: =7707.2178-144.397321*AC6+139.5614087*AF6-0.0008594506251*E6-265.7105668*I6-0.02506176117*J6+0.004708026652*N6 -> 8599.014 | AO6: =IF(N6="","",2190.39 + 2739.06*I6 + 0.034693*N6 - 16.722*V6 - 0.000802*E6 - 1.3691*AD6 + 1.8691*AE6 - 121.7*AC6 + 209.88*IF(AND(B6>=DATE(2020,3,20),B6<=DATE(2020,6,26)),1,0) - 0.011049*(I6*N6)) | AP6: =IF(B6<DATE(2008,1,1),"",3929.06 + 1212.53*I6 - 0.0003097*N6 + 59.426*V6 - 0.0006734*E6 - 1.036*AD6 + 1.2076*AE6 + 94.923*AF6 - 131.43*AC6 - 759.61*IF(AND(B6>=DATE(2020,3,20),B6<=DATE(2020,6,26)),1,0) - 17.324*(I6*V6)) | AQ6: =IF(N6="","",I6*N6) | AR6: =I6*E6 -> 500200 | AS6: =AC6*AF6 -> 0 | AT6: =IF(N6="","",2413.3773+89.103503*I6+0.018847679*N6-5.0917058*V6-0.00064564578*E6+1.4315076*AD6-3.1976817*AE6-66.972905*AC6-217.08397*IF(AND(B6>=DATE(2020,3,20),B6<=DATE(2020,6,26)),1,0)+190.76803*AF6) | AU6: =IF(N6="","",-480.76297+2186.3009*I6+0.033368804*N6-5.3903106*V6-0.00073731439*E6+0.93396876*AD6-1.6242981*AE6-61.304389*AC6-95.472727*IF(AND(B6>=DATE(2020,3,20),B6<=DATE(2020,6,26)),1,0)+156.04851*AF6-0.0087322858*AQ6) | AV6: =IF(N6="","",2518.0489-204.66184*I6+0.019354281*N6-2.3328708*V6-0.0022533804*E6+1.5259709*AD6-3.5842757*AE6-65.580099*AC6-62.828483*IF(AND(B6>=DATE(2020,3,20),B6<=DATE(2020,6,26)),1,0)+200.94286*AF6+0.00080379976*AR6) | AW6: =IF(N6="","",2361.7153+89.223162*I6+0.018847054*N6-5.0210815*V6-0.0006437347*E6+1.4213619*AD6-3.2156123*AE6+167.41121*AC6-224.35191*IF(AND(B6>=DATE(2020,3,20),B6<=DATE(2020,6,26)),1,0)+194.56435*AF6-19.897843*AS6) | AX6: =IF(N6="","",-654.03928+2464.5589*I6+0.035956453*N6-8.0754527*V6-0.00069441316*E6+0.69511606*AD6-1.1669613*AE6-90.724569*AC6-211.24919*IF(AND(B6>=DATE(2020,3,20),B6<=DATE(2020,6,26)),1,0)+147.22132*AF6-0.010108087*AQ6)
A7: 6 | B7: 33312 | C7: 6947 | E7: 499000 | G7: 19.894 | H7: 19.278 | I7: 1.045 | L7: 1068 | M7: 11.829 | O7: 3841 | V7: 82.8 | AC7: 0 | AD7: 148 | AE7: 0.7 | AF7: 11.6306 | AG7: =6753.47943187+0.36116788*I7+0.01252571*N7-22.85359542*V7+0.00407811*AA7-0.00067349*E7 -> 4525.5076 | AH7: =A7*'Simple Linear Regression'!$B$18+'Simple Linear Regression'!$B$17 -> 7890.4546 | AI7: =7491.3971+0.0137554*N7-0.00058829*E7-34.3283*V7+0.30565*L7+54.6031*M7 -> 5327.7914 | AJ7: =7491.3971-0.00058829*E7+0.30565*L7+54.6031*M7+0.0137554*N7-34.3283*V7 -> 5327.7914 | AL7: =2192.59+2373.87*I7+0.0316653*N7-15.7623*V7+0.00202406*AA7-0.000740146*E7-0.00963493*(I7*N7) -> 2998.8329 | AM7: =5205.907083+122.0638992*I7+13.609808*(N7/1000)-1.245906883*AD7+0.7746840854*AE7-134.2474226*AC7-1547.125689*IF(AND(B7>=DATE(2020,3,20),B7<=DATE(2020,6,26)),1,0) -> 5149.6119 | AN7: =7707.2178-144.397321*AC7+139.5614087*AF7-0.0008594506251*E7-265.7105668*I7-0.02506176117*J7+0.004708026652*N7 -> 8623.8673 | AO7: =IF(N7="","",2190.39 + 2739.06*I7 + 0.034693*N7 - 16.722*V7 - 0.000802*E7 - 1.3691*AD7 + 1.8691*AE7 - 121.7*AC7 + 209.88*IF(AND(B7>=DATE(2020,3,20),B7<=DATE(2020,6,26)),1,0) - 0.011049*(I7*N7)) | AP7: =IF(B7<DATE(2008,1,1),"",3929.06 + 1212.53*I7 - 0.0003097*N7 + 59.426*V7 - 0.0006734*E7 - 1.036*AD7 + 1.2076*AE7 + 94.923*AF7 - 131.43*AC7 - 759.61*IF(AND(B7>=DATE(2020,3,20),B7<=DATE(2020,6,26)),1,0) - 17.324*(I7*V7)) | AQ7: =IF(N7="","",I7*N7) | AR7: =I7*E7 -> 521455 | AS7: =AC7*AF7 -> 0 | AT7: =IF(N7="","",2413.3773+89.103503*I7+0.018847679*N7-5.0917058*V7-0.00064564578*E7+1.4315076*AD7-3.1976817*AE7-66.972905*AC7-217.08397*IF(AND(B7>=DATE(2020,3,20),B7<=DATE(2020,6,26)),1,0)+190.76803*AF7) | AU7: =IF(N7="","",-480.76297+2186.3009*I7+0.033368804*N7-5.3903106*V7-0.00073731439*E7+0.93396876*AD7-1.6242981*AE7-61.304389*AC7-95.472727*IF(AND(B7>=DATE(2020,3,20),B7<=DATE(2020,6,26)),1,0)+156.04851*AF7-0.0087322858*AQ7) | AV7: =IF(N7="","",2518.0489-204.66184*I7+0.019354281*N7-2.3328708*V7-0.0022533804*E7+1.5259709*AD7-3.5842757*AE7-65.580099*AC7-62.828483*IF(AND(B7>=DATE(2020,3,20),B7<=DATE(2020,6,26)),1,0)+200.94286*AF7+0.00080379976*AR7) | AW7: =IF(N7="","",2361.7153+89.223162*I7+0.018847054*N7-5.0210815*V7-0.0006437347*E7+1.4213619*AD7-3.2156123*AE7+167.41121*AC7-224.35191*IF(AND(B7>=DATE(2020,3,20),B7<=DATE(2020,6,26)),1,0)+194.56435*AF7-19.897843*AS7) | AX7: =IF(N7="","",-654.03928+2464.5589*I7+0.035956453*N7-8.0754527*V7-0.00069441316*E7+0.69511606*AD7-1.1669613*AE7-90.724569*AC7-211.24919*IF(AND(B7>=DATE(2020,3,20),B7<=DATE(2020,6,26)),1,0)+147.22132*AF7-0.010108087*AQ7)
A8: 7 | B8: 33319 | C8: 7328 | E8: 498000 | G8: 20.304 | H8: 18.796 | I8: 1.043 | L8: 1068 | M8: 12.409 | N8: 157889 | O8: 3841 | V8: 82.8 | AC8: 0 | AD8: 104.9 | AE8: 3.3 | AF8: 11.9177 | AG8: =6753.47943187+0.36116788*I8+0.01252571*N8-22.85359542*V8+0.00407811*AA8-0.00067349*E8 -> 6503.8522 | AH8: =A8*'Simple Linear Regression'!$B$18+'Simple Linear Regression'!$B$17 -> 7891.3076 | AI8: =7491.3971+0.0137554*N8-0.00058829*E8-34.3283*V8+0.30565*L8+54.6031*M8 -> 7531.8759 | AJ8: =7491.3971-0.00058829*E8+0.30565*L8+54.6031*M8+0.0137554*N8-34.3283*V8 -> 7531.8759 | AL8: =2192.59+2373.87*I8+0.0316653*N8-15.7623*V8+0.00202406*AA8-0.000740146*E8-0.00963493*(I8*N8) -> 6407.7646 | AM8: =5205.907083+122.0638992*I8+13.609808*(N8/1000)-1.245906883*AD8+0.7746840854*AE8-134.2474226*AC8-1547.125689*IF(AND(B8>=DATE(2020,3,20),B8<=DATE(2020,6,26)),1,0) -> 7353.9195 | AN8: =7707.2178-144.397321*AC8+139.5614087*AF8-0.0008594506251*E8-265.7105668*I8-0.02506176117*J8+0.004708026652*N8 -> 9408.6719 | AO8: =IF(N8="","",2190.39 + 2739.06*I8 + 0.034693*N8 - 16.722*V8 - 0.000802*E8 - 1.3691*AD8 + 1.8691*AE8 - 121.7*AC8 + 209.88*IF(AND(B8>=DATE(2020,3,20),B8<=DATE(2020,6,26)),1,0) - 0.011049*(I8*N8)) -> 6783.9148 | AP8: =IF(B8<DATE(2008,1,1),"",3929.06 + 1212.53*I8 - 0.0003097*N8 + 59.426*V8 - 0.0006734*E8 - 1.036*AD8 + 1.2076*AE8 + 94.923*AF8 - 131.43*AC8 - 759.61*IF(AND(B8>=DATE(2020,3,20),B8<=DATE(2020,6,26)),1,0) - 17.324*(I8*V8)) | AQ8: =IF(N8="","",I8*Target!N8) -> 164678.23 | AR8: =I8*E8 -> 519414 | AS8: =AC8*AF8 -> 0 | AT8: =IF(N8="","",2413.3773+89.103503*I8+0.018847679*N8-5.0917058*V8-0.00064564578*E8+1.4315076*AD8-3.1976817*AE8-66.972905*AC8-217.08397*IF(AND(B8>=DATE(2020,3,20),B8<=DATE(2020,6,26)),1,0)+190.76803*AF8) -> 7152.1576 | AU8: =IF(N8="","",-480.76297+2186.3009*I8+0.033368804*N8-5.3903106*V8-0.00073731439*E8+0.93396876*AD8-1.6242981*AE8-61.304389*AC8-95.472727*IF(AND(B8>=DATE(2020,3,20),B8<=DATE(2020,6,26)),1,0)+156.04851*AF8-0.0087322858*AQ8) -> 6768.9508 | AV8: =IF(N8="","",2518.0489-204.66184*I8+0.019354281*N8-2.3328708*V8-0.0022533804*E8+1.5259709*AD8-3.5842757*AE8-65.580099*AC8-62.828483*IF(AND(B8>=DATE(2020,3,20),B8<=DATE(2020,6,26)),1,0)+200.94286*AF8+0.00080379976*AR8) -> 7005.5973 | AW8: =IF(N8="","",2361.7153+89.223162*I8+0.018847054*N8-5.0210815*V8-0.0006437347*E8+1.4213619*AD8-3.2156123*AE8+167.41121*AC8-224.35191*IF(AND(B8>=DATE(2020,3,20),B8<=DATE(2020,6,26)),1,0)+194.56435*AF8-19.897843*AS8) -> 7151.441 | AX8: =IF(N8="","",-654.03928+2464.5589*I8+0.035956453*N8-8.0754527*V8-0.00069441316*E8+0.69511606*AD8-1.1669613*AE8-90.724569*AC8-211.24919*IF(AND(B8>=DATE(2020,3,20),B8<=DATE(2020,6,26)),1,0)+147.22132*AF8-0.010108087*AQ8) -> 6738.1832
A9: 8 | B9: 33326 | C9: 6777 | E9: 509000 | G9: 19.5825 | H9: 18.275 | I9: 1.047 | L9: 1068 | M9: 12.409 | N9: 157889 | O9: 3841 | V9: 82.8 | AC9: 0 | AD9: 79 | AE9: 7.1 | AF9: 12.2055 | AG9: =6753.47943187+0.36116788*I9+0.01252571*N9-22.85359542*V9+0.00407811*AA9-0.00067349*E9 -> 6496.4453 | AH9: =A9*'Simple Linear Regression'!$B$18+'Simple Linear Regression'!$B$17 -> 7892.1606 | AI9: =7491.3971+0.0137554*N9-0.00058829*E9-34.3283*V9+0.30565*L9+54.6031*M9 -> 7525.4047 | AJ9: =7491.3971-0.00058829*E9+0.30565*L9+54.6031*M9+0.0137554*N9-34.3283*V9 -> 7525.4047 | AL9: =2192.59+2373.87*I9+0.0316653*N9-15.7623*V9+0.00202406*AA9-0.000740146*E9-0.00963493*(I9*N9) -> 6403.0335 | AM9: =5205.907083+122.0638992*I9+13.609808*(N9/1000)-1.245906883*AD9+0.7746840854*AE9-134.2474226*AC9-1547.125689*IF(AND(B9>=DATE(2020,3,20),B9<=DATE(2020,6,26)),1,0) -> 7389.6206 | AN9: =7707.2178-144.397321*AC9+139.5614087*AF9-0.0008594506251*E9-265.7105668*I9-0.02506176117*J9+0.004708026652*N9 -> 9438.3209 | AO9: =IF(N9="","",2190.39 + 2739.06*I9 + 0.034693*N9 - 16.722*V9 - 0.000802*E9 - 1.3691*AD9 + 1.8691*AE9 - 121.7*AC9 + 209.88*IF(AND(B9>=DATE(2020,3,20),B9<=DATE(2020,6,26)),1,0) - 0.011049*(I9*N9)) -> 6821.6332 | AP9: =IF(B9<DATE(2008,1,1),"",3929.06 + 1212.53*I9 - 0.0003097*N9 + 59.426*V9 - 0.0006734*E9 - 1.036*AD9 + 1.2076*AE9 + 94.923*AF9 - 131.43*AC9 - 759.61*IF(AND(B9>=DATE(2020,3,20),B9<=DATE(2020,6,26)),1,0) - 17.324*(I9*V9)) | AQ9: =IF(N9="","",I9*N9) -> 165309.78 | AR9: =I9*E9 -> 532923 | AS9: =AC9*AF9 -> 0 | AT9: =IF(N9="","",2413.3773+89.103503*I9+0.018847679*N9-5.0917058*V9-0.00064564578*E9+1.4315076*AD9-3.1976817*AE9-66.972905*AC9-217.08397*IF(AND(B9>=DATE(2020,3,20),B9<=DATE(2020,6,26)),1,0)+190.76803*AF9) -> 7151.0877 | AU9: =IF(N9="","",-480.76297+2186.3009*I9+0.033368804*N9-5.3903106*V9-0.00073731439*E9+0.93396876*AD9-1.6242981*AE9-61.304389*AC9-95.472727*IF(AND(B9>=DATE(2020,3,20),B9<=DATE(2020,6,26)),1,0)+156.04851*AF9-0.0087322858*AQ9) -> 6778.6193 | AV9: =IF(N9="","",2518.0489-204.66184*I9+0.019354281*N9-2.3328708*V9-0.0022533804*E9+1.5259709*AD9-3.5842757*AE9-65.580099*AC9-62.828483*IF(AND(B9>=DATE(2020,3,20),B9<=DATE(2020,6,26)),1,0)+200.94286*AF9+0.00080379976*AR9) -> 6995.5385 | AW9: =IF(N9="","",2361.7153+89.223162*I9+0.018847054*N9-5.0210815*V9-0.0006437347*E9+1.4213619*AD9-3.2156123*AE9+167.41121*AC9-224.35191*IF(AND(B9>=DATE(2020,3,20),B9<=DATE(2020,6,26)),1,0)+194.56435*AF9-19.897843*AS9) -> 7151.6799 | AX9: =IF(N9="","",-654.03928+2464.5589*I9+0.035956453*N9-8.0754527*V9-0.00069441316*E9+0.69511606*AD9-1.1669613*AE9-90.724569*AC9-211.24919*IF(AND(B9>=DATE(2020,3,20),B9<=DATE(2020,6,26)),1,0)+147.22132*AF9-0.010108087*AQ9) -> 6753.9514
A10: 9 | B10: 33333 | C10: 7503 | E10: 499000 | G10: 19.63 | H10: 17.946 | I10: 1.052 | L10: 984 | M10: 12.409 | N10: 157889 | O10: 3866.7 | V10: 82.8 | AC10: 0 | AD10: 92.3 | AE10: 2.8 | AF10: 12.4916 | AG10: =6753.47943187+0.36116788*I10+0.01252571*N10-22.85359542*V10+0.00407811*AA10-0.00067349*E10 -> 6503.182 | AH10: =A10*'Simple Linear Regression'!$B$18+'Simple Linear Regression'!$B$17 -> 7893.0137 | AI10: =7491.3971+0.0137554*N10-0.00058829*E10-34.3283*V10+0.30565*L10+54.6031*M10 -> 7505.613 | AJ10: =7491.3971-0.00058829*E10+0.30565*L10+54.6031*M10+0.0137554*N10-34.3283*V10 -> 7505.613 | AL10: =2192.59+2373.87*I10+0.0316653*N10-15.7623*V10+0.00202406*AA10-0.000740146*E10-0.00963493*(I10*N10) -> 6414.6981 | AM10: =5205.907083+122.0638992*I10+13.609808*(N10/1000)-1.245906883*AD10+0.7746840854*AE10-134.2474226*AC10-1547.125689*IF(AND(B10>=DATE(2020,3,20),B10<=DATE(2020,6,26)),1,0) -> 7370.3292 | AN10: =7707.2178-144.397321*AC10+139.5614087*AF10-0.0008594506251*E10-265.7105668*I10-0.02506176117*J10+0.004708026652*N10 -> 9485.5153 | AO10: =IF(N10="","",2190.39 + 2739.06*I10 + 0.034693*N10 - 16.722*V10 - 0.000802*E10 - 1.3691*AD10 + 1.8691*AE10 - 121.7*AC10 + 209.88*IF(AND(B10>=DATE(2020,3,20),B10<=DATE(2020,6,26)),1,0) - 0.011049*(I10*N10)) -> 6808.3798 | AP10: =IF(B10<DATE(2008,1,1),"",3929.06 + 1212.53*I10 - 0.0003097*N10 + 59.426*V10 - 0.0006734*E10 - 1.036*AD10 + 1.2076*AE10 + 94.923*AF10 - 131.43*AC10 - 759.61*IF(AND(B10>=DATE(2020,3,20),B10<=DATE(2020,6,26)),1,0) - 17.324*(I10*V10)) | AQ10: =IF(N10="","",I10*N10) -> 166099.23 | AR10: =I10*E10 -> 524948 | AS10: =AC10*AF10 -> 0 | AT10: =IF(N10="","",2413.3773+89.103503*I10+0.018847679*N10-5.0917058*V10-0.00064564578*E10+1.4315076*AD10-3.1976817*AE10-66.972905*AC10-217.08397*IF(AND(B10>=DATE(2020,3,20),B10<=DATE(2020,6,26)),1,0)+190.76803*AF10) -> 7245.3575 | AU10: =IF(N10="","",-480.76297+2186.3009*I10+0.033368804*N10-5.3903106*V10-0.00073731439*E10+0.93396876*AD10-1.6242981*AE10-61.304389*AC10-95.472727*IF(AND(B10>=DATE(2020,3,20),B10<=DATE(2020,6,26)),1,0)+156.04851*AF10-0.0087322858*AQ10) -> 6854.082 | AV10: =IF(N10="","",2518.0489-204.66184*I10+0.019354281*N10-2.3328708*V10-0.0022533804*E10+1.5259709*AD10-3.5842757*AE10-65.580099*AC10-62.828483*IF(AND(B10>=DATE(2020,3,20),B10<=DATE(2020,6,26)),1,0)+200.94286*AF10+0.00080379976*AR10) -> 7103.8362 | AW10: =IF(N10="","",2361.7153+89.223162*I10+0.018847054*N10-5.0210815*V10-0.0006437347*E10+1.4213619*AD10-3.2156123*AE10+167.41121*AC10-224.35191*IF(AND(B10>=DATE(2020,3,20),B10<=DATE(2020,6,26)),1,0)+194.56435*AF10-19.897843*AS10) -> 7246.9594 | AX10: =IF(N10="","",-654.03928+2464.5589*I10+0.035956453*N10-8.0754527*V10-0.00069441316*E10+0.69511606*AD10-1.1669613*AE10-90.724569*AC10-211.24919*IF(AND(B10>=DATE(2020,3,20),B10<=DATE(2020,6,26)),1,0)+147.22132*AF10-0.010108087*AQ10) -> 6821.6216
A11: 10 | B11: 33340 | C11: 6916 | E11: 452000 | G11: 20.892 | H11: 19.172 | I11: 1.066 | L11: 984 | M11: 12.409 | N11: 157889 | O11: 3866.7 | V11: 82.5 | AC11: 0 | AD11: 37.2 | AE11: 14.2 | AF11: 12.7734 | AG11: =6753.47943187+0.36116788*I11+0.01252571*N11-22.85359542*V11+0.00407811*AA11-0.00067349*E11 -> 6541.6972 | AH11: =A11*'Simple Linear Regression'!$B$18+'Simple Linear Regression'!$B$17 -> 7893.8667 | AI11: =7491.3971+0.0137554*N11-0.00058829*E11-34.3283*V11+0.30565*L11+54.6031*M11 -> 7543.5611 | AJ11: =7491.3971-0.00058829*E11+0.30565*L11+54.6031*M11+0.0137554*N11-34.3283*V11 -> 7543.5611 | AL11: =2192.59+2373.87*I11+0.0316653*N11-15.7623*V11+0.00202406*AA11-0.000740146*E11-0.00963493*(I11*N11) -> 6466.1503 | AM11: =5205.907083+122.0638992*I11+13.609808*(N11/1000)-1.245906883*AD11+0.7746840854*AE11-134.2474226*AC11-1547.125689*IF(AND(B11>=DATE(2020,3,20),B11<=DATE(2020,6,26)),1,0) -> 7449.519 | AN11: =7707.2178-144.397321*AC11+139.5614087*AF11-0.0008594506251*E11-265.7105668*I11-0.02506176117*J11+0.004708026652*N11 -> 9561.518 | AO11: =IF(N11="","",2190.39 + 2739.06*I11 + 0.034693*N11 - 16.722*V11 - 0.000802*E11 - 1.3691*AD11 + 1.8691*AE11 - 121.7*AC11 + 209.88*IF(AND(B11>=DATE(2020,3,20),B11<=DATE(2020,6,26)),1,0) - 0.011049*(I11*N11)) -> 6961.7591 | AP11: =IF(B11<DATE(2008,1,1),"",3929.06 + 1212.53*I11 - 0.0003097*N11 + 59.426*V11 - 0.0006734*E11 - 1.036*AD11 + 1.2076*AE11 + 94.923*AF11 - 131.43*AC11 - 759.61*IF(AND(B11>=DATE(2020,3,20),B11<=DATE(2020,6,26)),1,0) - 17.324*(I11*V11)) | AQ11: =IF(N11="","",I11*N11) -> 168309.67 | AR11: =I11*E11 -> 481832 | AS11: =AC11*AF11 -> 0 | AT11: =IF(N11="","",2413.3773+89.103503*I11+0.018847679*N11-5.0917058*V11-0.00064564578*E11+1.4315076*AD11-3.1976817*AE11-66.972905*AC11-217.08397*IF(AND(B11>=DATE(2020,3,20),B11<=DATE(2020,6,26)),1,0)+190.76803*AF11) -> 7216.9066 | AU11: =IF(N11="","",-480.76297+2186.3009*I11+0.033368804*N11-5.3903106*V11-0.00073731439*E11+0.93396876*AD11-1.6242981*AE11-61.304389*AC11-95.472727*IF(AND(B11>=DATE(2020,3,20),B11<=DATE(2020,6,26)),1,0)+156.04851*AF11-0.0087322858*AQ11) -> 6875.6546 | AV11: =IF(N11="","",2518.0489-204.66184*I11+0.019354281*N11-2.3328708*V11-0.0022533804*E11+1.5259709*AD11-3.5842757*AE11-65.580099*AC11-62.828483*IF(AND(B11>=DATE(2020,3,20),B11<=DATE(2020,6,26)),1,0)+200.94286*AF11+0.00080379976*AR11) -> 7104.607 | AW11: =IF(N11="","",2361.7153+89.223162*I11+0.018847054*N11-5.0210815*V11-0.0006437347*E11+1.4213619*AD11-3.2156123*AE11+167.41121*AC11-224.35191*IF(AND(B11>=DATE(2020,3,20),B11<=DATE(2020,6,26)),1,0)+194.56435*AF11-19.897843*AS11) -> 7219.8236 | AX11: =IF(N11="","",-654.03928+2464.5589*I11+0.035956453*N11-8.0754527*V11-0.00069441316*E11+0.69511606*AD11-1.1669613*AE11-90.724569*AC11-211.24919*IF(AND(B11>=DATE(2020,3,20),B11<=DATE(2020,6,26)),1,0)+147.22132*AF11-0.010108087*AQ11) -> 6858.7248
A12: 11 | B12: 33347 | C12: 7045 | E12: 477000 | G12: 21.484 | H12: 19.712 | I12: 1.069 | L12: 984 | M12: 12.848 | N12: 153351 | O12: 3866.7 | V12: 82.5 | AC12: 0 | AD12: 62 | AE12: 14.6 | AF12: 13.0483 | AG12: =6753.47943187+0.36116788*I12+0.01252571*N12-22.85359542*V12+0.00407811*AA12-0.00067349*E12 -> 6468.0193 | AH12: =A12*'Simple Linear Regression'!$B$18+'Simple Linear Regression'!$B$17 -> 7894.7198 | AI12: =7491.3971+0.0137554*N12-0.00058829*E12-34.3283*V12+0.30565*L12+54.6031*M12 -> 7490.4026 | AJ12: =7491.3971-0.00058829*E12+0.30565*L12+54.6031*M12+0.0137554*N12-34.3283*V12 -> 7490.4026 | AL12: =2192.59+2373.87*I12+0.0316653*N12-15.7623*V12+0.00202406*AA12-0.000740146*E12-0.00963493*(I12*N12) -> 6353.2476 | AM12: =5205.907083+122.0638992*I12+13.609808*(N12/1000)-1.245906883*AD12+0.7746840854*AE12-134.2474226*AC12-1547.125689*IF(AND(B12>=DATE(2020,3,20),B12<=DATE(2020,6,26)),1,0) -> 7357.5352 | AN12: =7707.2178-144.397321*AC12+139.5614087*AF12-0.0008594506251*E12-265.7105668*I12-0.02506176117*J12+0.004708026652*N12 -> 9556.235 | AO12: =IF(N12="","",2190.39 + 2739.06*I12 + 0.034693*N12 - 16.722*V12 - 0.000802*E12 - 1.3691*AD12 + 1.8691*AE12 - 121.7*AC12 + 209.88*IF(AND(B12>=DATE(2020,3,20),B12<=DATE(2020,6,26)),1,0) - 0.011049*(I12*N12)) -> 6807.65 | AP12: =IF(B12<DATE(2008,1,1),"",3929.06 + 1212.53*I12 - 0.0003097*N12 + 59.426*V12 - 0.0006734*E12 - 1.036*AD12 + 1.2076*AE12 + 94.923*AF12 - 131.43*AC12 - 759.61*IF(AND(B12>=DATE(2020,3,20),B12<=DATE(2020,6,26)),1,0) - 17.324*(I12*V12)) | AQ12: =IF(N12="","",I12*N12) -> 163932.22 | AR12: =I12*E12 -> 509913 | AS12: =AC12*AF12 -> 0 | AT12: =IF(N12="","",2413.3773+89.103503*I12+0.018847679*N12-5.0917058*V12-0.00064564578*E12+1.4315076*AD12-3.1976817*AE12-66.972905*AC12-217.08397*IF(AND(B12>=DATE(2020,3,20),B12<=DATE(2020,6,26)),1,0)+190.76803*AF12) -> 7202.1664 | AU12: =IF(N12="","",-480.76297+2186.3009*I12+0.033368804*N12-5.3903106*V12-0.00073731439*E12+0.93396876*AD12-1.6242981*AE12-61.304389*AC12-95.472727*IF(AND(B12>=DATE(2020,3,20),B12<=DATE(2020,6,26)),1,0)+156.04851*AF12-0.0087322858*AQ12) -> 6815.9887 | AV12: =IF(N12="","",2518.0489-204.66184*I12+0.019354281*N12-2.3328708*V12-0.0022533804*E12+1.5259709*AD12-3.5842757*AE12-65.580099*AC12-62.828483*IF(AND(B12>=DATE(2020,3,20),B12<=DATE(2020,6,26)),1,0)+200.94286*AF12+0.00080379976*AR12) -> 7074.0499 | AW12: =IF(N12="","",2361.7153+89.223162*I12+0.018847054*N12-5.0210815*V12-0.0006437347*E12+1.4213619*AD12-3.2156123*AE12+167.41121*AC12-224.35191*IF(AND(B12>=DATE(2020,3,20),B12<=DATE(2020,6,26)),1,0)+194.56435*AF12-19.897843*AS12) -> 7205.9193 | AX12: =IF(N12="","",-654.03928+2464.5589*I12+0.035956453*N12-8.0754527*V12-0.00069441316*E12+0.69511606*AD12-1.1669613*AE12-90.724569*AC12-211.24919*IF(AND(B12>=DATE(2020,3,20),B12<=DATE(2020,6,26)),1,0)+147.22132*AF12-0.010108087*AQ12) -> 6787.0787
A13: 12 | B13: 33354 | C13: 6956 | E13: 478000 | G13: 21.188 | H13: 19.632 | I13: 1.09 | L13: 984 | M13: 12.848 | N13: 153351 | O13: 3866.7 | V13: 82.5 | AC13: 0 | AD13: 64.9 | AE13: 9.9 | AF13: 13.3132 | AG13: =6753.47943187+0.36116788*I13+0.01252571*N13-22.85359542*V13+0.00407811*AA13-0.00067349*E13 -> 6467.3534 | AH13: =A13*'Simple Linear Regression'!$B$18+'Simple Linear Regression'!$B$17 -> 7895.5728 | AI13: =7491.3971+0.0137554*N13-0.00058829*E13-34.3283*V13+0.30565*L13+54.6031*M13 -> 7489.8143 | AJ13: =7491.3971-0.00058829*E13+0.30565*L13+54.6031*M13+0.0137554*N13-34.3283*V13 -> 7489.8143 | AL13: =2192.59+2373.87*I13+0.0316653*N13-15.7623*V13+0.00202406*AA13-0.000740146*E13-0.00963493*(I13*N13) -> 6371.3307 | AM13: =5205.907083+122.0638992*I13+13.609808*(N13/1000)-1.245906883*AD13+0.7746840854*AE13-134.2474226*AC13-1547.125689*IF(AND(B13>=DATE(2020,3,20),B13<=DATE(2020,6,26)),1,0) -> 7352.8444 | AN13: =7707.2178-144.397321*AC13+139.5614087*AF13-0.0008594506251*E13-265.7105668*I13-0.02506176117*J13+0.004708026652*N13 -> 9586.7654 | AO13: =IF(N13="","",2190.39 + 2739.06*I13 + 0.034693*N13 - 16.722*V13 - 0.000802*E13 - 1.3691*AD13 + 1.8691*AE13 - 121.7*AC13 + 209.88*IF(AND(B13>=DATE(2020,3,20),B13<=DATE(2020,6,26)),1,0) - 0.011049*(I13*N13)) -> 6816.0312 | AP13: =IF(B13<DATE(2008,1,1),"",3929.06 + 1212.53*I13 - 0.0003097*N13 + 59.426*V13 - 0.0006734*E13 - 1.036*AD13 + 1.2076*AE13 + 94.923*AF13 - 131.43*AC13 - 759.61*IF(AND(B13>=DATE(2020,3,20),B13<=DATE(2020,6,26)),1,0) - 17.324*(I13*V13)) | AQ13: =IF(N13="","",I13*N13) -> 167152.59 | AR13: =I13*E13 -> 521020 | AS13: =AC13*AF13 -> 0 | AT13: =IF(N13="","",2413.3773+89.103503*I13+0.018847679*N13-5.0917058*V13-0.00064564578*E13+1.4315076*AD13-3.1976817*AE13-66.972905*AC13-217.08397*IF(AND(B13>=DATE(2020,3,20),B13<=DATE(2020,6,26)),1,0)+190.76803*AF13) -> 7273.1069 | AU13: =IF(N13="","",-480.76297+2186.3009*I13+0.033368804*N13-5.3903106*V13-0.00073731439*E13+0.93396876*AD13-1.6242981*AE13-61.304389*AC13-95.472727*IF(AND(B13>=DATE(2020,3,20),B13<=DATE(2020,6,26)),1,0)+156.04851*AF13-0.0087322858*AQ13) -> 6884.7224 | AV13: =IF(N13="","",2518.0489-204.66184*I13+0.019354281*N13-2.3328708*V13-0.0022533804*E13+1.5259709*AD13-3.5842757*AE13-65.580099*AC13-62.828483*IF(AND(B13>=DATE(2020,3,20),B13<=DATE(2020,6,26)),1,0)+200.94286*AF13+0.00080379976*AR13) -> 7150.9276 | AW13: =IF(N13="","",2361.7153+89.223162*I13+0.018847054*N13-5.0210815*V13-0.0006437347*E13+1.4213619*AD13-3.2156123*AE13+167.41121*AC13-224.35191*IF(AND(B13>=DATE(2020,3,20),B13<=DATE(2020,6,26)),1,0)+194.56435*AF13-19.897843*AS13) -> 7277.9246 | AX13: =IF(N13="","",-654.03928+2464.5589*I13+0.035956453*N13-8.0754527*V13-0.00069441316*E13+0.69511606*AD13-1.1669613*AE13-90.724569*AC13-211.24919*IF(AND(B13>=DATE(2020,3,20),B13<=DATE(2020,6,26)),1,0)+147.22132*AF13-0.010108087*AQ13) -> 6852.0877
A14: 13 | B14: 33361 | C14: 6976 | E14: 462000 | G14: 21.234 | H14: 19.72 | I14: 1.104 | L14: 984 | M14: 12.848 | N14: 153351 | O14: 3866.7 | V14: 82.5 | AC14: 0 | AD14: 30.2 | AE14: 21.4 | AF14: 13.5644 | AG14: =6753.47943187+0.36116788*I14+0.01252571*N14-22.85359542*V14+0.00407811*AA14-0.00067349*E14 -> 6478.1343 | AH14: =A14*'Simple Linear Regression'!$B$18+'Simple Linear Regression'!$B$17 -> 7896.4258 | AI14: =7491.3971+0.0137554*N14-0.00058829*E14-34.3283*V14+0.30565*L14+54.6031*M14 -> 7499.2269 | AJ14: =7491.3971-0.00058829*E14+0.30565*L14+54.6031*M14+0.0137554*N14-34.3283*V14 -> 7499.2269 | AL14: =2192.59+2373.87*I14+0.0316653*N14-15.7623*V14+0.00202406*AA14-0.000740146*E14-0.00963493*(I14*N14) -> 6395.7218 | AM14: =5205.907083+122.0638992*I14+13.609808*(N14/1000)-1.245906883*AD14+0.7746840854*AE14-134.2474226*AC14-1547.125689*IF(AND(B14>=DATE(2020,3,20),B14<=DATE(2020,6,26)),1,0) -> 7406.6951 | AN14: =7707.2178-144.397321*AC14+139.5614087*AF14-0.0008594506251*E14-265.7105668*I14-0.02506176117*J14+0.004708026652*N14 -> 9631.8545 | AO14: =IF(N14="","",2190.39 + 2739.06*I14 + 0.034693*N14 - 16.722*V14 - 0.000802*E14 - 1.3691*AD14 + 1.8691*AE14 - 121.7*AC14 + 209.88*IF(AND(B14>=DATE(2020,3,20),B14<=DATE(2020,6,26)),1,0) - 0.011049*(I14*N14)) -> 6912.4912 | AP14: =IF(B14<DATE(2008,1,1),"",3929.06 + 1212.53*I14 - 0.0003097*N14 + 59.426*V14 - 0.0006734*E14 - 1.036*AD14 + 1.2076*AE14 + 94.923*AF14 - 131.43*AC14 - 759.61*IF(AND(B14>=DATE(2020,3,20),B14<=DATE(2020,6,26)),1,0) - 17.324*(I14*V14)) | AQ14: =IF(N14="","",I14*N14) -> 169299.5 | AR14: =I14*E14 -> 510048 | AS14: =AC14*AF14 -> 0 | AT14: =IF(N14="","",2413.3773+89.103503*I14+0.018847679*N14-5.0917058*V14-0.00064564578*E14+1.4315076*AD14-3.1976817*AE14-66.972905*AC14-217.08397*IF(AND(B14>=DATE(2020,3,20),B14<=DATE(2020,6,26)),1,0)+190.76803*AF14) -> 7246.1589 | AU14: =IF(N14="","",-480.76297+2186.3009*I14+0.033368804*N14-5.3903106*V14-0.00073731439*E14+0.93396876*AD14-1.6242981*AE14-61.304389*AC14-95.472727*IF(AND(B14>=DATE(2020,3,20),B14<=DATE(2020,6,26)),1,0)+156.04851*AF14-0.0087322858*AQ14) -> 6896.4914 | AV14: =IF(N14="","",2518.0489-204.66184*I14+0.019354281*N14-2.3328708*V14-0.0022533804*E14+1.5259709*AD14-3.5842757*AE14-65.580099*AC14-62.828483*IF(AND(B14>=DATE(2020,3,20),B14<=DATE(2020,6,26)),1,0)+200.94286*AF14+0.00080379976*AR14) -> 7131.6036 | AW14: =IF(N14="","",2361.7153+89.223162*I14+0.018847054*N14-5.0210815*V14-0.0006437347*E14+1.4213619*AD14-3.2156123*AE14+167.41121*AC14-224.35191*IF(AND(B14>=DATE(2020,3,20),B14<=DATE(2020,6,26)),1,0)+194.56435*AF14-19.897843*AS14) -> 7252.0473 | AX14: =IF(N14="","",-654.03928+2464.5589*I14+0.035956453*N14-8.0754527*V14-0.00069441316*E14+0.69511606*AD14-1.1669613*AE14-90.724569*AC14-211.24919*IF(AND(B14>=DATE(2020,3,20),B14<=DATE(2020,6,26)),1,0)+147.22132*AF14-0.010108087*AQ14) -> 6875.4423
A15: 14 | B15: 33368 | C15: 7185 | E15: 451000 | G15: 21.69 | H15: 19.812 | I15: 1.113 | J15: 6035.178 | L15: 929 | M15: 12.848 | N15: 153351 | O15: 3913 | V15: 84.4 | AC15: 0 | AD15: 27.9 | AE15: 19.4 | AF15: 13.7981 | AG15: =6753.47943187+0.36116788*I15+0.01252571*N15-22.85359542*V15+0.00407811*AA15-0.00067349*E15 -> 6442.1241 | AH15: =A15*'Simple Linear Regression'!$B$18+'Simple Linear Regression'!$B$17 -> 7897.2789 | AI15: =7491.3971+0.0137554*N15-0.00058829*E15-34.3283*V15+0.30565*L15+54.6031*M15 -> 7423.6636 | AJ15: =7491.3971-0.00058829*E15+0.30565*L15+54.6031*M15+0.0137554*N15-34.3283*V15 -> 7423.6636 | AL15: =2192.59+2373.87*I15+0.0316653*N15-15.7623*V15+0.00202406*AA15-0.000740146*E15-0.00963493*(I15*N15) -> 6381.9822 | AM15: =5205.907083+122.0638992*I15+13.609808*(N15/1000)-1.245906883*AD15+0.7746840854*AE15-134.2474226*AC15-1547.125689*IF(AND(B15>=DATE(2020,3,20),B15<=DATE(2020,6,26)),1,0) -> 7409.1099 | AN15: =7707.2178-144.397321*AC15+139.5614087*AF15-0.0008594506251*E15-265.7105668*I15-0.02506176117*J15+0.004708026652*N15 -> 9520.2804 | AO15: =IF(N15="","",2190.39 + 2739.06*I15 + 0.034693*N15 - 16.722*V15 - 0.000802*E15 - 1.3691*AD15 + 1.8691*AE15 - 121.7*AC15 + 209.88*IF(AND(B15>=DATE(2020,3,20),B15<=DATE(2020,6,26)),1,0) - 0.011049*(I15*N15)) -> 6898.3543 | AP15: =IF(B15<DATE(2008,1,1),"",3929.06 + 1212.53*I15 - 0.0003097*N15 + 59.426*V15 - 0.0006734*E15 - 1.036*AD15 + 1.2076*AE15 + 94.923*AF15 - 131.43*AC15 - 759.61*IF(AND(B15>=DATE(2020,3,20),B15<=DATE(2020,6,26)),1,0) - 17.324*(I15*V15)) | AQ15: =IF(N15="","",I15*N15) -> 170679.66 | AR15: =I15*E15 -> 501963 | AS15: =AC15*AF15 -> 0 | AT15: =IF(N15="","",2413.3773+89.103503*I15+0.018847679*N15-5.0917058*V15-0.00064564578*E15+1.4315076*AD15-3.1976817*AE15-66.972905*AC15-217.08397*IF(AND(B15>=DATE(2020,3,20),B15<=DATE(2020,6,26)),1,0)+190.76803*AF15) -> 7292.0741 | AU15: =IF(N15="","",-480.76297+2186.3009*I15+0.033368804*N15-5.3903106*V15-0.00073731439*E15+0.93396876*AD15-1.6242981*AE15-61.304389*AC15-95.472727*IF(AND(B15>=DATE(2020,3,20),B15<=DATE(2020,6,26)),1,0)+156.04851*AF15-0.0087322858*AQ15) -> 6939.5541 | AV15: =IF(N15="","",2518.0489-204.66184*I15+0.019354281*N15-2.3328708*V15-0.0022533804*E15+1.5259709*AD15-3.5842757*AE15-65.580099*AC15-62.828483*IF(AND(B15>=DATE(2020,3,20),B15<=DATE(2020,6,26)),1,0)+200.94286*AF15+0.00080379976*AR15) -> 7194.2368 | AW15: =IF(N15="","",2361.7153+89.223162*I15+0.018847054*N15-5.0210815*V15-0.0006437347*E15+1.4213619*AD15-3.2156123*AE15+167.41121*AC15-224.35191*IF(AND(B15>=DATE(2020,3,20),B15<=DATE(2020,6,26)),1,0)+194.56435*AF15-19.897843*AS15) -> 7299.0231 | AX15: =IF(N15="","",-654.03928+2464.5589*I15+0.035956453*N15-8.0754527*V15-0.00069441316*E15+0.69511606*AD15-1.1669613*AE15-90.724569*AC15-211.24919*IF(AND(B15>=DATE(2020,3,20),B15<=DATE(2020,6,26)),1,0)+147.22132*AF15-0.010108087*AQ15) -> 6911.1086
A16: 15 | B16: 33375 | C16: 6899 | E16: 446000 | G16: 20.952 | H16: 18.9 | I16: 1.121 | J16: 6035.178 | L16: 929 | M16: 12.038 | N16: 179076 | O16: 3913 | V16: 84.4 | AC16: 0 | AD16: 4.5 | AE16: 42.5 | AF16: 14.0096 | AG16: =6753.47943187+0.36116788*I16+0.01252571*N16-22.85359542*V16+0.00407811*AA16-0.00067349*E16 -> 6767.7184 | AH16: =A16*'Simple Linear Regression'!$B$18+'Simple Linear Regression'!$B$17 -> 7898.1319 | AI16: =7491.3971+0.0137554*N16-0.00058829*E16-34.3283*V16+0.30565*L16+54.6031*M16 -> 7736.2342 | AJ16: =7491.3971-0.00058829*E16+0.30565*L16+54.6031*M16+0.0137554*N16-34.3283*V16 -> 7736.2342 | AL16: =2192.59+2373.87*I16+0.0316653*N16-15.7623*V16+0.00202406*AA16-0.000740146*E16-0.00963493*(I16*N16) -> 6929.594 | AM16: =5205.907083+122.0638992*I16+13.609808*(N16/1000)-1.245906883*AD16+0.7746840854*AE16-134.2474226*AC16-1547.125689*IF(AND(B16>=DATE(2020,3,20),B16<=DATE(2020,6,26)),1,0) -> 7807.2482 | AN16: =7707.2178-144.397321*AC16+139.5614087*AF16-0.0008594506251*E16-265.7105668*I16-0.02506176117*J16+0.004708026652*N16 -> 9673.0832 | AO16: =IF(N16="","",2190.39 + 2739.06*I16 + 0.034693*N16 - 16.722*V16 - 0.000802*E16 - 1.3691*AD16 + 1.8691*AE16 - 121.7*AC16 + 209.88*IF(AND(B16>=DATE(2020,3,20),B16<=DATE(2020,6,26)),1,0) - 0.011049*(I16*N16)) -> 7559.7843 | AP16: =IF(B16<DATE(2008,1,1),"",3929.06 + 1212.53*I16 - 0.0003097*N16 + 59.426*V16 - 0.0006734*E16 - 1.036*AD16 + 1.2076*AE16 + 94.923*AF16 - 131.43*AC16 - 759.61*IF(AND(B16>=DATE(2020,3,20),B16<=DATE(2020,6,26)),1,0) - 17.324*(I16*V16)) | AQ16: =IF(N16="","",I16*N16) -> 200744.2 | AR16: =I16*E16 -> 499966 | AS16: =AC16*AF16 -> 0 | AT16: =IF(N16="","",2413.3773+89.103503*I16+0.018847679*N16-5.0917058*V16-0.00064564578*E16+1.4315076*AD16-3.1976817*AE16-66.972905*AC16-217.08397*IF(AND(B16>=DATE(2020,3,20),B16<=DATE(2020,6,26)),1,0)+190.76803*AF16) -> 7713.8554 | AU16: =IF(N16="","",-480.76297+2186.3009*I16+0.033368804*N16-5.3903106*V16-0.00073731439*E16+0.93396876*AD16-1.6242981*AE16-61.304389*AC16-95.472727*IF(AND(B16>=DATE(2020,3,20),B16<=DATE(2020,6,26)),1,0)+156.04851*AF16-0.0087322858*AQ16) -> 7530.2396 | AV16: =IF(N16="","",2518.0489-204.66184*I16+0.019354281*N16-2.3328708*V16-0.0022533804*E16+1.5259709*AD16-3.5842757*AE16-65.580099*AC16-62.828483*IF(AND(B16>=DATE(2020,3,20),B16<=DATE(2020,6,26)),1,0)+200.94286*AF16+0.00080379976*AR16) -> 7624.145 | AW16: =IF(N16="","",2361.7153+89.223162*I16+0.018847054*N16-5.0210815*V16-0.0006437347*E16+1.4213619*AD16-3.2156123*AE16+167.41121*AC16-224.35191*IF(AND(B16>=DATE(2020,3,20),B16<=DATE(2020,6,26)),1,0)+194.56435*AF16-19.897843*AS16) -> 7721.4059 | AX16: =IF(N16="","",-654.03928+2464.5589*I16+0.035956453*N16-8.0754527*V16-0.00069441316*E16+0.69511606*AD16-1.1669613*AE16-90.724569*AC16-211.24919*IF(AND(B16>=DATE(2020,3,20),B16<=DATE(2020,6,26)),1,0)+147.22132*AF16-0.010108087*AQ16) -> 7543.2967
A17: 16 | B17: 33382 | C17: 7396 | E17: 448000 | G17: 21.036 | H17: 18.824 | I17: 1.129 | J17: 6035.178 | L17: 929 | M17: 12.038 | N17: 179076 | O17: 3913 | V17: 84.4 | AC17: 0 | AD17: 15.8 | AE17: 31.9 | AF17: 14.1945 | AG17: =6753.47943187+0.36116788*I17+0.01252571*N17-22.85359542*V17+0.00407811*AA17-0.00067349*E17 -> 6766.3743 | AH17: =A17*'Simple Linear Regression'!$B$18+'Simple Linear Regression'!$B$17 -> 7898.9849 | AI17: =7491.3971+0.0137554*N17-0.00058829*E17-34.3283*V17+0.30565*L17+54.6031*M17 -> 7735.0576 | AJ17: =7491.3971-0.00058829*E17+0.30565*L17+54.6031*M17+0.0137554*N17-34.3283*V17 -> 7735.0576 | AL17: =2192.59+2373.87*I17+0.0316653*N17-15.7623*V17+0.00202406*AA17-0.000740146*E17-0.00963493*(I17*N17) -> 6933.3016 | AM17: =5205.907083+122.0638992*I17+13.609808*(N17/1000)-1.245906883*AD17+0.7746840854*AE17-134.2474226*AC17-1547.125689*IF(AND(B17>=DATE(2020,3,20),B17<=DATE(2020,6,26)),1,0) -> 7785.9343 | AN17: =7707.2178-144.397321*AC17+139.5614087*AF17-0.0008594506251*E17-265.7105668*I17-0.02506176117*J17+0.004708026652*N17 -> 9695.0435 | AO17: =IF(N17="","",2190.39 + 2739.06*I17 + 0.034693*N17 - 16.722*V17 - 0.000802*E17 - 1.3691*AD17 + 1.8691*AE17 - 121.7*AC17 + 209.88*IF(AND(B17>=DATE(2020,3,20),B17<=DATE(2020,6,26)),1,0) - 0.011049*(I17*N17)) -> 7528.9806 | AP17: =IF(B17<DATE(2008,1,1),"",3929.06 + 1212.53*I17 - 0.0003097*N17 + 59.426*V17 - 0.0006734*E17 - 1.036*AD17 + 1.2076*AE17 + 94.923*AF17 - 131.43*AC17 - 759.61*IF(AND(B17>=DATE(2020,3,20),B17<=DATE(2020,6,26)),1,0) - 17.324*(I17*V17)) | AQ17: =IF(N17="","",I17*N17) -> 202176.8 | AR17: =I17*E17 -> 505792 | AS17: =AC17*AF17 -> 0 | AT17: =IF(N17="","",2413.3773+89.103503*I17+0.018847679*N17-5.0917058*V17-0.00064564578*E17+1.4315076*AD17-3.1976817*AE17-66.972905*AC17-217.08397*IF(AND(B17>=DATE(2020,3,20),B17<=DATE(2020,6,26)),1,0)+190.76803*AF17) -> 7798.6214 | AU17: =IF(N17="","",-480.76297+2186.3009*I17+0.033368804*N17-5.3903106*V17-0.00073731439*E17+0.93396876*AD17-1.6242981*AE17-61.304389*AC17-95.472727*IF(AND(B17>=DATE(2020,3,20),B17<=DATE(2020,6,26)),1,0)+156.04851*AF17-0.0087322858*AQ17) -> 7590.3702 | AV17: =IF(N17="","",2518.0489-204.66184*I17+0.019354281*N17-2.3328708*V17-0.0022533804*E17+1.5259709*AD17-3.5842757*AE17-65.580099*AC17-62.828483*IF(AND(B17>=DATE(2020,3,20),B17<=DATE(2020,6,26)),1,0)+200.94286*AF17+0.00080379976*AR17) -> 7715.0751 | AW17: =IF(N17="","",2361.7153+89.223162*I17+0.018847054*N17-5.0210815*V17-0.0006437347*E17+1.4213619*AD17-3.2156123*AE17+167.41121*AC17-224.35191*IF(AND(B17>=DATE(2020,3,20),B17<=DATE(2020,6,26)),1,0)+194.56435*AF17-19.897843*AS17) -> 7806.954 | AX17: =IF(N17="","",-654.03928+2464.5589*I17+0.035956453*N17-8.0754527*V17-0.00069441316*E17+0.69511606*AD17-1.1669613*AE17-90.724569*AC17-211.24919*IF(AND(B17>=DATE(2020,3,20),B17<=DATE(2020,6,26)),1,0)+147.22132*AF17-0.010108087*AQ17) -> 7594.5893
A18: 17 | B18: 33389 | C18: 7287 | E18: 443000 | G18: 21.21 | H18: 18.87 | I18: 1.14 | J18: 6035.178 | L18: 929 | M18: 12.038 | N18: 179076 | O18: 3913 | V18: 84.4 | AC18: 1 | AD18: 3.7 | AE18: 69 | AF18: 14.3479 | AG18: =6753.47943187+0.36116788*I18+0.01252571*N18-22.85359542*V18+0.00407811*AA18-0.00067349*E18 -> 6769.7457 | AH18: =A18*'Simple Linear Regression'!$B$18+'Simple Linear Regression'!$B$17 -> 7899.838 | AI18: =7491.3971+0.0137554*N18-0.00058829*E18-34.3283*V18+0.30565*L18+54.6031*M18 -> 7737.9991 | AJ18: =7491.3971-0.00058829*E18+0.30565*L18+54.6031*M18+0.0137554*N18-34.3283*V18 -> 7737.9991 | AL18: =2192.59+2373.87*I18+0.0316653*N18-15.7623*V18+0.00202406*AA18-0.000740146*E18-0.00963493*(I18*N18) -> 6944.1357 | AM18: =5205.907083+122.0638992*I18+13.609808*(N18/1000)-1.245906883*AD18+0.7746840854*AE18-134.2474226*AC18-1547.125689*IF(AND(B18>=DATE(2020,3,20),B18<=DATE(2020,6,26)),1,0) -> 7696.8458 | AN18: =7707.2178-144.397321*AC18+139.5614087*AF18-0.0008594506251*E18-265.7105668*I18-0.02506176117*J18+0.004708026652*N18 -> 9573.4293 | AO18: =IF(N18="","",2190.39 + 2739.06*I18 + 0.034693*N18 - 16.722*V18 - 0.000802*E18 - 1.3691*AD18 + 1.8691*AE18 - 121.7*AC18 + 209.88*IF(AND(B18>=DATE(2020,3,20),B18<=DATE(2020,6,26)),1,0) - 0.011049*(I18*N18)) -> 7505.5653 | AP18: =IF(B18<DATE(2008,1,1),"",3929.06 + 1212.53*I18 - 0.0003097*N18 + 59.426*V18 - 0.0006734*E18 - 1.036*AD18 + 1.2076*AE18 + 94.923*AF18 - 131.43*AC18 - 759.61*IF(AND(B18>=DATE(2020,3,20),B18<=DATE(2020,6,26)),1,0) - 17.324*(I18*V18)) | AQ18: =IF(N18="","",I18*N18) -> 204146.64 | AR18: =I18*E18 -> 505020 | AS18: =AC18*AF18 -> 14.3479 | AT18: =IF(N18="","",2413.3773+89.103503*I18+0.018847679*N18-5.0917058*V18-0.00064564578*E18+1.4315076*AD18-3.1976817*AE18-66.972905*AC18-217.08397*IF(AND(B18>=DATE(2020,3,20),B18<=DATE(2020,6,26)),1,0)+190.76803*AF18) -> 7629.1655 | AU18: =IF(N18="","",-480.76297+2186.3009*I18+0.033368804*N18-5.3903106*V18-0.00073731439*E18+0.93396876*AD18-1.6242981*AE18-61.304389*AC18-95.472727*IF(AND(B18>=DATE(2020,3,20),B18<=DATE(2020,6,26)),1,0)+156.04851*AF18-0.0087322858*AQ18) -> 7491.9758 | AV18: =IF(N18="","",2518.0489-204.66184*I18+0.019354281*N18-2.3328708*V18-0.0022533804*E18+1.5259709*AD18-3.5842757*AE18-65.580099*AC18-62.828483*IF(AND(B18>=DATE(2020,3,20),B18<=DATE(2020,6,26)),1,0)+200.94286*AF18+0.00080379976*AR18) -> 7537.2738 | AW18: =IF(N18="","",2361.7153+89.223162*I18+0.018847054*N18-5.0210815*V18-0.0006437347*E18+1.4213619*AD18-3.2156123*AE18+167.41121*AC18-224.35191*IF(AND(B18>=DATE(2020,3,20),B18<=DATE(2020,6,26)),1,0)+194.56435*AF18-19.897843*AS18) -> 7586.4216 | AX18: =IF(N18="","",-654.03928+2464.5589*I18+0.035956453*N18-8.0754527*V18-0.00069441316*E18+0.69511606*AD18-1.1669613*AE18-90.724569*AC18-211.24919*IF(AND(B18>=DATE(2020,3,20),B18<=DATE(2020,6,26)),1,0)+147.22132*AF18-0.010108087*AQ18) -> 7485.4142
